Workbook

Sheet RICE
A1: DEPARTMENT OF AGRICULTURE-REGIONAL FIELD OFFICE NO. 02
A2: CY 2025 & FY 2026 PROGRAM ACCOMPLISHMENTS/STATUS AND FY 2027 PLAN AND BUDGET PROPOSAL
A3: RICE PROGRAM
A4: PROVINCE: ISABELA
A5: DISTRICT: I
A7: PROGRAM/SUBPROGRAM/ INDICATORS | B7: UNIT OF MEASURE | C7: FY 2025 GAA | E7: FY 2026 GAA | G7: FY 2027 PROPOSAL | M7: Remarks (Breakdown of Municipality Target for FY 2027 )
G8: TIER 1 | I8: TIER 2 | K8: TOTAL
C9: ANNUAL PHYSICAL TARGET | D9: BUDGET (Actual Obligation in ₱ '000) | E9: ACCOMPLISHMENT | G9: PHYSICAL TARGET | H9: ANNUAL BUDGET (₱ '000) | I9: PHYSICAL TARGET | J9: ANNUAL BUDGET (₱ '000) | K9: PHYSICAL TARGET | L9: ANNUAL BUDGET (₱ '000)
E10: PHYSICAL TARGET | F10: ANNUAL BUDGET (₱ '000)
D11: =D12+D22 -> 151856.8 | F11: =F12+F21 -> 328111.17 | H11: =H12+H21 -> 348197.5 | J11: =J12+J21 -> 146692.63 | L11: =L12+L21 -> 494890.13
A12: I. Production Support Services (PSS) | D12: 151856.8 | F12: =SUM(F14:F20) -> 328111.17 | H12: =SUM(H14:H20) -> 348197.5 | J12: =SUM(J14:J20) -> 146692.63 | L12: =SUM(L14:L20) -> 494890.13
A13: Fertilizer Assistance - Ameliorants (solid) | B13: kg | C13: 17908 | D13: 16475.36 | F13: =E13*1 -> 0
A14: Fertilizer Assistance - Bio Fertilizer (pack) | B14: kg | C14: 14080 | D14: 14080 | F14: =E14*1 -> 0
A15: Fertilizer Assistance - inorganic - hybrid area | B15: hectare | C15: 16402 | D15: 55766.8 | E15: 34939.789 | F15: 118795.28 | G15: 36349 | H15: 72698.842 | I15: 337.2 | J15: 6674.3947 | K15: =G15+I15 -> 36686.2 | L15: =H15+J15 -> 79373.236 | M15: CABAGAN DELFIN ALBANO (MAGSAYSAY) DIVILACAN CITY OF ILAGAN (Capital) MACONACON SAN PABLO SANTA MARIA SANTO TOMAS TUMAUINI
A16: Fertilizer Assistance - inorganic - inbred area | B16: hectare | E16: 10181.455 | F16: 34616.948 | G16: 10526.35 | H16: 21052.709 | K16: =G16+I16 -> 10526.35 | L16: =H16+J16 -> 21052.709
A17: Seed assistance-Commercial Hybrid | B17: hectare | C17: 16402 | D17: 82010 | E17: 34939.789 | F17: 174698.94 | G17: 36349 | H17: 254445.95 | I17: 3337.2 | J17: =24528400.45/1000 -> 24528.4 | K17: =G17+I17 -> 39686.2 | L17: =H17+J17 -> 278974.35
A18: FDV/IMC for Inbred | I18: 10526.35 | J18: =24210615.83/1000 -> 24210.616 | K18: =G18+I18 -> 10526.35 | L18: =H18+J18 -> 24210.616
A19: FDV/IMC for Hybrid | I19: 39686.62 | J19: =91279221.86/1000 -> 91279.222 | K19: =G19+I19 -> 39686.62 | L19: =H19+J19 -> 91279.222
A20: Drone voucher | B20: hectare
A21: Hermetic cocoon | B21: number | F21: =SUM(F22:F23) -> 0
A22: II. Extension Support, Education and Training Services (ESETS)
A23: Rice Farm Cluster Establishment | B23: site | D23: 0 | K23: =G23+I23 -> 0 | L23: =H23+J23 -> 0
A24: Scale-up Palayamanan for Rice Based Farm | B24: site | D24: 0 | G24: 13 | H24: 6500 | K24: =G24+I24 -> 13 | L24: =H24+J24 -> 6500
A25: III. AGRICULTURAL MACHINERY, EQUIPMENT, FACILITIES AND INFRASTRUCTURES PROGRAM (AMEFIP) | F25: 1600
A26: III.1. AGRICULTURAL MACHINERY, EQUIPMENT, AND FACILITIES SUPPORT SERVICES (AMEFSS) | F26: 0
A27: A. Provision of Post harvest Machinery and Equipment
A28: Vaccum Pack Sealer | B28: number
A29: Fork Lift | B29: number
A30: Seed Processing center | B30: number
A31: Rice Processing Center | B31: number
A32: Recirculating Dryer | B32: number
A33: Paddy Rice Hauler | B33: number
A34: Packaging System | B34: number
A35: Combine Harvester | B35: number
A36: Hauling Truck | B36: number
A37: Drying Pavement | B37: number
A38: 4wd Tractor | B38: number
A39: Rice Straw Baler | B39: number
A40: B. Provision of Farm Production -Related Machinery and Equiment
A41: Four-Wheel Drive Tractor with accessories | B41: distributed (no.)
...

Sheet CORN
A1: DEPARTMENT OF AGRICULTURE-REGIONAL FIELD OFFICE NO. 02
A2: CY 2025 & FY 2026 PROGRAM ACCOMPLISHMENTS/STATUS AND FY 2027 PLAN AND BUDGET PROPOSAL
A3: CORN PROGRAM
A4: PROVINCE: ISABELA
A5: DISTRICT: I
A7: PROGRAM/SUBPROGRAM/ INDICATORS | B7: UNIT OF MEASURE | C7: FY 2025 GAA | E7: FY 2026 GAA | G7: FY 2027 PROPOSAL | M7: Remarks (Breakdown of Municipality Target for FY 2027 )
G8: TIER 1 | I8: TIER 2 | K8: TOTAL
C9: ANNUAL PHYSICAL TARGET | D9: BUDGET (Actual Obligation in ₱ '000) | E9: ACCOMPLISHMENT | G9: PHYSICAL TARGET | H9: ANNUAL BUDGET (₱ '000) | I9: PHYSICAL TARGET | J9: ANNUAL BUDGET (₱ '000) | K9: PHYSICAL TARGET | L9: ANNUAL BUDGET (₱ '000)
E10: PHYSICAL TARGET | F10: ANNUAL BUDGET (₱ '000)
A11: I. PRODUCTION SUPPORT SERVICES | D11: =SUM(D12:D43) -> 106677.47 | F11: =SUM(F12:F47) -> 101270.92 | H11: =SUM(H12:H47) -> 36572.6 | J11: =SUM(J12:J47) -> 230317.2 | L11: =SUM(L12:L47) -> 266889.8
A12: 1. Registered Seed (RS) Production
A13: Flint | C13: 4000 | D13: =C13*0.05 -> 200
A14: Glutinous | C14: 3800 | D14: =C14*0.05 -> 190
A15: 2. Recommended Corn Production Technologies (RCPT)
A16: Hybrid Yellow | B16: kilograms | C16: 6300 | D16: =350*2*6000/1000 -> 4200 | E16: 5400 | F16: 3900 | I16: =300*27 -> 8100 | J16: =300*19.5 -> 5850 | K16: =SUM(G16,I16) -> 8100 | L16: =SUM(H16,J16) -> 5850 | M16: Delfin Albano
A17: Inorganic Fertilizer | B17: kilograms | C17: =((350*4)+(200*6)+(150*7)+(200*1))*50 -> 192500 | D17: =5298500/1000 -> 5298.5 | E17: 110000 | F17: 4400 | I17: =300*11*50 -> 165000 | J17: =300*11*2 -> 6600 | K17: =SUM(G17,I17) -> 165000 | L17: =SUM(H17,J17) -> 6600 | M17: Delfin Albano
A18: Biofertilizer | B18: packs | C18: 1650 | D18: =903000/1000 -> 903 | E18: 1200 | F18: 240 | I18: =300*6 -> 1800 | J18: =300*6*0.2 -> 360 | K18: =SUM(G18,I18) -> 1800 | L18: =SUM(H18,J18) -> 360 | M18: Delfin Albano
A19: Agricultural Lime | B19: kilograms | C19: =3500*50 -> 175000 | D19: =1519000/1000 -> 1519 | E19: 100000 | F19: 1200 | I19: =300*10*50 -> 150000 | J19: =300*10*0.6 -> 1800 | K19: =SUM(G19,I19) -> 150000 | L19: =SUM(H19,J19) -> 1800 | M19: Delfin Albano
A20: Plant Growth Enhancer | B20: packs | E20: 200 | F20: 160
A21: Complete Foliar Fertilizer | B21: kilograms | E21: 600 | F21: 360
A22: 2. Recommended Corn Production Technologies (RCPT)
A23: OPV Glutinous | B23: kilograms | G23: =200*25 -> 5000 | H23: =(G23/2000)*150 -> 375 | K23: =SUM(G23,I23) -> 5000 | L23: =SUM(H23,J23) -> 375 | M23: Sto. Tomas
A24: Inorganic Fertilizer | B24: kilograms | G24: =200*11*50 -> 110000 | H24: =200*11*2 -> 4400 | K24: =SUM(G24,I24) -> 110000 | L24: =SUM(H24,J24) -> 4400 | M24: Sto. Tomas
A25: Biofertilizer | B25: packs | G25: =200*6 -> 1200 | H25: =200*6*0.2 -> 240 | K25: =SUM(G25,I25) -> 1200 | L25: =SUM(H25,J25) -> 240 | M25: Sto. Tomas
A26: Agricultural Lime | B26: kilograms | G26: =200*10*50 -> 100000 | H26: =200*10*0.6 -> 1200 | K26: =SUM(G26,I26) -> 100000 | L26: =SUM(H26,J26) -> 1200 | M26: Sto. Tomas
A27: 3. Corn Production Enhancement Project (CPEP)
A28: Hybrid (GM) | B28: kilograms | C28: =11864*9 -> 106776 | D28: =69539000/1000 -> 69539 | E28: 57420 | F28: 41470 | G28: =662*18 -> 11916 | H28: =662*19.5 -> 12909 | I28: =8275*18 -> 148950 | J28: =8275*13 -> 107575 | K28: =SUM(G28,I28) -> 160866 | L28: =SUM(H28,J28) -> 120484 | M28: Cabagan, City of Ilagan, Delfin Albano, San Pablo, Sta. Maria, Sto. Tomas, Tumauini
A29: Inorganic Fertilizer for GM | B29: kilograms | C29: =11864*50 -> 593200 | D29: =(5932*1.35)+(5932*1.411) -> 16378.252 | E29: 319000 | F29: 12760 | G29: =662*50 -> 33100 | H29: =662*2 -> 1324 | I29: =8275*50 -> 413750 | J29: =8275*2 -> 16550 | K29: =SUM(G29,I29) -> 446850 | L29: =SUM(H29,J29) -> 17874
A30: Hybrid (Conventional) | B30: kilograms | E30: 38322 | F30: 21290 | G30: =441*18 -> 7938 | H30: =441*10 -> 4410 | I30: =5517*18 -> 99306 | J30: =5517*10 -> 55170 | K30: =SUM(G30,I30) -> 107244 | L30: =SUM(H30,J30) -> 59580
A31: Inorganic Fertilizer for Conventional | B31: kilograms | E31: 212900 | F31: 8516 | G31: =441*150 -> 66150 | H31: =441*6 -> 2646 | I31: =5517*150 -> 827550 | J31: =5517*6 -> 33102 | K31: =SUM(G31,I31) -> 893700 | L31: =SUM(H31,J31) -> 35748
A32: Agricultural Gypsum for Conventional | B32: kilograms | G32: =441*50 -> 22050 | H32: =441*0.6 -> 264.6 | I32: =5517*50 -> 275850 | J32: =5517*0.6 -> 3310.2 | K32: =SUM(G32,I32) -> 297900 | L32: =SUM(H32,J32) -> 3574.8
A33: 4. Support to Cassava
A34: Production of cassava seed pieces | B34: pieces | C34: 155000 | D34: =C34*1/1000 -> 155 | E34: 845000 | F34: 1300 | G34: 845000 | H34: =(G34/65000)*100 -> 1300 | K34: =SUM(G34,I34) -> 845000 | L34: =SUM(H34,J34) -> 1300 | M34: City of Ilagan, Delfin Albano, Tumauini
A35: Procurement of cassava seed pieces | B35: pieces | C35: 2430000 | D35: =C35*1.5/1000 -> 3645
A36: Procurement of Inorganic Fertilizer | B36: kilograms | C36: 25900 | D36: =(258.5*1.35)+(258.5*1.411) -> 713.7185 | E36: 6500 | F36: 260 | G36: =(G34/13000)*100 -> 6500 | H36: =55*4 -> 220 | K36: =SUM(G36,I36) -> 6500 | L36: =SUM(H36,J36) -> 220 | M36: City of Ilagan, Delfin Albano, Tumauini
A37: Solar Bubble Dryer | B37: number | E37: 5 | F37: 1250
A38: 5. Support to Sorghum
A39: Sorghum Seeds | B39: kilograms | C39: 20000 | D39: =C39*58.75/1000 -> 1175 | E39: 600 | F39: 360 | G39: 1200 | H39: =(G39/10)*6 -> 720 | K39: =SUM(G39,I39) -> 1200 | L39: =SUM(H39,J39) -> 720 | M39: City of Ilagan, Delfin Albano, Tumauini, Jones, Cauayan City
A40: Inorganic Fertilizer | B40: kilograms | C40: 100000 | D40: =(1000*1.35)+(1000*1.411) -> 2761 | E40: 6000 | F40: 240 | G40: =(G39/10)*100 -> 12000 | H40: =(G40/100)*4 -> 480 | K40: =SUM(G40,I40) -> 12000 | L40: =SUM(H40,J40) -> 480 | M40: City of Ilagan, Delfin Albano, Tumauini, Jones, Cauayan City
A41: 6. White Corn Production Enhancement Project (WCPEP)
...

Sheet HVCDP
A1: DEPARTMENT OF AGRICULTURE-REGIONAL FIELD OFFICE NO. 02
A2: CY 2025 & FY 2026 PROGRAM ACCOMPLISHMENTS/STATUS AND FY 2027 PLAN AND BUDGET PROPOSAL
A3: HIGH VALUE CROPS DEVELOPMENT PROGRAM
A4: PROVINCE: ISABELA
A5: DISTRICT: I
A7: PROGRAM/SUBPROGRAM/ INDICATORS | B7: UNIT OF MEASURE | C7: FY 2025 GAA | E7: FY 2026 GAA | G7: FY 2027 PROPOSAL | M7: Remarks (Breakdown of Municipality Target for FY 2027 )
G8: TIER 1 | I8: TIER 2 | K8: TOTAL
C9: ANNUAL PHYSICAL TARGET | D9: BUDGET (Actual Obligation in ₱ '000) | E9: ACCOMPLISHMENT | G9: PHYSICAL TARGET | H9: ANNUAL BUDGET (₱ '000) | I9: PHYSICAL TARGET | J9: ANNUAL BUDGET (₱ '000) | K9: PHYSICAL TARGET | L9: ANNUAL BUDGET (₱ '000)
E10: PHYSICAL TARGET | F10: ANNUAL BUDGET (₱ '000)
A11: OPERATIONS | D11: =D12+D622 -> 2954.5 | E11: =E12+E622 -> 0 | F11: =F12+F622 -> 3274.715 | H11: =H12+H622 -> 10338.982
A12: I. TECHNICAL AND SUPPORT SEVICES PROGRAM | D12: =D13+D461 -> 2954.5 | F12: =F13+F461 -> 2674.715 | H12: =H13 -> 6638.9818
A13: A. Production Support Services Sub-Program | D13: =SUM(D19:D460) -> 2954.5 | F13: =SUM(F19:F460) -> 2674.715 | H13: =sum(H27:H428) -> 6638.9818
A14: Outcome Indicators
A15: Beneficiaries rating the production support services (PSS) delivered to be at least satisfactory
A16: Deliveries of producrtion support services validated by LGU's to have been delivered at the appropriate time
A17: Output Indicators
A18: LGU's assisted with production support services
A19: Input Indicators
A20: Seed Distribution
A21: Procured
A22: Produced
A23: Distributed
A24: Area Planted
A25: Mungbean
A26: Procured | B26: kilogram
A27: Produced | B27: kilogram | C27: 2000 | D27: 400 | E27: 1000 | F27: =E27*0.25 -> 250 | G27: =300*20 -> 6000 | H27: =G27*0.25 -> 1500
A28: Distributed | B28: kilogram | C28: 2000 | E28: =E27 -> 1000 | G28: =G27 -> 6000
A29: Area Planted | B29: hectare | C29: 100 | E29: =E28/25 -> 40 | G29: =G28/20 -> 300
A30: Peanut
A31: Procured | B31: kilogram
A32: Produced | B32: kilogram
A33: Distributed | B33: kilogram
A34: Area Planted | B34: hectare
A35: White Potato
A36: Procured
A37: Produced
A38: Distributed
A39: Area Planted
A40: Hot Pepper
A41: Procured
...

Sheet NUPAP
A1: DEPARTMENT OF AGRICULTURE-REGIONAL FIELD OFFICE NO. 02
A2: CY 2025 & FY 2026 PROGRAM ACCOMPLISHMENTS/STATUS AND FY 2027 PLAN AND BUDGET PROPOSAL
A3: NATIONAL URBAN AND PERI-URBAN AGRICULTURE PROGRAM
A4: PROVINCE: ISABELA
A5: DISTRICT: I
A7: PROGRAM/SUBPROGRAM/ INDICATORS | B7: UNIT OF MEASURE | C7: FY 2025 GAA | E7: FY 2026 GAA | G7: FY 2027 PROPOSAL | M7: Remarks (Breakdown of Municipality Target for FY 2027 )
C8: ANNUAL PHYSICAL TARGET | D8: ANNUAL BUDGET (₱ '000) | G8: TIER 1 | I8: TIER 2 | K8: TOTAL
E9: ACCOMPLISHMENT | G9: PHYSICAL TARGET | H9: ANNUAL BUDGET (₱ '000) | I9: PHYSICAL TARGET | J9: ANNUAL BUDGET (₱ '000) | K9: PHYSICAL TARGET | L9: ANNUAL BUDGET (₱ '000)
E10: PHYSICAL TARGET | F10: ANNUAL BUDGET (₱ '000)
A11: I. TECHNICAL AND SUPPORT SEVICES PROGRAM | D11: =D12 -> 634.31872 | F11: =F12 -> 50.5
A12: A. Production Support Services Sub-Program | D12: =SUM(D14:D39) -> 634.31872 | F12: =SUM(F14:F40) -> 50.5
A13: 1. Seeds Procured for Distribution
A14: Lowland Vegetables | B14: kilograms distributed | C14: 11 | D14: 141.02561
A15: Highland Vegetables | B15: kilograms distributed | C15: 11 | D15: 141.02561
A16: 2. Planting Materials for Distribution
A17: Fruit Bearing Tree (seedlings) | B17: pieces
A18: Strawberry (cuttings) | B18: pieces | C18: 100 | D18: 7.619
A19: Ginger | B19: pieces
A20: Mango | B20: pieces
A21: Calamansi Seedlings | C21: 125 | D21: 12.5
A22: Calamansi Seedlings | B22: pieces
A24: 3. Soil Mix/Fertilizer:
A25: Organic Fertilizer - Solid | B25: kilograms distributed | C25: 3000 | D25: 38.1 | E25: =60+41 -> 101 | F25: =30+20.5 -> 50.5
A26: Soilless Media/Potting Mix | B26: kilograms distributed | C26: 2250 | D26: 33.3333
A27: Liquid Fertilizer - Hydroponic Solution | B27: liter
A28: Foliar Fertilizer | B28: kilograms distributed
A29: 4. Other Farm Inputs
A30: Seedling Tray | B30: pieces | C30: 300 | D30: 27.501
A31: Plastic Crate | B31: pieces | C31: 100 | D31: 62.5
A32: Plastic Mulch | B32: rolls | C32: 10 | D32: 29.5238
A33: Set of Garden Tools | B33: number
A34: Clay Pot | B34: number
A35: Soft Pots | B35: number | C35: 100 | D35: 12.5
A36: Stackable pots | B36: number | C36: 20 | D36: 76.1904
A37: Plastic Drum | B37: number | C37: 10 | D37: 40
A38: Garden Hose | B38: number
A39: Wheel barrow | B39: number | C39: 2 | D39: 12.5
A40: Water Sprinkler | B40: number
A41: Extension Support, Education and Training Services Sub-Program
A43: II. AGRICULTURAL MACHINERY, EQUIPMENT, FACILITES AND INFRASTRUCTURE PROGRAM | D43: =SUM(D44:D58) -> 2750 | F43: =SUM(F44:F58) -> 2762 | H43: =H44+H58 -> 4380
...

Sheet LIVESTOCK
A1: DEPARTMENT OF AGRICULTURE-REGIONAL FIELD OFFICE NO. 02
A2: CY 2025 & FY 2026 PROGRAM ACCOMPLISHMENTS/STATUS AND FY 2027 PLAN AND BUDGET PROPOSAL
A3: LIVESTOCK PROGRAM
A4: PROVINCE: ISABELA
A5: DISTRICT: I
A7: PROGRAM/SUBPROGRAM/ INDICATORS | B7: UNIT OF MEASURE | C7: FY 2025 GAA | E7: FY 2026 GAA | G7: FY 2027 PROPOSAL | M7: Remarks (Breakdown of Municipality Target for FY 2027 )
G8: TIER 1 | I8: TIER 2 | K8: TOTAL
C9: ACCOMPLISHMENT | E9: ACCOMPLISHMENT | G9: PHYSICAL TARGET | H9: ANNUAL BUDGET (₱ '000) | I9: PHYSICAL TARGET | J9: ANNUAL BUDGET (₱ '000) | K9: PHYSICAL TARGET | L9: ANNUAL BUDGET (₱ '000)
C10: PHYSICAL | D10: BUDGET (Actual Obligation) | E10: PHYSICAL TARGET | F10: ANNUAL BUDGET (₱ '000)
A11: I. Production Support Services Sub-Program | D11: =SUM(D14:D34) -> 4052.89 | F11: =SUM(F14:F25) -> 3222.2 | H11: =SUM(H14:H25) -> 2280.005
A12: A. National Animal Genetic Resources Improvement Program
A13: 1. Unified National Artificial Insemination Program
A14: Cattle | B14: number | C14: 500 | D14: 1388.49 | E14: 500 | F14: 1200 | G14: 1280 | H14: =G14*0.5 -> 640
A15: Goat | B15: number | C15: 60 | D15: 74.4 | E15: 30 | F15: 37.2 | G15: 120 | H15: =G15*0.5 -> 60
A16: Planting Material distributed | B16: number | G16: 11667 | H16: =G16*0.015 -> 175.005
A17: 2. Philippine Native Animal Development
A18: Native Chicken Distribtuion | C18: 100 | D18: 60 | E18: 100 | F18: 60 | G18: 500 | H18: =G18*0.5 -> 250
A19: Duck Distribution | B19: number
A21: B. Development, Maintenance, and Rehabilitation/ Upgrading of Government Stock Farms, and Other Facilities
A22: Cattle | B22: number
A23: Goat (Meat type) | B23: number | C23: 5 | D23: 275 | E23: 5 | F23: 275
A24: Goat (Dairy type) | B24: number
A25: Sheep | B25: number | C25: 41 | D25: 2255 | E25: 30 | F25: =E25*55 -> 1650 | G25: 21 | H25: =G25*55 -> 1155
A27: C. Support to Prevention and Control of Economically Important Diseases
A28: 1. Drugs and Biologic Support | B28: number
A29: 2. Calibrated sentinelling and Repopulation
A30: Piglets Distributed | B30: No. of heads distributed
A31: Feeds Distributed | B31: number
A32: Test Kit Distributed | B32: number
A33: LEED
A34: Cattle Multiplier Farm | B34: number
A35: II. AGRICULTURAL MACHINERY, EQUIPMENT, FACILITES AND INFRASTRUCTURE PROGRAM | F35: =F36 -> 3500 | H35: =H36 -> 16600
A36: A. Agricultural Machinery, Equipment and Facilities Support Services Sub-Program | F36: =SUM(F39:F49) -> 3500 | H36: =SUM(H39:H49) -> 16600
A37: 1. Production Facilities Established
A38: 1.1 Livestock Economic Enterprise Development (LEED)
A39: Cattle Multiplier Farm | B39: number
A40: Chicken Multiplier Farm | B40: number
A41: Honeybee Multiplier Farm | B41: number
A42: Duck Multiplier Farm | B42: number
A43: Sheep Multiplier Farm | B43: number
...

Sheet OAP
A1: DEPARTMENT OF AGRICULTURE-REGIONAL FIELD OFFICE NO. 02 | R1: Note: Kindly fill out 2027 Proposal (Tier 1 &2) and indicate on the Column M the target municipalities for each Programs/Activities/Projects. Also, Please double check the amounts indicated in FY 2026 GAA.
A2: CY 2025 & FY 2026 PROGRAM ACCOMPLISHMENTS/STATUS AND FY 2027 PLAN AND BUDGET PROPOSAL
A3: OAP PROGRAM
A4: PROVINCE: ISABELA
A5: DISTRICT: I
A7: PROGRAM/SUBPROGRAM/ INDICATORS | B7: UNIT OF MEASURE | C7: CY 2023 GAA | E7: FY 2025 GAA | G7: FY 2026 GAA | O7: FY 2026 RECOMMENDED BUDGET | Q7: FY 2027 PROPOSAL | W7: Remarks (Breakdown of Municipality Target for FY 2027 )
C8: ACCOMPLISHMENT | E8: ANNUAL PHYSICAL TARGET | F8: ANNUAL BUDGET (₱ '000) | I8: TIER 2 | K8: TOTAL | M8: TOTAL | Q8: TIER 1 | S8: TIER 2 | U8: TOTAL
C9: PHYSICAL | D9: ANNUAL BUDGET (₱ '000) | G9: ACCOMPLISHMENT | I9: PHYSICAL TARGET | J9: ANNUAL BUDGET (₱ '000) | K9: PHYSICAL TARGET | L9: ANNUAL BUDGET (₱ '000) | M9: PHYSICAL TARGET | N9: BUDGET | Q9: PHYSICAL TARGET | R9: ANNUAL BUDGET (₱ '000) | S9: PHYSICAL TARGET | T9: ANNUAL BUDGET (₱ '000) | U9: PHYSICAL TARGET | V9: ANNUAL BUDGET (₱ '000)
G10: PHYSICAL TARGET | H10: ANNUAL BUDGET (₱ '000) | O10: PHYSICAL TARGET | P10: ANNUAL BUDGET (₱ '000)
A11: I. TECHNICAL AND SUPPORT SERVICES PROGRAM | D11: =D12+D44 -> 1200 | F11: 6950 | G11: =G12 -> 1079 | H11: =H12 -> 1050 | N11: =#REF!+#REF! -> #REF! | P11: =P12 -> 1050 | R11: =R12 -> 2200
A12: I.1. Production Support Services Sub-program | D12: =SUM(D13:D42) -> 1200 | F12: 1950 | G12: =SUM(G13:G42) -> 1079 | H12: =SUM(H13:H42) -> 1050 | N12: =#REF!+#REF! -> #REF! | P12: =SUM(P13:P42) -> 1050 | R12: =SUM(R15:R36) -> 2200
A13: A. On- station seeds production and distribution
A14: a.1. Vegetables | B14: number
A15: Individual provided with vegetable seeds | B15: number
A16: Male | B16: number | C16: 15 | E16: 30
A17: Female | B17: number | C17: 30 | E17: 30
A18: Group | B18: number | C18: 2 | E18: 2 | G18: 6 | M18: =#REF!+#REF! -> #REF! | N18: =#REF!+#REF! -> #REF! | O18: 6 | Q18: 6
A19: Assorted Open-pollinated varieties | B19: kg | C19: 20 | D19: 400 | E19: 70 | F19: 1000 | G19: 70 | H19: 550 | M19: =#REF!+#REF! -> #REF! | N19: =#REF!+#REF! -> #REF! | O19: 70 | P19: 550 | Q19: 60 | R19: 700 | W19: Provincewide
M20: =#REF!+#REF! -> #REF! | N20: =#REF!+#REF! -> #REF!
A21: a.2. Rice | B21: number | M21: =#REF!+#REF! -> #REF! | N21: =#REF!+#REF! -> #REF!
A22: Individual provided with upland rice seeds | B22: number | M22: =#REF!+#REF! -> #REF! | N22: =#REF!+#REF! -> #REF!
A23: Male | B23: number | C23: 15 | E23: 10 | M23: =#REF!+#REF! -> #REF! | N23: =#REF!+#REF! -> #REF!
A24: Female | B24: number | C24: 15 | E24: 10 | M24: =#REF!+#REF! -> #REF! | N24: =#REF!+#REF! -> #REF!
A25: Group | B25: number | C25: 1 | E25: 1 | G25: 3 | M25: =#REF!+#REF! -> #REF! | N25: =#REF!+#REF! -> #REF! | O25: 3 | Q25: 4
A26: Upland rice | B26: kg | C26: 1000 | D26: 400 | E26: 750 | F26: 500 | G26: 1000 | H26: 500 | M26: =#REF!+#REF! -> #REF! | N26: =#REF!+#REF! -> #REF! | O26: 1000 | P26: 500 | Q26: 1000 | R26: 500 | W26: Provincewide
M27: =#REF!+#REF! -> #REF! | N27: =#REF!+#REF! -> #REF!
A28: a.3. Corn | B28: number | M28: =#REF!+#REF! -> #REF! | N28: =#REF!+#REF! -> #REF!
A29: Individual provided with OPV corn seeds | B29: number | M29: =#REF!+#REF! -> #REF! | N29: =#REF!+#REF! -> #REF!
A30: Male | B30: number | C30: 15 | E30: 10 | M30: =#REF!+#REF! -> #REF! | N30: =#REF!+#REF! -> #REF!
A31: Female | B31: number | C31: 15 | E31: 10 | M31: =#REF!+#REF! -> #REF! | N31: =#REF!+#REF! -> #REF!
A32: Group | B32: number | C32: 1 | E32: 1 | M32: =#REF!+#REF! -> #REF! | N32: =#REF!+#REF! -> #REF!
A33: OPV Corn | B33: kg | C33: 800 | D33: 400 | E33: 500 | F33: 450 | M33: =#REF!+#REF! -> #REF! | N33: =#REF!+#REF! -> #REF!
A35: Peanut Seeds | B35: Kg | Q35: 200 | R35: 500 | W35: Provincewide
A36: Assorted Vegetable Seedlings | B36: Pcs | Q36: 75000 | R36: 500 | W36: Provincewide
M37: =#REF!+#REF! -> #REF! | N37: =#REF!+#REF! -> #REF!
A38: B. Farm supplies distributed | B38: number | M38: =#REF!+#REF! -> #REF! | N38: =#REF!+#REF! -> #REF!
A39: Seedling Trays (100 holes) | B39: Pieces | M39: =#REF!+#REF! -> #REF! | N39: =#REF!+#REF! -> #REF!
A40: UV Plastic 6mil UV polyethylene plastic film for green house (7mX90mx.006 inch) | B40: Rolls | M40: =#REF!+#REF! -> #REF! | N40: =#REF!+#REF! -> #REF!
M41: =#REF!+#REF! -> #REF! | N41: =#REF!+#REF! -> #REF!
A42: C. Establishment of Organic Multi-Purpose Shed | B42: number | M42: =#REF!+#REF! -> #REF! | N42: =#REF!+#REF! -> #REF!
...

Sheet HALAL
A1: DEPARTMENT OF AGRICULTURE-REGIONAL FIELD OFFICE NO. 02
A2: CY 2025 & FY 2026 PROGRAM ACCOMPLISHMENTS/STATUS AND FY 2027 PLAN AND BUDGET PROPOSAL
A3: HALAL PROGRAM
A4: PROVINCE:ISABELA
A5: DISTRICT: I
A7: PROGRAM/SUBPROGRAM/ INDICATORS | B7: UNIT OF MEASURE | C7: FY 2025 GAA | E7: FY 2026 GAA | G7: FY 2027 PROPOSAL | M7: Remarks (Breakdown of Municipality Target for FY 2027 )
C8: ANNUAL PHYSICAL TARGET | D8: ANNUAL BUDGET (₱ '000) | G8: TIER 1 | I8: TIER 2 | K8: TOTAL
E9: ACCOMPLISHMENT | G9: PHYSICAL TARGET | H9: ANNUAL BUDGET (₱ '000) | I9: PHYSICAL TARGET | J9: ANNUAL BUDGET (₱ '000) | K9: PHYSICAL TARGET | L9: ANNUAL BUDGET (₱ '000)
E10: PHYSICAL TARGET | F10: ANNUAL BUDGET (₱ '000)
A11: I. TECHNICAL AND SUPPORT SERVICES PROGRAM
A12: A. Extension Support, Education and Training Services
A13: 1. Advanced Training cum Production on Halal Farming Systems | D13: 60
A14: Halal orientation conducted | B14: number | C14: 1
A15: Participants | B15: number | C15: 25
A16: 2. Halal Product Certification Assistance | D16: 50 | E16: 4 | F16: 175
A17: Product for certification | B17: number | C17: 1
A18: 3. Assistance on the Production of DA Assisted Halal Certified Products | D18: 90
A19: Products assisted | B19: number | C19: 1
A21: B. Field Program Management Activities (FPMA)
A22: 1. Halal Product Certification Assistance
A23: Hiring of | B23: number
A25: GRAND TOTAL | D25: =SUM(D13:D19) -> 200 | F25: =F16 -> 175
A27: Prepared by: | E27: In coordination with: | L27: Concurred by:
A32: BERNADETTE T. GALOSO | E32: MACARIO B. ANDAL, CPA | L32: ROSE MARY G. AQUINO, Ph.D.
A33: Chief, PMED | E33: Chief, Budget Section | L33: Regional Executive Director

Sheet FMR
A1: DEPARTMENT OF AGRICULTURE-REGIONAL FIELD OFFICE NO. 02
A2: CY 2025 & FY 2026 PROGRAM ACCOMPLISHMENTS/STATUS AND FY 2027 PLAN AND BUDGET PROPOSAL
A3: FARM-TO-MARKET ROAD DEVELOPMENT PROGRAM
A4: PROVINCE: ISABELA
A5: DISTRICT: I
A7: MUNICIPALITY | B7: LOCATION (BARANGAY) | C7: NAME OF PROJECTS | D7: ESTIMATED LENGTH (KM) | E7: ESTIMATED AMOUNT (₱ '000)
A8: FY 2025 PROPOSAL (TIER I)
A9: CABAGAN | B9: Sitio Malasi, Brgy. San Antonio | C9: Concreting of Sitio Malasi-San Antonio FMR, Brgy. San Antonio, Cabagan, Isabela | D9: 1 | E9: 15000
A10: ILAGAN CITY | B10: Rang-Ayan(Bintacan) | C10: Concreting of Rang-Ayan FMR, Brgy. Rang-ayan ( Bintacan), Ilagan City, Isabela | D10: 1 | E10: 15000
A11: MACONACON | B11: Riena Mercedes | C11: Concreting of Kamanggaan-Mundura-Sitio Diaduan FMR , Brgy. Reina Mercedes, Maconacon, Isabela | D11: 1 | E11: 15000
B12: Malasin- Fely | C12: Concreting of Brgy. Malasin - Brgy. Fely FMR, Brgy. Malasin- Fely, Maconacon, Isabela | D12: 1 | E12: 15000
A13: DELFIN ALBANO | B13: San Antonio | C13: Concreting of Brgy. San Antonio FMR, Brgy. San Antonio, Delfin Albano, Isabela | D13: 1 | E13: 15000
A14: TUMAUINI | B14: Sto. Niño | C14: Concreting of Sto. Niño-Lalauanan FMR | D14: 3.9 | E14: 40000
A15: SUBTOTAL | D15: =SUM(D9:D14) -> 8.9 | E15: =SUM(E9:E14) -> 115000
A17: FY 2025 PROPOSAL (TIER II)
A18: ILAGAN CITY | B18: Cabisera 25 | C18: Concreting Of Cabisera 25 Fmr Phase I, Brgy.Cabisera 25, Ilagan City, Isabela | D18: 1 | E18: 15000
A19: TUMAUINI | B19: Annafunan | C19: Concreting Of Annafunan Fmr, Brgy. Annafunan, Tumauini, Isabela | D19: 1.2 | E19: 18000
A20: STA. MARIA | B20: San Isidro West | C20: Concreting Of San Isidro West Fmr, Brgy. San Isidro West, Sta. Maria, Isabela | D20: 1 | E20: 15000
A21: CABAGAN | B21: Anao | C21: Concreting Of Brgy Anao-Ngarag-Cubag Fmr, Brgy. Anao, Cabagan, Isabela | D21: 1.15 | E21: 15000
A22: SUBTOTAL | D22: =SUM(D18:D21) -> 4.35 | E22: =SUM(E18:E21) -> 63000
A23: TOTAL | D23: =D22+D15 -> 13.25 | E23: =E22+E15 -> 178000
A25: FY 2025 NEP
A26: CABAGAN | B26: San Antonio | C26: Concreting of Malasin-San Antonio FMR | D26: 1 | E26: 15000
B27: San Antonio | C27: Concreting of Sitio Binag - Sitio Gassug, Brgy. San Antonio FMR Phase II | D27: 0.667 | E27: 10000
B28: Pilig Alto | C28: Concreting of Brgy. Pilig Alto FMR | D28: 2 | E28: 30000
B29: Cansan | C29: Concreting of Sitio Pelo, Brgy. Cansan FMR | D29: 1 | E29: 15000
B30: Tallag | C30: Concreting of Tallag Proper- Sitio Punta FMR | D30: 2 | E30: 30000
A31: STO. TOMAS | B31: Bubug | C31: Concreting of Bubug FMR,( Phase I) | D31: 1 | E31: 15000
B32: Bubug | C32: Concreting Sitio Matakayan- Malacab FMR Phase II | D32: 0.667 | E32: 10000
B33: Bubug | C33: Concreting of Brgy. Bubug FMR ( Phase II) | D33: 1.333 | E33: 20000
B34: Barumbong | C34: Concreting of Brgy. Barumbong FMR | D34: 1 | E34: 15000
B35: Bagabag-Biga Oriental | C35: Concreting of Brgy. Bagabag-Biga Oriental Phase 2 FMR | D35: 1 | E35: 15000
B36: Calanigan Norte | C36: Concreting of Brgy. Calanigan Norte FMR | D36: 1 | E36: 15000
A37: STO. TOMAS | B37: Barumbong | C37: Concreting of Sitio Villa - Sitio Colunguan FMR | D37: 1 | E37: 15000
A38: SAN PABLO | B38: Simanu Norte | C38: Concreting of Brgy. Simanu Norte FMR Phase II | D38: 0.667 | E38: 10000
B39: Poblacion- Dalena | C39: Concreting of Rodeo Arena Poblacion-Sitio Antagan FMR | D39: 1 | E39: 15000
A40: TUMAUINI | B40: Bayabo East | C40: Concreting of Bayabo East FMR | D40: 1 | E40: 15000
B41: Caligayan | C41: Concreting of Caligayan FMR | D41: 1 | E41: 15000
A42: ILAGAN CITY | B42: Imelda | C42: Concreting of Villa Imelda FMR | D42: 2 | E42: 30000
B43: Gayong -Gayong Sur | C43: Concreting of Brgy. Gayong- Gayong Sur FMR | D43: 1 | E43: 15000
...

Sheet PRDP
A1: DEPARTMENT OF AGRICULTURE-REGIONAL FIELD OFFICE NO. 02
A2: CY 2025 & FY 2026 PROGRAM ACCOMPLISHMENTS/STATUS AND FY 2027 PLAN AND BUDGET PROPOSAL
A3: PHILIPPINE RURAL DEVELOPMENT PROJECT
A4: PROVINCE: ISABELA
A5: DISTRICT: I
A7: MUNICIPALITY | B7: LOCATION (BARANGAY) | C7: NAME OF PROJECTS | D7: ESTIMATED LENGTH (KM) | E7: ESTIMATED AMOUNT (₱ '000)
A8: FY 2026 PIPELINED/PROPOSAL
A9: Cabagan | B9: Cansan | C9: Construction of Cabagan Warehouse with Solar Dryer | D9: 1040 sq.m. | E9: =15000000/1000 -> 15000
A11: TOTAL | E11: =SUM(E9:E10) -> 15000
A13: Prepared by: | C13: In coordination with | D13: Concurred by:
A18: BERNADETTE T. GALOSO | C18: MACARIO B. ANDAL, CPA | D18: ROSE MARY G. AQUINO, Ph.D.
A19: Chief, PMED | C19: Chief, Budget Section | D19: Regional Executive Director

Sheet 4Ks
A1: DEPARTMENT OF AGRICULTURE-REGIONAL FIELD OFFICE NO. 02
A2: CY 2025 & FY 2026 PROGRAM ACCOMPLISHMENTS/STATUS AND FY 2027 PLAN AND BUDGET PROPOSAL | H2: Note: Kindly fill out 2027 Proposal (Tier 1 &2) and indicate on the Column M the target municipalities for each Programs/Activities/Projects. Also, Please double check the amounts indicated in FY 2026 GAA.
A3: KABUHAYAN AT KAUNLARAN NG KABABAYANG KATUTUBO (4Ks) PROGRAM
A4: PROVINCE: ISABELA
A5: DISTRICT: I
A7: PROGRAM/SUBPROGRAM/ INDICATORS | B7: UNIT OF MEASURE | C7: FY 2025 GAA | E7: FY 2026 GAA | G7: FY 2027 PROPOSAL | M7: Remarks (Breakdown of Municipality Target for FY 2027 )
C8: ANNUAL PHYSICAL TARGET | D8: ANNUAL BUDGET (₱ '000) | G8: TIER 1 | I8: TIER 2 | K8: TOTAL
E9: ACCOMPLISHMENT | G9: PHYSICAL TARGET | H9: ANNUAL BUDGET (₱ '000) | I9: PHYSICAL TARGET | J9: ANNUAL BUDGET (₱ '000) | K9: PHYSICAL TARGET | L9: ANNUAL BUDGET (₱ '000)
E10: PHYSICAL TARGET | F10: ANNUAL BUDGET (₱ '000)
A11: I. PRODUCTION AND LIVELIHOOD COMPONENT | D11: =D12+D18+D28+D35 -> 2605.55 | F11: =F12+F18+F28+F35 -> 3040.4 | H11: =H12+H18+H28+H35 -> 1015.82 | J11: =J12+J18+J28+J35 -> 0
A12: 1. Provision of Agricultural Inputs and Livestock | D12: =D14+D18+D28 -> 1427.775 | F12: =F18+F28+F35 -> 1520.2 | H12: =sum(H13:H16) -> 225
A13: 1. Corn and Cassava Related Activity | D13: =D14 -> 250
A14: GM Hybrid Corn Seeds | B14: no. of kg distributed | C14: 50 | D14: 250 | G14: 50 | H14: 225 | M14: San Pablo
A15: b. Inorganic Fertilizer | B15: no. of kg distributed
A16: c. Cassava Seed Pieces | B16: no. of seedpieces distributed
A18: 2. High Value Crops Related Activity | D18: =SUM(D19:D31) -> 977.775 | F18: =SUM(F19:F26) -> 772.7 | H18: =sum(H19:H26) -> 419.82
A19: Upland Vegetables | B19: no. of kg distributed | C19: 1 | D19: 69 | G19: 0.25 | H19: 30 | M19: San Pablo
A20: Lowland Vegetables | B20: no. of kg distributed | C20: 14.5 | D20: 74.875 | E20: 25.2 | F20: 52.7 | G20: 11.2 | H20: 69.82 | M20: San Pablo
A21: Fruit Bearing Trees | B21: no. of pcs distributed | C21: 980 | D21: 183.9 | E21: 600 | F21: 95
A22: Organic Fertilizer | B22: no. of kg distributed | G22: 40 | H22: 20 | M22: San Pablo
A23: Ube Planting Materials | B23: no. of kg distributed | C23: 1000 | D23: 300 | E23: 2500 | F23: 625 | G23: 1000 | H23: 300 | M23: San Pablo
A24: Ginger Planting Materials | B24: no. of kg distributed
A25: Taro/Galyang Planting Materials | B25: no. of kg distributed
A26: Banana Planting Materials | B26: no. of pcs distributed | C26: 250 | D26: 30
A28: 3. Livestock Related Activity | C28: - | D28: =SUM(D29:D33) -> 200 | F28: =SUM(F29:F33) -> 700
A29: a. Native Chicken | B29: no. of head distributed | C29: - | D29: - | E29: 200 | F29: 120
A30: b. Duck | B30: no. of head distributed | E30: 200 | F30: 140
A31: c. Carabao | B31: no. of head distributed | C31: 2 | D31: 120 | E31: 4 | F31: 240
A32: d. Native/Upgraded Pig | B32: no. of head distributed
A33: e. Goat | C33: 10 | D33: 80 | E33: 20 | F33: 200
A35: 4. Agricultural Machineries Tools and Equipments | F35: =F41+F42 -> 47.5 | H35: =sum(H36:H43) -> 371
A36: a. Hand Tractor with Implement | B36: No. of units | G36: 1 | H36: 300 | M36: San Pablo
A37: b. Motorized Boat | B37: No. of units
A38: c. Micro Tiller | B38: No. of units
A39: d. Knapsack | B39: No. of units | G39: 4 | H39: 10 | M39: San Pablo
A40: e. Grass Cutter | B40: No. of units | G40: 1 | H40: 25 | M40: San Pablo
A41: f. Garden Hose | E41: 10 | F41: 30
A42: g. Plastic Mulch | E42: 5 | F42: 17.5
A43: h. Garden Tools | G43: 34 | H43: 36 | M43: San Pablo
A44: i. Pump and Engine Set
...

Sheet MCRA
A1: DEPARTMENT OF AGRICULTURE-REGIONAL FIELD OFFICE NO. 02
A2: CY 2025 & FY 2026 PROGRAM ACCOMPLISHMENTS/STATUS AND FY 2027 PLAN AND BUDGET PROPOSAL | H2: Note: Kindly fill out 2027 Proposal (Tier 1 &2) and indicate on the Column M the target municipalities for each Programs/Activities/Projects. Also, Please double check the amounts indicated in FY 2026 GAA.
A3: MAINSTREAMING CLIMATE RESILIENT AGRICULTURE (MCRA) TO THE REGIONAL PROGRAMS & PROJECTS
A4: PROVINCE: ISABELA
A5: DISTRICT: I
A7: PROGRAM/SUBPROGRAM/ INDICATORS | B7: UNIT OF MEASURE | C7: FY 2025 GAA | E7: FY 2026 GAA | G7: FY 2027 PROPOSAL | M7: Remarks (Breakdown of Municipality Target for FY 2027 )
C8: PHYSICAL TARGET | D8: ANNUAL BUDGET (₱ '000) | G8: TIER 1 | I8: TIER 2 | K8: TOTAL
E9: ACCOMPLISHMENT | G9: PHYSICAL TARGET | H9: ANNUAL BUDGET (₱ '000) | I9: PHYSICAL TARGET | J9: ANNUAL BUDGET (₱ '000) | K9: PHYSICAL TARGET | L9: ANNUAL BUDGET (₱ '000)
E10: PHYSICAL TARGET | F10: ANNUAL BUDGET (₱ '000)
A11: TECHNICAL AND SUPPORT SEVICES PROGRAM
A12: I. Production Support Services Sub-Program | D12: =D13 -> 1597 | F12: =F13+F41 -> 10717.304
A13: A. Productivity-Enhancing/Processing Technologies | D13: =SUM(D14:D40) -> 1597
A14: Mushroom house, Fruiting Bags, and Equipment | B14: Number
A15: Hauling Truck | B15: Number
A16: Impulse Plastic Bag Sealer | B16: Number | C16: 1 | D16: 10
A17: Shading Net | B17: Number | C17: 5 | D17: 100
A18: Seedling Rack | B18: Number | C18: 6 | D18: 90
A19: Digital Weighing Scale | B19: Number | C19: 1 | D19: 10
A20: Feed mixer | B20: Number | C20: 1 | D20: 135
A21: Pelletizer | B21: Number | C21: 1 | D21: 65
A22: Plastic mulch | B22: Number | C22: 4 | D22: 30
A24: Multifunction-tiller/cultivator (long foong) | B24: Number
A25: Rotary tilling type hand tractor | B25: Number | C25: 1 | D25: 100
A26: Shredder | B26: Number | C26: 1 | D26: 33
A27: Ready to Lay Chicken | B27: heads | C27: 335 | D27: 266
A28: Poultry Feeds | B28: bags | C28: 67 | D28: 133
A29: Biologics | B29: boxes | C29: 66 | D29: 25
A30: Fruiting bags | B30: pcs | C30: 4748 | D30: 300
A31: Assorted vegetables | B31: Number | C31: 3 | D31: 300
A32: Provision Inorganic Fertilizer | B32: bags | I32: 50 | J32: 100 | M32: City of Ilagan
A33: Provision of Organic Fertilizer | B33: bags | I33: 100 | J33: 100 | M33: City of Ilagan
A34: Provision of Assorted vegetable seeds | B34: packs | I34: 200 | J34: 50 | M34: City of Ilagan
A35: Provision of Free-Range Chicken | B35: heads | I35: 100 | J35: 70 | M35: City of Ilagan
A36: Provision of MungBean | B36: packs | I36: 80 | J36: 8 | M36: City of Ilagan
A37: Provision of Swine | B37: heads | I37: 18 | J37: 180 | M37: City of Ilagan Cabagan
A38: Provision of Feeds | B38: bags | I38: 36 | J38: 80 | M38: City of Ilagan Cabagan
A39: Provision of Hauling Truck | B39: unit | I39: 1 | J39: 2200 | M39: City of Ilagan
A40: Provision of Assorted vegetable seeds | B40: packs | I40: 57 | J40: 57.14 | M40: Cabagan
A41: B. Sustained AMIA CREATE | F41: =sum(F42:F45,F47:F56) -> 10717.304
A42: - Sheep | B42: heads
...

Sheet NSHP
A1: DEPARTMENT OF AGRICULTURE-REGIONAL FIELD OFFICE NO. 02
A2: CY 2025 & FY 2026 PROGRAM ACCOMPLISHMENTS/STATUS AND FY 2027 PLAN AND BUDGET PROPOSAL | P2: Note: Kindly fill out 2027 Proposal (Tier 1 &2) and indicate on the Column M the target municipalities for each Programs/Activities/Projects. Also, Please double check the amounts indicated in FY 2026 GAA.
A3: NATIONAL SOIL HEALTH PROGRAM
A4: PROVINCE: ISABELA
A5: DISTRICT: 1
A7: PROGRAM/SUBPROGRAM/ INDICATORS | B7: UNIT OF MEASURE | C7: FY 2025 GAA | E7: FY 2026 PROPOSAL | K7: FY 2026 RECOMMENDED BUDGET | M7: FY 2026 GAA | O7: FY 2027 PROPOSAL | U7: Remarks (Breakdown of Municipality Target for FY 2027 )
E8: TIER 1 | G8: TIER 2 | I8: TOTAL | O8: TIER 1 | Q8: TIER 2 | S8: TOTAL
C9: ACCOMPLISHMENT | E9: PHYSICAL TARGET | F9: ANNUAL BUDGET (₱ '000) | G9: PHYSICAL TARGET | H9: ANNUAL BUDGET (₱ '000) | I9: PHYSICAL TARGET | J9: ANNUAL BUDGET (₱ '000) | M9: ACCOMPLISHMENT | O9: PHYSICAL TARGET | P9: ANNUAL BUDGET (₱ '000) | Q9: PHYSICAL TARGET | R9: ANNUAL BUDGET (₱ '000) | S9: PHYSICAL TARGET | T9: ANNUAL BUDGET (₱ '000)
C10: PHYSICAL | D10: BUDGET (Actual Obligation) | K10: PHYSICAL TARGET | L10: ANNUAL BUDGET (₱ '000) | M10: PHYSICAL TARGET | N10: ANNUAL BUDGET (₱ '000)
A11: National Soil Health Program (Tier II)
A12: I. Operation of Regional Soil Laboratories in support to NSHP Activities
A13: 1.1 Soil Analysis | B13: number of samples | E13: 27 | F13: 170 | I13: =E13+G13 -> 27 | J13: =F13+H13 -> 170 | K13: 27 | L13: 170 | M13: 27 | N13: 170
A14: 1.2 Fertilizer Analysis | B14: number of samples | E14: 9 | F14: 81 | I14: =E14+G14 -> 9 | J14: =F14+H14 -> 81 | K14: 9 | L14: 81 | M14: 9 | N14: 81
A15: 1.3 Plant Tissue Analysis | B15: number of samples | E15: 5 | F15: 90 | I15: =E15+G15 -> 5 | J15: =F15+H15 -> 90 | K15: 5 | L15: 90 | M15: 5 | N15: 90
A16: 1.4 Participation to Proficiency Testing | B16: Number of PT participated | F16: 0 | I16: =E16+G16 -> 0 | J16: =F16+H16 -> 0 | L16: 0 | N16: 0
A17: 1.5 STK Production/distribution | B17: number of STK Produced/ distributed | E17: 27 | F17: 39 | I17: =E17+G17 -> 27 | J17: =F17+H17 -> 39 | K17: 27 | L17: 39 | M17: 27 | N17: 39
A18: 1.6 Maintenance of Regulatory/Statutory issuances acquired | B18: number of regulatory/ statutory issuances acquired/ maintained
A20: II. Operation of Mobile Soil Laboratory
A21: 2.1 Soil Chemical Analysis (STK/Chemical) | B21: no. of sample analyzed | E21: 170 | F21: 118 | I21: =E21+G21 -> 170 | J21: =F21+H21 -> 118 | K21: 170 | L21: 118 | M21: 170 | N21: 118
A22: 2.2. Soil Physical Analysis | B22: no. of sample analyzed | E22: 25 | F22: 109 | I22: =E22+G22 -> 25 | J22: =F22+H22 -> 109 | K22: 25 | L22: 109 | M22: 25 | N22: 109
A23: 2.3 Soil Microbiological Analysis | B23: no. of sample analyzed | E23: 25 | F23: 109 | I23: =E23+G23 -> 25 | J23: =F23+H23 -> 109 | K23: 25 | L23: 109 | M23: 25 | N23: 109
A24: 2.4 Distribution of Soil Health card | B24: no. of Soil Health Card distributed | E24: 170 | F24: 56 | I24: =E24+G24 -> 170 | J24: =F24+H24 -> 56 | K24: 170 | L24: 56 | M24: 170 | N24: 56
A25: 2.5 Trainings conducted | B25: no. of training conducted | E25: 1 | F25: 250 | I25: =E25+G25 -> 1 | J25: =F25+H25 -> 250 | K25: 1 | L25: 250 | M25: 1 | N25: 250
A26: GRAND TOTAL | F26: =SUM(F13:F25) -> 1022 | J26: =SUM(J13:J25) -> 1022 | L26: =SUM(L13:L25) -> 1022 | N26: =SUM(N13:N25) -> 1022
A28: Prepared by: | C28: Prepared by: | G28: In coordination with: | N28: Concurred by:
A33: BERNADETTE T. GALOSO | C33: BERNADETTE T. GALOSO | G33: MACARIO B. ANDAL, CPA | N33: ROSE MARY G. AQUINO, Ph.D.
A34: Chief, PMED | C34: Chief, PMED | G34: Chief, Budget Section | N34: Regional Executive Director

Sheet 2025-2027
A1: CY 2025, FY 2026, AND FY 2027 BUDGET SUMMARY (₱ '000)
A2: REGION 02
A3: ISABELA PROVINCE
A4: DISTRICT I
A7: PROGRAM/PROJECT FUND SOURCE | B7: CY 2025 GAA | C7: FY 2026 GAA | D7: FY 2027 PROPOSAL | G7: Variance | H7: % Change (Increase/Decrease)
D8: TIER 1 | E8: TIER 2 | F8: TOTAL
A9: National Rice Program | B9: =RICE!D60 -> 151856.8 | C9: =RICE!F60 -> 329711.17 | D9: =RICE!H60 -> 348197.5 | E9: =RICE!J60 -> 146692.63 | F9: =D9+E9 -> 494890.13 | G9: =F9-C9 -> 165178.96 | H9: =(G9/C9)*100 -> 50.098077
A10: National Corn Program | B10: =CORN!D87 -> 133654.33 | C10: =CORN!F87 -> 121670.92 | D10: =CORN!H87 -> 296172.6 | E10: =CORN!J87 -> 230317.2 | F10: =D10+E10 -> 526489.8 | G10: =F10-C10 -> 404818.88 | H10: =(G10/C10)*100 -> 332.71622
A11: National High Value Crops Development Program | B11: =HVCDP!D781 -> 2954.5 | C11: =HVCDP!F781 -> 3274.715 | D11: =HVCDP!H781 -> 10338.982 | E11: =HVCDP!J781 | F11: =D11+E11 -> 10338.982 | G11: =F11-C11 -> 7064.2668 | H11: =(G11/C11)*100 -> 215.72158
A12: National Urban and Peri-Urban Agriculture Program | B12: =NUPAP!D60 -> 3384.3187 | C12: =NUPAP!F60 -> 2812.5 | D12: =NUPAP!H60 -> 4380 | E12: =NUPAP!J60 -> 0 | F12: =D12+E12 -> 4380 | G12: =F12-C12 -> 1567.5 | H12: =(G12/C12)*100 -> 55.733333
A13: National Livestock Program | B13: =LIVESTOCK!D50 -> 4052.89 | C13: =LIVESTOCK!F50 -> 6722.2 | D13: =LIVESTOCK!H50 -> 18880.005 | E13: =LIVESTOCK!J50 -> 0 | F13: =D13+E13 -> 18880.005 | G13: =F13-C13 -> 12157.805 | H13: =(G13/C13)*100 -> 180.86051
A14: National Organic Agriculture Program | B14: =OAP!F57 -> 6950 | C14: =OAP!H57 -> 1050 | D14: =OAP!R57 -> 2200 | E14: =OAP!T57 | F14: =D14+E14 -> 2200 | G14: =F14-C14 -> 1150 | H14: =(G14/C14)*100 -> 109.52381
A15: HALAL Food Industry Development Program | B15: =HALAL!D25 -> 200 | C15: =HALAL!F25 -> 175 | D15: =HALAL!H25 | E15: =HALAL!J25 | F15: =D15+E15 -> 0 | G15: =F15-C15 -> -175 | H15: =(G15/C15)*100 -> -100
A16: Locally Funded Projects | F16: =D16+E16 -> 0
A17: Farm-to-Market Road (FMR) Development Program | B17: =FMR!E71 -> 345000 | C17: =FMR!E322 -> 500000 | D17: =FMR!E331 -> 155000 | E17: =FMR!E343 -> 292200 | F17: =D17+E17 -> 447200 | G17: =F17-C17 -> -52800 | H17: =(G17/C17)*100 -> -10.56
A18: Kabuhayan at Kaunlaran ng Kababayang Katutubo (4Ks) Program | B18: ='4Ks'!D58 -> 2605.55 | C18: ='4Ks'!F58 -> 3040.4 | D18: ='4Ks'!H58 -> 1015.82 | E18: ='4Ks'!J58 -> 0 | F18: =D18+E18 -> 1015.82 | G18: =F18-C18 -> -2024.58 | H18: =(G18/C18)*100 -> -66.589265
A19: Mainstreaming Climate Resilient Agriculture (MCRA) to the Regional Programs & Projects | B19: =MCRA!D63 -> 1597 | C19: =MCRA!F63 -> 10717.304 | D19: =MCRA!H63 | E19: =MCRA!J63 -> 2845.14 | F19: =D19+E19 -> 2845.14 | G19: =F19-C19 -> -7872.164 | H19: =(G19/C19)*100 -> -73.452839
A20: National Soil Health Program | B20: =NSHP!D26 | C20: =NSHP!N26 -> 1022 | D20: =NSHP!P26 | E20: =NSHP!R26 | F20: =D20+E20 -> 0 | G20: =F20-C20 -> -1022 | H20: =(G20/C20)*100 -> -100
A21: Foreign Assisted Project | F21: =D21+E21 -> 0
A22: Philippine Rural Development Projects* | B22: =PRDP!E11 -> 15000 | F22: =D22+E22 -> 0
A23: TOTAL | B23: =SUM(B9:B22) -> 667255.39 | C23: =SUM(C9:C22) -> 980196.21 | D23: =SUM(D9:D22) -> 836184.9 | E23: =SUM(E9:E22) -> 672054.97 | F23: =D23+E23 -> 1508239.9 | G23: =F23-C23 -> 528043.66 | H23: =(G23/C23)*100 -> 53.871221
A25: Prepared by: | C25: In coordination with | F25: Concurred by:
A30: BERNADETTE T. GALOSO | C30: MACARIO B. ANDAL, CPA | F30: ROSE MARY G. AQUINO, Ph.D.
A31: Chief, PMED | C31: Chief, Budget Section | F31: Regional Executive Director
