Workbook

Sheet RICE

Sheet CORN
A1: DEPARTMENT OF AGRICULTURE-REGIONAL FIELD OFFICE NO. 02
A2: CY 2023-2024 PROGRAM ACCOMPLISHMENTS/STATUS AND FY 2025 PLAN AND BUDGET BASED ON NEP (₱ '000)
A3: CORN PROGRAM
A4: PROVINCE: BATANES
A5: DISTRICT: LONE
A7: PROGRAM/SUBPROGRAM/ INDICATORS | B7: UNIT OF MEASURE | C7: CY 2023 GAA | E7: FY 2024 GAA | G7: FY 2025 PROPOSAL
C8: ACCOMPLISHMENT | E8: ANNUAL PHYSICAL TARGET | F8: ANNUAL BUDGET | G8: TIER 1 | I8: TIER 2 | K8: TOTAL
C9: PHYSICAL | D9: ACTUAL OBLIGATION | G9: PHYSICAL TARGET | H9: BUDGET | I9: PHYSICAL TARGET | J9: BUDGET | K9: PHYSICAL TARGET | L9: BUDGET
A11: PRODUCTION SUPPORT SERVICES | D11: =SUM(D12:D33) -> 0 | F11: =SUM(F12:F33) -> 0 | H11: =SUM(H12:H33) -> 0 | J11: =SUM(J12:J33) -> 0 | L11: =SUM(L12:L33) -> 0
A12: Registered Seed (RS) Production
A13: Flint | K13: =G13+I13 -> 0 | L13: =H13+J13 -> 0
A14: Glutinous | K14: =G14+I14 -> 0 | L14: =H14+J14 -> 0
A15: Recommended Corn Production Technologies (RCPT)
A16: Hybrid | B16: kilograms | K16: =G16+I16 -> 0 | L16: =H16+J16 -> 0
A17: Inorganic Fertilizer | B17: kilograms | K17: =G17+I17 -> 0 | L17: =H17+J17 -> 0
A18: Bio-N | B18: packs | K18: =G18+I18 -> 0 | L18: =H18+J18 -> 0
A19: Agricultural Lime | B19: kilograms | K19: =G19+I19 -> 0 | L19: =H19+J19 -> 0
A20: Corn Production Enhancement Project (CPEP)
A21: Hybrid | K21: =G21+I21 -> 0 | L21: =H21+J21 -> 0
A22: Inorganic Fertilizer | K22: =G22+I22 -> 0 | L22: =H22+J22 -> 0
A23: Bio-N
A24: Support to Cassava
A25: Production of cassava seed pieces | B25: pieces | K25: =G25+I25 -> 0 | L25: =H25+J25 -> 0
A26: Procurement of cassava seed pieces | B26: pieces | K26: =G26+I26 -> 0 | L26: =H26+J26 -> 0
A27: Procurement of Inorganic Fertilizer | B27: kilograms | K27: =G27+I27 -> 0 | L27: =H27+J27 -> 0
A28: Support to Sorghum
A29: Sorghum Seeds | B29: kilograms | K29: =G29+I29 -> 0 | L29: =H29+J29 -> 0
A30: Inorganic Fertilizer | B30: kilograms | K30: =G30+I30 -> 0 | L30: =H30+J30 -> 0
A31: Support to Soybean
A32: Soybean Seeds | B32: kilograms | K32: =G32+I32 -> 0 | L32: =H32+J32 -> 0
A33: Inorganic Fertilizer | B33: kilograms | K33: =G33+I33 -> 0 | L33: =H33+J33 -> 0
A35: AGRICULTURAL MACHINERY, EQUIPMENT AND FACILITIES SUPPORT SERVICES | D35: =SUM(D36:D63) -> 0 | F35: =SUM(F36:F63) -> 0 | H35: =SUM(H36:H63) -> 0 | J35: =SUM(J36:J63) -> 0 | L35: =SUM(L36:L63) -> 0
A36: Four-wheel drive tractor for Corn (90-95HP) | B36: number | K36: =G36+I36 -> 0 | L36: =H36+J36 -> 0
A37: Four-wheel drive tractor for Cassava (90-95HP) | B37: number | K37: =G37+I37 -> 0 | L37: =H37+J37 -> 0
A38: Forage Chopper | B38: number | K38: =G38+I38 -> 0 | L38: =H38+J38 -> 0
A39: Double-row Corn Planter | B39: number | K39: =G39+I39 -> 0 | L39: =H39+J39 -> 0
A40: Mechanical Four-row Planter | B40: number | K40: =G40+I40 -> 0 | L40: =H40+J40 -> 0
A41: Pneumatic Four-row Planter | B41: number | K41: =G41+I41 -> 0 | L41: =H41+J41 -> 0
A42: Hand Tractor with Corn Planter | B42: number | K42: =G42+I42 -> 0 | L42: =H42+J42 -> 0
A43: Soybean Seeder (9-rows) | B43: number | K43: =G43+I43 -> 0 | L43: =H43+J43 -> 0
...

Sheet HVCDP
A1: DEPARTMENT OF AGRICULTURE-REGIONAL FIELD OFFICE NO. 02 | B1: DEPARTMENT OF AGRICULTURE-REGIONAL FIELD OFFICE NO. 02
A2: CY 2025 & FY 2026 PROGRAM ACCOMPLISHMENTS/STATUS AND FY 2027 PLAN AND BUDGET PROPOSAL
A3: HIGH VALUE CROPS DEVELOPMENT PROGRAM
A4: PROVINCE: BATANES
A5: DISTRICT: LONE DISTRICT
A7: PROGRAM/SUBPROGRAM/ INDICATORS | B7: UNIT OF MEASURE | C7: CY 2025 GAA | E7: FY 2026 GAA | G7: FY 2027 PROPOSAL | M7: Remarks (Breakdown of Municipality Target for FY 2027 )
G8: TIER 1 | I8: TIER 2 | K8: TOTAL
C9: ANNUAL PHYSICAL TARGET | D9: BUDGET (Actual Obligation in ₱ '000) | E9: ACCOMPLISHMENT | G9: PHYSICAL TARGET | H9: ANNUAL BUDGET (₱ '000) | I9: PHYSICAL TARGET | J9: ANNUAL BUDGET (₱ '000) | K9: PHYSICAL TARGET | L9: ANNUAL BUDGET (₱ '000)
E10: PHYSICAL TARGET | F10: ANNUAL BUDGET (₱ '000)
A11: OPERATIONS | D11: =D12+D625 -> 5625.71
A12: I. TECHNICAL AND SUPPORT SEVICES PROGRAM | D12: =D13 -> 5025.71 | F12: 9435.71 | H12: =H13 -> 8020 | L12: =L13 -> 8020
A13: A. Production Support Services Sub-Program | D13: =D46+D326+D327+D330+D433 -> 5025.71 | F13: =F46+F327+F433 -> 9435.71 | H13: =H46+H327+H433 -> 8020 | L13: =L46+L327+L433 -> 8020
A14: Outcome Indicators
A15: Beneficiaries rating the production support services (PSS) delivered to be at least satisfactory
A16: Deliveries of producrtion support services validated by LGU's to have been delivered at the appropriate time
A17: Output Indicators
A18: LGU's assisted with production support services
A19: Input Indicators
A20: Seed Distribution
A21: Procured
A22: Produced
A23: Distributed
A24: Area Planted
A25: Mungbean
... A45: Garlic
A46: Procured | B46: kilogram | C46: 20000 | D46: 4000 | E46: 35000 | F46: 8750 | G46: 28000 | H46: =G46*0.25 -> 7000 | K46: 28000 | L46: =K46*0.25 -> 7000
A47: Produced | B47: kilogram
A48: Distributed | B48: kilogram | C48: 20000 | E48: 15000 | G48: =G46 -> 28000 | K48: =K46 -> 28000
A49: Area Planted | B49: hectare | C49: 28.57 | E49: 21.428571 | G49: =G48/700 -> 40 | K49: =K48/700 -> 40
A50: Yellow Onion
A51: Procured
A52: Produced
A53: Distributed
A54: Area Planted
A55: Shallot
A56: Procured
A57: Produced
A58: Distributed
A59: Area Planted
A60: Red Onion
...

Sheet NUPAP
A1: DEPARTMENT OF AGRICULTURE-REGIONAL FIELD OFFICE NO. 02
A2: CY 2025 & FY 2026 PROGRAM ACCOMPLISHMENTS/STATUS AND FY 2027 PLAN AND BUDGET PROPOSAL
A3: NATIONAL URBAN AND PERI-URBAN AGRICULTURE PROGRAM
A4: PROVINCE: BATANES
A5: DISTRICT: LONE
A7: PROGRAM/SUBPROGRAM/ INDICATORS | B7: UNIT OF MEASURE | C7: CY 2025 GAA | E7: FY 2026 GAA | G7: FY 2027 PROPOSAL | M7: Remarks (Breakdown of Municipality Target for FY 2027 )
G8: TIER 1 | I8: TIER 2 | K8: TOTAL
C9: ANNUAL PHYSICAL TARGET | D9: BUDGET (Actual Obligation in ₱ '000) | E9: ACCOMPLISHMENT | G9: PHYSICAL TARGET | H9: ANNUAL BUDGET (₱ '000) | I9: PHYSICAL TARGET | J9: ANNUAL BUDGET (₱ '000) | K9: PHYSICAL TARGET | L9: ANNUAL BUDGET (₱ '000)
E10: PHYSICAL TARGET | F10: ANNUAL BUDGET (₱ '000)
A11: I. TECHNICAL AND SUPPORT SEVICES PROGRAM | D11: =D12 -> 194.94733 | F11: =F12 -> 30 | M11: No Targets for FY 2027. Targets are only for AMEFSS
A12: A. Production Support Services Sub-Program | D12: =SUM(D14:D32) -> 194.94733 | F12: =SUM(F14:F32) -> 30
A13: 1. Seeds Procured for Distribution
A14: Lowland Vegetables | B14: kilograms distributed | C14: 4 | D14: 51.28204
A15: Highland Vegetables | B15: kilograms distributed | C15: 4 | D15: 51.28204
A16: 2. Planting Materials for Distribution
A17: Fruit Bearing Tree (seedlings) | B17: pieces
A18: Strawberry cuttings (cuttings) | B18: pieces | C18: 50 | D18: 3.8095
A19: Ginger
A20: Mango
A21: 3. Soil Mix/Fertilizer:
A22: Organic Fertilizer - solid | B22: kilograms distributed | C22: 1500 | D22: 19.05 | E22: 60 | F22: 30
A23: Soilless Media/Potting Mix | B23: kilograms distributed | C23: 1125 | D23: 16.66665
A24: Foliar Fertilizer
A25: 4. Other Farm Inputs
A26: Seedling Tray | B26: pieces
A27: Plastic Crate | B27: pieces
A28: Stackable pots | B28: pieces | C28: 10 | D28: 38.0952
A29: Plastic Drum | B29: number
A30: Wheel Barrow | B30: number
A31: Hauling Truck | B31: number
A32: Plastic mulch | B32: number | C32: 5 | D32: 14.7619
A33: B. Extension Support, Education and Training Services Sub-Program
A35: II. AGRICULTURAL MACHINERY, EQUIPMENT, FACILITES AND INFRASTRUCTURE PROGRAM | D35: =D36 -> 0 | F35: =F36 -> 2762
A36: A. Agricultural Machinery, Equipment and Facilities Support Services Sub-Program | D36: =SUM(D37:D45) -> 0 | F36: =SUM(F38:F45) -> 2762
A37: 1. Farm production-related machinery and equipment distributed
A38: Soil Auger | B38: number | E38: 1 | F38: 47
A39: Mini-tilling Machine | B39: number
A40: Multicultivator | E40: 1 | F40: 100
A41: 2. Other Facilities and Activities
A42: Poultry Housing with Module | B42: number | E42: 1 | F42: 315
...

Sheet LIVESTOCK
A1: DEPARTMENT OF AGRICULTURE-REGIONAL FIELD OFFICE NO. 02 | B1: DEPARTMENT OF AGRICULTURE-REGIONAL FIELD OFFICE NO. 02
A2: CY 2025 & FY 2026 PROGRAM ACCOMPLISHMENTS/STATUS AND FY 2027 PLAN AND BUDGET PROPOSAL
A3: LIVESTOCK PROGRAM
A4: PROVINCE: BATANES
A5: DISTRICT: LONE
A7: PROGRAM/SUBPROGRAM/ INDICATORS | B7: UNIT OF MEASURE | C7: CY 2025 GAA | E7: FY 2026 GAA | G7: FY 2027 PROPOSAL | M7: Remarks (Breakdown of Municipality Target for FY 2027 )
G8: TIER 1 | I8: TIER 2 | K8: TOTAL
C9: ANNUAL PHYSICAL TARGET | D9: BUDGET (Actual Obligation in ₱ '000) | E9: ACCOMPLISHMENT | G9: PHYSICAL TARGET | H9: ANNUAL BUDGET (₱ '000) | I9: PHYSICAL TARGET | J9: ANNUAL BUDGET (₱ '000) | K9: PHYSICAL TARGET | L9: ANNUAL BUDGET (₱ '000)
E10: PHYSICAL TARGET | F10: ANNUAL BUDGET (₱ '000)
A11: I. TECHNICAL AND SUPPORT SEVICES PROGRAM | D11: 405.46 | F11: =F12 -> 405.46 | H11: =H12 -> 1630 | L11: =L12 -> 1630
A12: A. Production Support Services Sub-Program | D12: 405.46 | F12: =SUM(F15:F17) -> 405.46 | H12: =SUM(H15:H24) -> 1630 | L12: =SUM(L15:L24) -> 1630
A13: A.1 National Animal Genetic Resources Improvement Program
A14: 1.1. Unified National Artificial Insemination Program
A15: Cattle | B15: number | C15: 425 | D15: 405.46 | E15: 425 | F15: 405.46 | G15: 250 | H15: =250*0.5 -> 125 | K15: 250 | L15: =250*0.5 -> 125
A16: Goat | B16: number
A17: 2. Philippine Native Animal Development
A18: 2.1. Stock Distribution (Swine) | B18: number
A20: 1.2. Feed Base Development Program
A21: 1. Planting Materials Distributed | B21: number | G21: 70000 | H21: =G21*15/1000 -> 1050 | K21: 70000 | L21: =K21*15/1000 -> 1050
A22: 2. Philippine Native Animal Development
A23: Native Chicken Distribtuion | G23: 660 | H23: =G23*0.5 -> 330 | K23: 660 | L23: =K23*0.5 -> 330
A24: Duck Distribution | G24: 250 | H24: =G24*0.5 -> 125 | K24: 250 | L24: =K24*0.5 -> 125
A25: III. Support to Prevention and Control of Economically Important Diseases
A26: 1. Drug and Biologic Support | B26: doses
A28: II. AGRICULTURAL MACHINERY, EQUIPMENT, FACILITES AND INFRASTRUCTURE PROGRAM | D28: =D29 -> 3800 | F28: =F29 -> 0
A29: A. Agricultural Machinery, Equipment and Facilities Support Services Sub-Program | D29: =D33 -> 3800 | F29: =SUM(F32:F36) -> 0
A30: 1. Production Facilities Established | B30: No. of farm established
A31: 1.1. Livestock Economic Enterprise Development (LEED) | B31: No. of farm established
A32: Cattle Multiplier Farm | B32: No. of farm established
A33: Chicken Multiplier Farm | B33: No. of farm established | C33: 1 | D33: 3800
A34: Honeybee Multiplier Farm | B34: No. of farm established
A35: Goat Multiplier FArm | B35: No. of farm established
A36: Sheep Multiplier Farm | B36: No. of farm established
A37: Rabbit Multiplier Farm
A38: Carabao Multiplier
A39: Swine Clusters under INSPIRE
A41: GRAND TOTAL | D41: =D11+D28 -> 4205.46 | F41: =F28+F12 -> 405.46 | H41: =H11+H28 -> 1630 | J41: =J11+J28 -> 0 | L41: =L11+L28 -> 1630
A43: Prepared by: | E43: In coordination with: | L43: Concurred by:
A48: BERNADETTE T. GALOSO | E48: MACARIO B. ANDAL, CPA | L48: ROSE MARY G. AQUINO, Ph.D.
A49: Chief, PMED | E49: Chief, Budget Section | L49: Regional Executive Director

Sheet OAP
A1: DEPARTMENT OF AGRICULTURE-REGIONAL FIELD OFFICE NO. 02
A2: CY 2025 & FY 2026 PROGRAM ACCOMPLISHMENTS/STATUS AND FY 2027 PLAN AND BUDGET PROPOSAL
A3: ORGANIC AGRICULTURE PROGRAM
A4: PROVINCE: BATANES
A5: DISTRICT: LONE
A7: PROGRAM/SUBPROGRAM/ INDICATORS | B7: UNIT OF MEASURE | C7: CY 2025 GAA | E7: FY 2026 GAA | G7: FY 2027 PROPOSAL | M7: Remarks (Breakdown of Municipality Target for FY 2027 )
G8: TIER 1 | I8: TIER 2 | K8: TOTAL
C9: ANNUAL PHYSICAL TARGET | D9: BUDGET (Actual Obligation in ₱ '000) | E9: ACCOMPLISHMENT | G9: PHYSICAL TARGET | H9: ANNUAL BUDGET (₱ '000) | I9: PHYSICAL TARGET | J9: ANNUAL BUDGET (₱ '000) | K9: PHYSICAL TARGET | L9: ANNUAL BUDGET (₱ '000)
E10: PHYSICAL TARGET | F10: ANNUAL BUDGET (₱ '000)
A11: OPERATIONS | D11: =D12 -> 1450 | F11: =F12 -> 750 | H11: =H12 -> 2100 | L11: =L12 -> 2100
A12: I. TECHNICAL AND SUPPORT SERVICES PROGRAM | D12: =D13 -> 1450 | F12: =F13 -> 750 | H12: =H13 -> 2100 | L12: =L13 -> 2100
A13: I.1. Production Support Services Sub-program | D13: =D20+D27+D35 -> 1450 | F13: =F20+F27+F35 -> 750 | H13: =H20+H27+H37 -> 2100 | L13: =L20+L27+L37 -> 2100
A14: A. On- station seeds production and distribution
A15: a.1. Vegetables | B15: number
A16: Individual provided with vegetable seeds | B16: number
A17: Male | B17: number | C17: 15
A18: Female | B18: number | C18: 15
A19: Group | B19: kg | C19: 1 | E19: 6 | G19: 5 | K19: 5
A20: Assorted Open-pollinated varieties | C20: 35 | D20: 500 | E20: 30 | F20: 400 | G20: 50 | H20: 600 | K20: 50 | L20: 600
B21: kg
A22: a.2. Rice | B22: number
A23: Individual provided with upland rice seeds | B23: number
A24: Male | B24: number | C24: 10
A25: Female | B25: number | C25: 10
A26: Group | C26: 1 | E26: 6
A27: Upland rice | C27: 750 | D27: 500 | E27: 750 | F27: 350 | G27: 2000 | H27: 1000 | K27: 2000 | L27: 1000
B28: kg
A29: a.3. Corn | B29: number
A30: Individual provided with OPV corn seeds | B30: number
A31: Male | B31: number | C31: 10
A32: Female | B32: number | C32: 10
A33: Group | C33: 1
B34: kg
A35: OPV Corn | C35: 500 | D35: 450
A37: Peanut Seeds | G37: 200 | H37: 500 | K37: 200 | L37: 500
A44: B. Farm supplies distributed | B44: Pieces
A45: Seedling Trays (100 holes) | B45: Rolls
A46: UV Plastic 6mil UV polyethylene plastic film for green house (7mX90mx.006 inch)
B47: number
A48: II.2. Extension Support, Education and Training Services Sub-Program
...

Sheet FMR
A1: DEPARTMENT OF AGRICULTURE-REGIONAL FIELD OFFICE NO. 02
A2: CY 2025 & FY 2026 PROGRAM ACCOMPLISHMENTS/STATUS AND FY 2027 PLAN AND BUDGET PROPOSAL
A3: FARM-TO-MARKET ROAD DEVELOPMENT PROGRAM
A4: PROVINCE: BATANES
A5: DISTRICT: LONE
A7: MUNICIPALITY | B7: LOCATION (BARANGAY) | C7: NAME OF PROJECTS | D7: ESTIMATED LENGTH (KM) | E7: ESTIMATED AMOUNT (₱ '000)
A8: CY 2025 GAA
A9: ITBAYAT | B9: Sta. Rosa | C9: Concreting of Viewdeck- Sitio Pasduxan FMR | D9: 1 | E9: 15000
A10: UYUGAN | B10: Kayuganan | C10: Concreting of Gi- Arani- Vadinaran FMR | D10: 1 | E10: 15000
A11: TOTAL | D11: 2 | E11: 30000
A12: FY 2026 GAA
A13: IVANA | B13: San Vicente | C13: Concreting of Vatang-Matu FMR, Brgy. San Vicente, Ivana, Batanes | D13: 1.333 | E13: 20000
A14: ITBAYAT | B14: Sta. Rosa | C14: Concreting of Katuyan, Sta. Rosa FMR, Itbayat, Batanes | D14: 1 | E14: 20000
A15: MAHATAO | B15: Panatayan | C15: Concreting of Chaina-Tayaran-Gidem FMR, Phase III Brgy. Panatayan, Mahatao, Batanes | D15: 0.5 | E15: 10000
A16: BASCO | B16: San Antonio | C16: Construction of Diajang to Divia FMR, Phase I , Brgy. San Antonio, Basco, Batanes | D16: 0.5 | E16: 15000
A17: TOTAL | D17: =SUM(D13:D16) -> 3.333 | E17: =SUM(E13:E16) -> 65000
A18: FY 2027 PROPOSAL (TIER I)
A19: BASCO | B19: Kayvaluganan | C19: Construction of Charatayan-San Miguel Phase II FMR, Brgy. Kayvaluganan, Basco, Batanes | D19: 0.3 | E19: 7500
A20: BASCO | B20: Kayhuvukan | C20: Construction of Vahangsien-Nayep Phase II FMR, Brgy. Kayhuvukan, Basco, Batanes | D20: 0.5 | E20: 12500
A21: BASCO | B21: Kayhuvukan | C21: Construction of Diuran-Satuvang FMR, Brgy. Kayhuvukan, Basco, Batanes | D21: 0.5 | E21: 12500
A22: MAHATAO | B22: Uvoy | C22: Construction of Diseb-Tavadang FMR, Uvoy, Mahatao, Batanes | D22: 0.5 | E22: 12500
A23: IVANA | B23: Radiwan | C23: Construction of San Felix-Racuj FMR, Brgy. Radiwan, Ivana, Batanes | D23: 0.5 | E23: 12500
A24: UYUGAN | B24: Kayvaluganan | C24: Construction of Sumanga-Chavuan FMR, Brgy. Kayvaluganan, Uyugan, Batanes | D24: 0.65 | E24: 16500
A25: UYUGAN | B25: Imnajbu | C25: Construction of Chingteb-Babal FMR Phase III FMR, Brgy. Imnajbu, Uyugan, Isabela | D25: 0.84 | E25: 21000
A26: ITBAYAT | B26: Sta. Maria | C26: Construction of Iñas-Vugayong FMR, Brgy. Sta. Maria, Itbayat, Batanes | D26: 0.9 | E26: 22500
A27: SABTANG | B27: Sinakan | C27: Concreting of Supi-Iraya FMR, Brgy. Sinakan, Sabtang, Batanes | D27: 1 | E27: 25000
A28: ITBAYAT | B28: San Rafael | C28: Construction of Yawran-Riñwan FMR, Brgy. San Rafael, Itbayat, Batanes | D28: 0.5 | E28: 12500
A29: SUBTOTAL | D29: =SUM(D23:D28) -> 4.39 | E29: =SUM(E19:E28) -> 155000
A31: FY 2027 PROPOSAL (TIER II)
A32: SABTANG | B32: Savidug | C32: Construction of Satuvang-Chaninu, Brgy. Savidug FMR Phase III, Brgy. Savidug, Sabtang, Batanes | D32: 0.5 | E32: 16000
A33: SABTANG | B33: Malakdang | C33: Construction of Sitio Riwas-Roro Port, Brgy. Malakdang FMR, Brgy. Malakdang, Sabtang, Batanes | D33: 0.5 | E33: 13500
A34: Itbayat | B34: Raele | C34: Construction of Aran-an-Kaysaysakan, Raele FMR, Brgy. Raele, Itbayat, Batanes | D34: 1 | E34: 23400
A35: Itbayat | B35: Sta. Lucia | C35: Construction of Camaya-Ripused, Sta. Lucia FMR, Brgy. Sta. Lucia, Itbayat, Batanes | D35: 1.1 | E35: 25700
A36: Uyugan | B36: Kayvaluganan | C36: Construction of Chanalan-Mahedhed, Brgy. Kayvaluganan FMR, Brgy. Kayvaluganan, Uyugan, Batanes | D36: 0.77 | E36: 49000
A37: BASCO | B37: San Antonio | C37: Construction of Chinteb-Chahayan FMR, Brgy. San Antonio, Basco, Batanes | D37: 0.5 | E37: 19500
A38: BASCO | B38: Kayvaluganan | C38: Construction of Sapuno-Malakdang FMR, Brgy. Kayvaluganan, Basco, Batanes | D38: 0.5 | E38: 21500
A39: UYUGAN | B39: Imnajbu | C39: Construction of Chingteb-Babal FMR Phase III, Brgy Imnajbu, Uyugan, Batanes | D39: 0.84 | E39: 46200
A40: IVANA | B40: Radiwan | C40: Construction of Nakurang-Tukon-Chatujian, Brgy Radiwan FMR Phase IV, Brgy. Radiwan, Ivana, Batanes | D40: 1 | E40: 48000
A41: IVANA | B41: Tuhel | C41: Construction of Sivukot-Aramain, Brgy Tuhel FMR, Brgy. Tubel, Ivana, Batanes | D41: 0.82 | E41: 39120
A42: SUBTOTAL | D42: =SUM(D38:D41) -> 3.16 | E42: =SUM(E32:E41) -> 301920
...

Sheet SAAD
A1: DEPARTMENT OF AGRICULTURE-REGIONAL FIELD OFFICE NO. 02
A2: CY 2025 & FY 2026 PROGRAM ACCOMPLISHMENTS/STATUS AND FY 2027 PLAN AND BUDGET PROPOSAL
A3: SPECIAL AREA FOR AGRICULTURAL DEVELOPMENT
A4: PROVINCE: BATANES
A5: DISTRICT: LONE
A7: PROGRAM/SUBPROGRAM/ INDICATORS | B7: UNIT OF MEASURE | C7: CY 2025 GAA | E7: FY 2026 GAA | G7: FY 2027 PROPOSAL | M7: Remarks (Breakdown of Municipality Target for FY 2027 )
G8: TIER 1 | I8: TIER 2 | K8: TOTAL
C9: ANNUAL PHYSICAL TARGET | D9: BUDGET (Actual Obligation in ₱ '000) | E9: ACCOMPLISHMENT | G9: PHYSICAL TARGET | H9: ANNUAL BUDGET (₱ '000) | I9: PHYSICAL TARGET | J9: ANNUAL BUDGET (₱ '000) | K9: PHYSICAL TARGET | L9: ANNUAL BUDGET (₱ '000)
E10: PHYSICAL TARGET | F10: ANNUAL BUDGET (₱ '000)
A11: I. SOCIAL PREPARATION | D11: 700 | F11: 500 | H11: 353 | L11: 353
A12: A. Community Needs Assessment (CNA)
A13: a.1 Orientations, Meetings, Assessments and Consultation conducted | B13: number | E13: 1 | G13: 1 | K13: 1 | M13: Basco, Ivana, Itbayat, Uyugan
A14: a.2 Beneficiary Needs Assessment/ Participatory Rural Appraisal (PRA) conducted | B14: group | C14: 1
A15: B. Beneficiary Capacitation and General Development
A16: b.1 Capability Building activities conducted | B16: group | C16: 4 | E16: 4 | G16: 4 | K16: 4 | M16: Basco, Ivana, Itbayat, Uyugan
A17: C. Database and Profiling
A18: c.1 Beneficiary Profiling conducted | B18: group | C18: 4 | E18: 4 | G18: 4 | K18: 4 | M18: Basco, Ivana, Itbayat, Uyugan
A19: c.2 Database Uploading conducted | B19: group | C19: 4 | E19: 4 | G19: 4 | K19: 4 | M19: Basco, Ivana, Itbayat, Uyugan
A21: II. FOOD PRODUCTION AND LIVELIHOOD INTERVENTIONS | D21: =D22+D23 -> 7961 | F21: =F22+F23 -> 2023 | H21: =H22+H23 -> 1555 | L21: =L22 -> 1555
A22: 2.1 HVC-based Project distributed | B22: group | C22: 4 | D22: 7661 | E22: 3 | F22: 1623 | G22: 4 | H22: 1555 | K22: 4 | L22: 1555 | M22: Basco, Ivana, Itbayat, Uyugan
A23: 2.2 Specialized Trainings conducted | B23: number | C23: 5 | D23: 300 | E23: 3 | F23: 400
A25: III. MARKETING ASSISTANCE AND ENTERPRISE DEVELOPMENT | D25: =D26+D27 -> 300 | F25: =F26+F27 -> 400 | H25: 434 | L25: 434
A26: 3.1 Market-related trainings conducted | B26: number | C26: 4 | D26: 300 | E26: 4 | F26: 400 | G26: 4 | K26: 4 | M26: Basco, Ivana, Itbayat, Uyugan
A27: 3.2 Partially established CBEs | B27: group | G27: 3 | K27: 3 | M27: Basco, Ivana, Itbayat, Uyugan
A29: IV. PROGRAM MANAGEMENT | D29: 0 | F29: 0
A30: 4.1. Project Management Offices Maintained
A31: 4.1.1. Hiring/renewal of manpower
A32: A. RPMSO
A33: B. PPMSO
A34: 4.1.2 Office Oprating Requirements
A35: 4.2. Review and Planning Workshop
A36: A. Plan and Budget Preparation (PBP)
A37: B. Budget Execution Document (BED) Preparation
A38: 4.3. Monitoring and Evaluation
A39: 4.3.1. Conduct of Performance and Budget
A40: 4.3.2. Implementation of management information
A41: - Sub-project monitoring
... A45: 4.3.2. Regional Assessment
A47: GRAND TOTAL | D47: =D29+D25+D21+D11 -> 8961 | F47: =F29+F25+F21+F11 -> 2923 | H47: =H11+H21+H25 -> 2342 | L47: =L11+L21+L25 -> 2342
A48: Note: FY 2027 budget allocation for the Social Preparation and MAED is by component.
...

Sheet MCRA
A1: DEPARTMENT OF AGRICULTURE-REGIONAL FIELD OFFICE NO. 02
A2: CY 2025 & FY 2026 PROGRAM ACCOMPLISHMENTS/STATUS AND FY 2027 PLAN AND BUDGET PROPOSAL
A3: PROGRAM: MAINSTREAMING CLIMATE RESILIENT AGRICULTURE (MCRA) TO THE REGIONAL PROGRAMS AND PROJECTS
A4: PROVINCE: BATANES
A5: DISTRICT: LONE
A7: PROGRAM/SUBPROGRAM/ INDICATORS | B7: UNIT OF MEASURE | C7: CY 2025 GAA | E7: FY 2026 GAA | G7: FY 2027 PROPOSAL | M7: Remarks (Breakdown of Municipality Target for FY 2027 )
G8: TIER 1 | I8: TIER 2 | K8: TOTAL
C9: ANNUAL PHYSICAL TARGET | D9: BUDGET (Actual Obligation in ₱ '000) | E9: ACCOMPLISHMENT | G9: PHYSICAL TARGET | H9: ANNUAL BUDGET (₱ '000) | I9: PHYSICAL TARGET | J9: ANNUAL BUDGET (₱ '000) | K9: PHYSICAL TARGET | L9: ANNUAL BUDGET (₱ '000)
E10: PHYSICAL TARGET | F10: ANNUAL BUDGET (₱ '000)
A11: TECHNICAL AND SUPPORT SEVICES PROGRAM
A12: I. Production Support Services Sub-Program
A13: Productivity-Enhancing/Processing Technologies
A14: Push Cart | B14: Number
A15: Jaketted Kettle | B15: Number
A16: Air Burble Washing Machine | B16: Number
A17: Bottle Tilling-type Hand Tractor | B17: Number
A18: Hauling Truck | B18: Number
A20: I. AGRICULTURAL MACHINERY, EQUIPMENT, FACILITES AND INFRASTRUCTURE PROGRAM | D20: =D21 -> 1000
A21: A. Agricultural Machinery, Equipment and Facilities Support Services Sub-Program | D21: =SUM(D22:D26) -> 1000
A22: Four Wheel Drice Tractor | B22: Number
A23: Rice Combine Harvester | B23: Number
A24: Riding type Direct Seeder | B24: Number
A25: Rotary Tilling-type Hand Tractor | B25: Number
A26: Automated Weather System (AWS) established | B26: Number | C26: 1 | D26: 1000
A28: GRAND TOTAL | D28: =D12+D20 -> 1000 | F28: 0 | H28: 0 | J28: 0 | L28: 0
A30: Prepared by: | E30: In coordination with: | L30: Concurred by:
A35: BERNADETTE T. GALOSO | E35: MACARIO B. ANDAL, CPA | L35: ROSE MARY G. AQUINO, Ph.D.
A36: Chief, PMED | E36: Chief, Budget Section | L36: Regional Executive Director

Sheet 4Ks
A1: DEPARTMENT OF AGRICULTURE-REGIONAL FIELD OFFICE NO. 02
A2: CY 2025 & FY 2026 PROGRAM ACCOMPLISHMENTS/STATUS AND FY 2027 PLAN AND BUDGET PROPOSAL
A3: KABUHAYAN AT KAUNLARAN NG KABABAYANG KATUTUBO (4Ks) PROGRAM
A4: PROVINCE: BATANES
A5: DISTRICT: LONE
A7: PROGRAM/SUBPROGRAM/ INDICATORS | B7: UNIT OF MEASURE | C7: CY 2025 GAA | E7: FY 2026 GAA | G7: FY 2027 PROPOSAL | M7: Remarks (Breakdown of Municipality Target for FY 2027 )
G8: TIER 1 | I8: TIER 2 | K8: TOTAL
C9: ANNUAL PHYSICAL TARGET | D9: BUDGET (Actual Obligation in ₱ '000) | E9: ACCOMPLISHMENT | G9: PHYSICAL TARGET | H9: ANNUAL BUDGET (₱ '000) | I9: PHYSICAL TARGET | J9: ANNUAL BUDGET (₱ '000) | K9: PHYSICAL TARGET | L9: ANNUAL BUDGET (₱ '000)
E10: PHYSICAL TARGET | F10: ANNUAL BUDGET (₱ '000)
A11: I. PRODUCTION AND LIVELIHOOD COMPONENT | D11: =SUM(D19:D20) -> 364.5 | F11: =F19+F20 -> 171.4 | H11: =H19+H20 -> 156.728 | L11: =L19+L20 -> 156.728
A12: 1. Provision of Agricultural Inputs and Livestock | D12: =SUM(D13,D18,D28) -> 0
A13: 2.1.1. Corn and Cassava Related Activity
A14: a. GM Hybrid Corn Seeds | B14: no. of kg distributed | D14: -
A15: b. Inorganic Fertilizer | B15: no. of kg distributed | D15: -
A16: c. Cassava Seed Pieces | B16: no. of seedpieces distributed | C16: - | D16: -
C17: - | D17: -
A18: A. High Value Crops Related Activity
A19: Upland Vegetables | B19: no. of kg distributed | C19: 9 | D19: 292.5 | E19: 1.6 | F19: 108.6 | G19: 5.65 | H19: 82.56 | K19: 5.65 | L19: 82.56 | M19: BASCO only
A20: Lowland Vegetables | B20: no. of kg distributed | C20: 13 | D20: 72 | E20: 25.8 | F20: 62.8 | G20: 13.7 | H20: 74.168 | K20: 13.7 | L20: 74.168 | M20: BASCO only
A21: c. Fruit Bearing Trees | B21: no. of pcs distributed | C21: - | D21: -
A22: d. Organic Fertilizer | B22: no. of kg distributed | C22: - | D22: -
A23: Ube Planting Materials | B23: no. of kg distributed
A24: f. Ginger Planting Materials | B24: no. of kg distributed | C24: - | D24: -
A25: g. Taro/Galyang Planting Materials | B25: no. of kg distributed | C25: - | D25: -
A26: h. Banana Planting Materials | B26: no. of pcs distributed | D26: -
C27: - | D27: -
A28: 2.1.3. Livestock Related Activity | C28: - | D28: -
A29: a. Native Chicken | B29: no. of head distributed | C29: - | D29: -
A30: b. Duck | B30: no. of head distributed | C30: - | D30: -
A31: c. Carabao with attach implement | B31: no. of head distributed | C31: - | D31: -
A32: d. Native/Upgraded Pig | B32: no. of head distributed | C32: - | D32: -
C33: - | D33: -
A34: 2.2. Provision of agricultural machineries | C34: - | D34: -
A35: 2.2.1. Corn and Cassava Related Activity | C35: - | D35: -
A36: a. Hand Tractor with planter | B36: no. of unit distributed | C36: - | D36: -
A37: b. Hand Tractor with Two-Row Planter | B37: no. of unit distributed | C37: - | D37: -
A38: c. Power Tiller/Cultivator | B38: no. of unit distributed | C38: - | D38: -
C39: - | D39: -
A40: 2.2.2. Fishery Related Activity | C40: - | D40: -
A41: a. Fishing Boat with Fish Net | B41: no. of unit distributed | C41: - | D41: -
...

Sheet NHSP
A1: DEPARTMENT OF AGRICULTURE-REGIONAL FIELD OFFICE NO. 02
A2: CY 2025 & FY 2026 PROGRAM ACCOMPLISHMENTS/STATUS AND FY 2027 PLAN AND BUDGET PROPOSAL
A3: NATIONAL SOIL HEALTH PROGRAM
A4: PROVINCE: BATANES
A5: DISTRICT: LONE
A7: PROGRAM/SUBPROGRAM/ INDICATORS | B7: UNIT OF MEASURE | C7: CY 2025 GAA | E7: FY 2026 GAA | G7: FY 2027 PROPOSAL | M7: Remarks (Breakdown of Municipality Target for FY 2027 )
G8: TIER 1 | I8: TIER 2 | K8: TOTAL
C9: ANNUAL PHYSICAL TARGET | D9: BUDGET (Actual Obligation in ₱ '000) | E9: ACCOMPLISHMENT | G9: PHYSICAL TARGET | H9: ANNUAL BUDGET (₱ '000) | I9: PHYSICAL TARGET | J9: ANNUAL BUDGET (₱ '000) | K9: PHYSICAL TARGET | L9: ANNUAL BUDGET (₱ '000)
E10: PHYSICAL TARGET | F10: ANNUAL BUDGET (₱ '000)
A11: National Soil Health Program (Tier II)
A12: I. Operation of Regional Soil Laboratories in support to NSHP Activities
A13: 1.1 Soil Analysis | B13: number of samples | C13: 36 | D13: 462.5 | E13: 36 | F13: 226
A14: 1.2 Fertilizer Analysis | B14: number of samples | C14: 5 | D14: 20 | E14: 5 | F14: 45
A15: 1.3 Plant Tissue Analysis | B15: number of samples | C15: 4 | D15: 7.5 | F15: 0
A16: 1.4 Participation to Proficiency Testing | B16: Number of PT participated | F16: 0
A17: 1.5 STK Production/distribution | B17: number of STK Produced/ distributed | E17: 36 | F17: 50
A18: 1.6 Maintenance of Regulatory/Statutory issuances acquired | B18: number of regulatory/ statutory issuances acquired/ maintained | F18: 0
A20: II. Operation of Mobile Soil Laboratory
A21: 2.1 Soil Chemical Analysis (STK/Chemical) | B21: no. of sample analyzed | F21: 0
A22: 2.2. Soil Physical Analysis | B22: no. of sample analyzed | F22: 0
A23: 2.3 Soil Microbiological Analysis | B23: no. of sample analyzed | F23: 0
A24: 2.4 Distribution of Soil Health card | B24: no. of Soil Health Card distributed | F24: 0
A25: 2.5 Trainings conducted | B25: no. of training conducted
A26: GRAND TOTAL | D26: =D13+D14+D15 -> 490 | F26: =SUM(F13:F25) -> 321 | H26: 0 | J26: 0 | L26: 0
A28: Prepared by: | E28: In coordination with: | L28: Concurred by:
A33: BERNADETTE T. GALOSO | E33: MACARIO B. ANDAL, CPA | L33: ROSE MARY G. AQUINO, Ph.D.
A34: Chief, PMED | E34: Chief, Budget Section | L34: Regional Executive Director

Sheet GRAND TOTAL
A2: CY 2025, 2026 AND FY 2027 BUDGET SUMMARY (₱ '000)
A3: REGION 02
A4: BATANES PROVINCE
A5: LONE DISTRICT
A7: PROGRAM/PROJECT FUND SOURCE | B7: CY 2025 GAA | C7: FY 2026 GAA | D7: FY 2027 PROPOSAL | G7: Variance | H7: % Change (Increase/Decrease)
D8: TIER 1 | E8: TIER 2 | F8: TOTAL
A9: Operations
A10: National High Value Crops Development Program | B10: =HVCDP!D793 -> 5625.71 | C10: =HVCDP!F793 -> 11435.71 | D10: =HVCDP!H793 -> 8020 | E10: =HVCDP!J793 -> 0 | F10: =SUM(D10:E10) -> 8020 | G10: =F10-C100 -> 8020 | H10: =G10/C10*100 -> 70.131194
A11: National Urban and Peri-Urban Agriculture Program | B11: =NUPAP!D48 -> 194.94733 | C11: =NUPAP!F48 -> 2792 | D11: =NUPAP!H48 -> 0 | E11: =NUPAP!J48 -> 0 | F11: =SUM(D11:E11) -> 0 | G11: =F11-C11 -> -2792 | H11: =G11/C11*100 -> -100
A12: National Livestock Program | B12: =LIVESTOCK!D41 -> 4205.46 | C12: =LIVESTOCK!F41 -> 405.46 | D12: =LIVESTOCK!H41 -> 1630 | E12: =LIVESTOCK!J41 -> 0 | F12: =SUM(D12:E12) -> 1630 | G12: =F12-C12 -> 1224.54 | H12: =G12/C12*100 -> 302.01253
A13: National Organic Agriculture Program | B13: =OAP!D60 -> 1450 | C13: =OAP!F60 -> 750 | D13: =OAP!H60 -> 2100 | E13: =OAP!J60 -> 0 | F13: =SUM(D13:E13) -> 2100 | G13: =F13-C13 -> 1350 | H13: =G13/C13*100 -> 180
A14: HALAL Development Industry Program | G14: =F14-C14 -> 0 | H14: =G14/C14*100 -> #DIV/0!
A15: Locally Funded Projects
A16: Farm-to-Market Road (FMR) Development Program | B16: =FMR!E11 -> 30000 | C16: =FMR!E17 -> 65000 | D16: =FMR!E29 -> 155000 | E16: =FMR!E42 -> 301920 | F16: =SUM(D16:E16) -> 456920 | G16: =F16-C16 -> 391920 | H16: =G16/C16*100 -> 602.95385
A17: Special Area for Agricultural Development (SAAD) Program | B17: =SAAD!D47 -> 8961 | C17: =SAAD!F47 -> 2923 | D17: =SAAD!H47 -> 2342 | E17: 0 | F17: =SUM(D17:E17) -> 2342 | G17: =F17-C17 -> -581 | H17: =G17/C17*100 -> -19.876839
A18: Kabuhayan at Kaunlaran ng Kababayang Katutubo (4Ks) Program | B18: 364.5 | C18: 171.4 | D18: 156.73 | E18: 0 | F18: =SUM(D18:E18) -> 156.73 | G18: =F18-C18 -> -14.67 | H18: =G18/C18*100 -> -8.5589265
A19: Mainstreaming Climate Resilient Agriculture (MCRA) to the Regional Programs and Projects | B19: =MCRA!D28 -> 1000 | C19: =MCRA!F28 -> 0 | D19: =MCRA!H28 -> 0 | E19: =MCRA!J28 -> 0 | F19: =SUM(D19:E19) -> 0 | G19: =F19-C19 -> 0 | H19: 0
A20: National Soil Health Program | B20: =NHSP!D26 -> 490 | C20: =NHSP!F26 -> 321 | D20: 0 | E20: 0 | F20: =SUM(D20:E20) -> 0 | G20: =F20-C20 -> -321 | H20: =G20/C20*100 -> -100
A21: Foreign Assisted Project | F21: =SUM(D21:E21) -> 0 | G21: =F21-C21 -> 0 | H21: =G21/C21*100 -> #DIV/0!
A22: Philippine Rural Development Projects | F22: =SUM(D22:E22) -> 0 | G22: =F22-C22 -> 0 | H22: =G22/C22*100 -> #DIV/0!
A23: TOTAL | B23: =SUM(B10:B13,B16:B20) -> 52291.617 | C23: =SUM(C10:C13,C16:C20) -> 83798.57 | D23: =SUM(D10:D13,D16:D20) -> 169248.73 | E23: =SUM(E10:E13,E16:E20) -> 301920 | F23: =SUM(D23:E23) -> 471168.73 | G23: =F23-C23 -> 387370.16 | H23: =G23/C23*100 -> 462.26345
A28: Prepared by: | D28: In coordination with: | G28: Concurred by:
A33: BERNADETTE T. GALOSO | D33: MACARIO B. ANDAL, CPA | G33: ROSE MARY G. AQUINO, Ph.D.
A34: Chief, PMED | D34: Chief, Budget Section | G34: Regional Executive Director
