Workbook

Sheet RICE
A1: DEPARTMENT OF AGRICULTURE-REGIONAL FIELD OFFICE NO. 02
A2: CY 2025 & FY 2026 PROGRAM ACCOMPLISHMENTS/STATUS AND FY 2027 PLAN AND BUDGET PROPOSAL
A3: RICE PROGRAM
A4: PROVINCE: NUEVA VIZCAYA
A5: DISTRICT: LONE
A7: PROGRAM/SUBPROGRAM/ INDICATORS | B7: UNIT OF MEASURE | C7: FY 2025 GAA | E7: FY 2026 GAA | G7: FY 2027 PROPOSAL | M7: Remarks (Breakdown of Municipality Target for FY 2027 )
G8: TIER 1 | I8: TIER 2 | K8: TOTAL
C9: ANNUAL PHYSICAL TARGET | D9: BUDGET (Actual Obligation in ₱ '000) | E9: ACCOMPLISHMENT | G9: PHYSICAL TARGET | H9: ANNUAL BUDGET (₱ '000) | I9: PHYSICAL TARGET | J9: ANNUAL BUDGET (₱ '000) | K9: PHYSICAL TARGET | L9: ANNUAL BUDGET (₱ '000)
E10: PHYSICAL TARGET | F10: ANNUAL BUDGET (₱ '000)
A11: I. TECHNICAL AND SUPPORT SERVICES PROGRAM (TSSP) | D11: =D12+D24 -> 169094.59 | F11: =F12+F24 -> 298457 | H11: =H12+H24 -> 148500 | J11: =J12+J24 -> 113686.1 | L11: =L12+L24 -> 262186.1
A12: A. Production Support Services (PSS) | D12: =SUM(D13:D17) -> 169094.59 | F12: =SUM(F14:F23) -> 298457 | H12: =SUM(H14:H23) -> 148500 | J12: =SUM(J14:J23) -> 113686.1 | L12: =SUM(L14:L23) -> 262186.1
A13: Fertilizer Assistance - Ameliorants (solid) | C13: 15198 | D13: 14028.92
A14: Fertilizer Assistance - Bio Fertilizer (pack) | C14: 14028 | D14: 14028
A15: Fertilizer Assistance - inorganic - hybrid area | B15: hectare | C15: 16314 | D15: 55467.6 | E15: 22775 | F15: 77435 | G15: 13500 | H15: 27000 | I15: 1726 | J15: 3452 | K15: =G15+I15 -> 15226 | L15: =H15+J15 -> 30452 | M15: A. Castañeda Ambaguio Aritao Bagabag Bambang Bayombong Diadi Dupax del Norte Dupax del Sur Kasibu Kayapa Quezon Solano Sta. Fe Villaverde
A16: Fertilizer Assistance - inorganic - inbred area | B16: hectare | E16: 30858 | F16: 104917 | G16: 13500 | H16: 27000 | K16: =G16+I16 -> 13500 | L16: =H16+J16 -> 27000
A17: Seed assistance-Commercial Hybrid | B17: hectare | C17: 17114 | D17: 85570.07 | E17: 22775 | F17: 113875 | G17: 13500 | H17: 94500 | I17: 1276 | J17: 12686.1 | K17: =G17+I17 -> 14776 | L17: =H17+J17 -> 107186.1
A18: Drone voucher | K18: =G18+I18 -> 0 | L18: =H18+J18 -> 0
A19: FDV/IMC for Inbred | I19: 26634 | J19: =62528200/1000 -> 62528.2 | K19: =G19+I19 -> 26634 | L19: =H19+J19 -> 62528.2
A20: FDV/IMC for Hybrid | I20: 15226 | J20: 35019.8 | K20: =G20+I20 -> 15226 | L20: =H20+J20 -> 35019.8
A21: Hermetic cocoon
A22: Model Farm Established- hybrid seeds distributed | B22: number | E22: 100 | F22: 700
A23: Model Farm Established- Inorganic fertilizer distributed | B23: number | E23: 100 | F23: 1530
A24: B. Extension Support, Education and Training Services (ESETS) | D24: =D25
A25: Rice Farm Cluster Establishment | B25: site | G25: 5 | H25: 33430 | K25: =G25+I25 -> 5 | L25: =H25+J25 -> 33430
A26: Scale-up Palayamanan for Rice Based Farm | B26: site | G26: 12 | H26: 6000 | K26: =G26+I26 -> 12 | L26: =H26+J26 -> 6000
A28: II. AGRICULTURAL MACHINERY, EQUIPMENT, FACILITIES AND INFRASTRUCTURES PROGRAM (AMEFIP) | D28: =D29+D52 -> 2562.5 | F28: =F29+F52 -> 5100
A29: A. AGRICULTURAL MACHINERY, EQUIPMENT, AND FACILITIES SUPPORT SERVICES (AMEFSS) | D29: =SUM(D31:D49) -> 2562.5 | F29: =SUM(F30:F50) -> 0
A30: 1. Provision of Post-harvest Machinery and Equipment
A31: Vaccum Pack Sealer | B31: number | C31: 1 | D31: 2000
A32: Fork Lift | B32: number | C32: 1 | D32: 562.5
A33: Seed Processing center | B33: number
A34: Rice Processing Center | B34: number
A35: Recirculating Dryer | B35: number
A36: Paddy Rice Hauler | B36: number
A37: Packaging System | B37: number
A38: Combine Harvester | B38: number
A39: 4wd Tractor | B39: number
A40: Seeder | B40: number
A41: 4WD Tractors with accessories | B41: number
A42: Hauling Truck | B42: number
...

Sheet CORN
A1: DEPARTMENT OF AGRICULTURE-REGIONAL FIELD OFFICE NO. 02
A2: CY 2025 & FY 2026 PROGRAM ACCOMPLISHMENTS/STATUS AND FY 2027 PLAN AND BUDGET PROPOSAL
A3: CORN PROGRAM
A4: PROVINCE: NUEVA VIZCAYA
A5: DISTRICT: LONE
A7: PROGRAM/SUBPROGRAM/ INDICATORS | B7: UNIT OF MEASURE | C7: FY 2025 GAA | E7: FY 2026 GAA | G7: FY 2027 PROPOSAL | M7: Remarks (Breakdown of Municipality Target for FY 2027 )
G8: TIER 1 | I8: TIER 2 | K8: TOTAL
C9: ANNUAL PHYSICAL TARGET | D9: BUDGET (Actual Obligation in ₱ '000) | E9: ACCOMPLISHMENT | G9: PHYSICAL TARGET | H9: ANNUAL BUDGET (₱ '000) | I9: PHYSICAL TARGET | J9: ANNUAL BUDGET (₱ '000) | K9: PHYSICAL TARGET | L9: ANNUAL BUDGET (₱ '000)
E10: PHYSICAL TARGET | F10: ANNUAL BUDGET (₱ '000)
A11: I. PRODUCTION SUPPORT SERVICES | D11: =SUM(D12:D32) -> 13593.85 | F11: =SUM(F12:F37) -> 69465 | H11: =SUM(H12:H37) -> 5581 | J11: =SUM(J12:J37) -> 156400 | L11: =SUM(L12:L37) -> 161981
A12: 1. Registered Seed (RS) Production
A13: Flint | B13: kilograms | C13: 2000 | D13: 100
A14: Glutinous | B14: kilograms | C14: 2000 | D14: 100
A15: Inorganic Fertilizer | B15: kilograms
A16: 2. Recommended Corn Production Technologies (RCPT)
A17: Hybrid | B17: kilograms
A18: Inorganic Fertilizer | B18: kilograms
A19: Biofertilizer | B19: packs
A20: Plant Growth Enhancer | B20: packs
A21: Agricultural Lime | B21: kilograms
A22: Complete Foliar Fertilizer | B22: kilograms
A23: 3. Yellow Corn Production Enhancement Project (YCPEP)
A24: Hybrid Seeds (GM) | B24: kilograms | C24: =1800*9 -> 16200 | D24: =10482500/1000 -> 10482.5 | E24: 45090 | F24: 32565 | G24: 2304 | H24: =(G24/9)*6.5 -> 1664 | I24: =6000*18 -> 108000 | J24: =6000*13 -> 78000 | K24: =SUM(G24,I24) -> 110304 | L24: =SUM(H24,J24) -> 79664 | M24: Bagabag, Bambang, Bayombong, Diadi, Dupax del Norte, Kayapa, Kasibu, Quezon, Solano, Villaverde
A25: Inorganic Fertilizer for GM | B25: kilograms | C25: =1800*50 -> 90000 | D25: =(900*1.35)+(900*1.411) -> 2484.9 | E25: 250500 | F25: 10020 | G25: 6400 | H25: =(G25/50)*2 -> 256 | I25: =6000*50 -> 300000 | J25: =6000*2 -> 12000 | K25: =SUM(G25,I25) -> 306400 | L25: =SUM(H25,J25) -> 12256
A26: Hybrid Seeds (Conventional) | B26: kilograms | E26: 30060 | F26: 16700 | G26: 1530 | H26: =(G26/9)*5 -> 850 | I26: =4000*18 -> 72000 | J26: =4000*10 -> 40000 | K26: =SUM(G26,I26) -> 73530 | L26: =SUM(H26,J26) -> 40850
A27: Inorganic Fertilizer for Conventional | B27: kilograms | E27: 167000 | F27: 6680 | G27: 12750 | H27: =(G27/150)*6 -> 510 | I27: =4000*150 -> 600000 | J27: =4000*6 -> 24000 | K27: =SUM(G27,I27) -> 612750 | L27: =SUM(H27,J27) -> 24510
A28: Agricultural Gypsum for Conventional | B28: kilograms | G28: 4250 | H28: =(G28/50)*0.6 -> 51 | I28: =4000*50 -> 200000 | J28: =4000*0.6 -> 2400 | K28: =SUM(G28,I28) -> 204250 | L28: =SUM(H28,J28) -> 2451
A29: 4. Support to Cassava
A30: Production of cassava seed pieces | B30: pieces | C30: 195000 | D30: =C30*1/1000 -> 195 | E30: 325000 | F30: 500 | G30: 325000 | H30: =(G30/65000)*100 -> 500 | K30: =SUM(G30,I30) -> 325000 | L30: =SUM(H30,J30) -> 500 | M30: Bagabag, Bayombong, Quezon
A31: Procurement of cassava seed pieces | B31: pieces | C31: 100000 | D31: =C31*1.5/1000 -> 150
A32: Procurement of Inorganic Fertilizer | B32: kilograms | C32: 2950 | D32: =(29.5*1.35)+(29.5*1.411) -> 81.4495 | E32: 2500 | F32: 100 | G32: 2500 | H32: =(G32/100)*4 -> 100 | K32: =SUM(G32,I32) -> 2500 | L32: =SUM(H32,J32) -> 100 | M32: Bagabag, Bayombong, Quezon
A33: Solar Bubble Dryer | B33: number | E33: 5 | F33: 1250
A34: 5. White Corn Production Enhancement Project (WCPEP)
A35: OPV Flint Corn Seeds | B35: kilograms | E35: 2000 | F35: 150
A36: OPV Glutinous Corn Seeds | B36: kilograms | E36: 4000 | F36: 300 | G36: 6000 | H36: =(150/2000)*G36 -> 450 | K36: =SUM(G36,I36) -> 6000 | L36: =SUM(H36,J36) -> 450 | M36: Diadi, Kayapa, Quezon, Solano
A37: Inorganic Fertilizer | B37: kilograms | E37: 30000 | F37: 1200 | G37: 30000 | H37: =(G37/100)*4 -> 1200 | K37: =SUM(G37,I37) -> 30000 | L37: =SUM(H37,J37) -> 1200 | M37: Diadi, Kayapa, Quezon, Solano
A38: 5. Soybean Production Enhancement Project (SPEP)
A39: Soybean Seeds | B39: kilograms | G39: 700 | H39: =(1200/2000)*G39 -> 420 | K39: =SUM(G39,I39) -> 700 | L39: =SUM(H39,J39) -> 420 | M39: Bagabag, Quezon
A40: Inorganic Fertilizer | B40: kilograms | G40: 2800 | H40: =(G40/100)*4 -> 112 | K40: =SUM(G40,I40) -> 2800 | L40: =SUM(H40,J40) -> 112 | M40: Bagabag, Quezon
A42: II. EXTENSION SUPPORT, EDUCATION & TRAINING SERVICES
...

Sheet HVCDP
A1: DEPARTMENT OF AGRICULTURE-REGIONAL FIELD OFFICE NO. 02
A2: CY 2025 & FY 2026 PROGRAM ACCOMPLISHMENTS/STATUS AND FY 2027 PLAN AND BUDGET PROPOSAL
A3: HIGH VALUE CROPS DEVELOPMENT PROGRAM
A4: PROVINCE: NUEVA VIZCAYA
A5: DISTRICT: LONE
A7: PROGRAM/SUBPROGRAM/ INDICATORS | B7: UNIT OF MEASURE | C7: FY 2025 GAA | E7: FY 2026 GAA | G7: FY 2027 PROPOSAL | M7: Remarks (Breakdown of Municipality Target for FY 2027 )
G8: TIER 1 | I8: TIER 2 | K8: TOTAL
C9: ANNUAL PHYSICAL TARGET | D9: BUDGET (Actual Obligation in ₱ '000) | E9: ACCOMPLISHMENT | G9: PHYSICAL TARGET | H9: ANNUAL BUDGET (₱ '000) | I9: PHYSICAL TARGET | J9: ANNUAL BUDGET (₱ '000) | K9: PHYSICAL TARGET | L9: ANNUAL BUDGET (₱ '000)
E10: PHYSICAL TARGET | F10: ANNUAL BUDGET (₱ '000)
A11: OPERATIONS | D11: =D12+D625 -> 125655.82
A12: I. TECHNICAL AND SUPPORT SEVICES PROGRAM | D12: =D13+D463 -> 46155.82 | F12: 15000.29 | H12: =H13+H463 -> 33080.71 | L12: =L13+L463 -> 33080.71
A13: A. Production Support Services Sub-Program | D13: =D46+D61+D76+D163+D168+D308+D309+D314+D328+D48+D183+D188+D330+D329+D114+D153+D184+D332+D433 -> 42855.82 | F13: 15000.29 | H13: =sum(H27:H433) -> 33080.71 | L13: =sum(L27:L433) -> 33080.71
A14: Outcome Indicators
A15: Beneficiaries rating the production support services (PSS) delivered to be at least satisfactory
A16: Deliveries of producrtion support services validated by LGU's to have been delivered at the appropriate time
A17: Output Indicators
A18: LGU's assisted with production support services
A19: Input Indicators | B19: kilogram
A20: Seed Distribution | B20: kilogram
A21: Procured | B21: kilogram
A22: Produced | B22: kilogram
A23: Distributed | B23: kilogram
A24: Area Planted | B24: hectare
A25: Mungbean | B25: kilogram
A26: Procured | B26: kilogram
A27: Produced | B27: kilogram | G27: 1000 | H27: =G27*0.25 -> 250 | K27: 1000 | L27: =K27*0.25 -> 250
A28: Distributed | B28: kilogram | G28: =G27 -> 1000 | K28: =K27 -> 1000
A29: Area Planted | B29: hectare | G29: =G28/20 -> 50 | K29: =K28/20 -> 50
A30: Peanut | B30: kilogram
A31: Procured | B31: kilogram
A32: Produced | B32: kilogram
A33: Distributed | B33: kilogram
A34: Area Planted | B34: hectare
A35: White Potato | B35: kilogram
A36: Procured | B36: kilogram
A37: Produced | B37: kilogram
A38: Distributed | B38: kilogram
A39: Area Planted | B39: kilogram
A40: Hot Pepper | B40: kilogram
A41: Procured | B41: kilogram
...

Sheet NUPAP
A1: DEPARTMENT OF AGRICULTURE-REGIONAL FIELD OFFICE NO. 02
A2: CY 2025 & FY 2026 PROGRAM ACCOMPLISHMENTS/STATUS AND FY 2027 PLAN AND BUDGET PROPOSAL
A3: NATIONAL URBAN AND PERI-URBAN AGRICULTURE PROGRAM
A4: PROVINCE: NUEVA VIZCAYA
A5: DISTRICT: LONE
A7: PROGRAM/SUBPROGRAM/ INDICATORS | B7: UNIT OF MEASURE | C7: FY 2025 GAA | E7: FY 2026 GAA | G7: FY 2027 PROPOSAL | M7: Remarks (Breakdown of Municipality Target for FY 2027 )
G8: TIER 1 | I8: TIER 2 | K8: TOTAL
C9: ANNUAL PHYSICAL TARGET | D9: BUDGET (Actual Obligation in ₱ '000) | E9: ACCOMPLISHMENT | G9: PHYSICAL TARGET | H9: ANNUAL BUDGET (₱ '000) | I9: PHYSICAL TARGET | J9: ANNUAL BUDGET (₱ '000) | K9: PHYSICAL TARGET | L9: ANNUAL BUDGET (₱ '000)
E10: PHYSICAL TARGET | F10: ANNUAL BUDGET (₱ '000)
A11: OPERATIONS
A12: I. TECHNICAL AND SUPPORT SEVICES PROGRAM | D12: =D13+D41 -> 876.77762 | F12: =F13 -> 80.5
A13: I.A. Production Support Services Sub-Program | D13: =SUM(D15:D40) -> 876.77762 | F13: =SUM(F15:F39) -> 80.5
A14: Seeds Procured for Distribution
A15: Lowland Vegetables | B15: kilograms distributed | C15: 13 | D15: 169.87176
A16: Highland Vegetables | B16: kilograms distributed | C16: 13 | D16: 169.87176
A17: Planting Materials for Distribution
A18: Fruit Bearing Tree (seedlings) | B18: pieces
A19: Strawberry (cuttings) | B19: pieces | C19: 200 | D19: 15.238
A20: Ginger | B20: pieces
A21: Mango | B21: pieces
A22: Calamansi (seedlings) | B22: pieces | C22: 125 | D22: 12.5
A23: Soil Mix/Fertilizer:
A24: Organic Fertilizer - solid | B24: kilograms distributed | C24: 6000 | D24: 76.2 | E24: 161 | F24: 80.5
A25: Soilless Media/Potting Mix | B25: kilograms distributed | C25: 4500 | D25: 66.6667
A26: Liquid Fertilizer - Hydroponic Solution | B26: liter
A27: Foliar Fertilizer | B27: kilograms distributed
A28: Other Farm Inputs
A29: Seedling Tray | B29: pieces | C29: 300 | D29: 27.501
A30: Plastic crate | B30: pieces | C30: 100 | D30: 62.5
A31: Plastic Mulch | B31: rolls | C31: 20 | D31: 59.0476
A32: Water Sprinkler | B32: number
A33: Set of Garden Tools | B33: number
A34: Clay Pot | B34: number
A35: Soft pots | B35: number | C35: 100 | D35: 12.5
A36: Stackable pots | B36: number | C36: 40 | D36: 152.3808
A37: Plastic Drum | B37: number | C37: 10 | D37: 40
A38: Garden Hose | B38: number
A39: Wheel Barrow | B39: number | C39: 2 | D39: 12.5
A40: Hauling Truck | B40: number
A41: I.B. Extension Support, Education and Training Services Sub-Program
...

Sheet LIVESTOCK
A1: DEPARTMENT OF AGRICULTURE-REGIONAL FIELD OFFICE NO. 02
A2: CY 2025 & FY 2026 PROGRAM ACCOMPLISHMENTS/STATUS AND FY 2027 PLAN AND BUDGET PROPOSAL
A3: LIVESTOCK PROGRAM
A4: PROVINCE: NUEVA VIZCAYA
A5: DISTRICT: LONE
A7: PROGRAM/SUBPROGRAM/ INDICATORS | B7: UNIT OF MEASURE | C7: FY 2025 GAA | E7: FY 2026 GAA | G7: FY 2027 PROPOSAL | M7: Remarks (Breakdown of Municipality Target for FY 2027 )
G8: TIER 1 | I8: TIER 2 | K8: TOTAL
C9: ANNUAL PHYSICAL TARGET | D9: BUDGET (Actual Obligation in ₱ '000) | E9: ACCOMPLISHMENT | G9: PHYSICAL TARGET | H9: ANNUAL BUDGET (₱ '000) | I9: PHYSICAL TARGET | J9: ANNUAL BUDGET (₱ '000) | K9: PHYSICAL TARGET | L9: ANNUAL BUDGET (₱ '000)
E10: PHYSICAL TARGET | F10: ANNUAL BUDGET (₱ '000)
A11: I. TECHNICAL AND SUPPORT SEVICES PROGRAM | D11: =D12 -> 3497.2 | F11: =F12 -> 3133.83 | H11: =H12 -> 4030 | L11: =L12 -> 4030
A12: A. Production Support Services Sub-Program | D12: =D13 -> 3497.2 | F12: =F13 -> 3133.83 | H12: =H13 -> 4030 | L12: =L13 -> 4030
A13: 1. National Animal Genetic Resources Improvement Program | D13: =D14+D21 -> 3497.2 | F13: =F14+F21 -> 3133.83 | H13: =H14+H21 -> 4030 | L13: =L14+L21 -> 4030
A14: 1.1. Unified National Artificial Insemination Program | D14: =D15+D16 -> 967.2 | F14: =F15+F16 -> 933.83 | H14: =H15+H16+H17 -> 1250 | L14: =L15+L16+L17 -> 1250
A15: Cattle | B15: number | C15: 910 | D15: 920.7 | E15: 900 | F15: 910.58 | G15: 1000 | H15: =1000*0.5 -> 500 | K15: 1000 | L15: =1000*0.5 -> 500
A16: Goat | B16: number | C16: 200 | D16: 46.5 | E16: 100 | F16: 23.25
A17: Planting Materials Distributed | G17: 50000 | H17: =G17*0.015 -> 750 | K17: 50000 | L17: =K17*0.015 -> 750
A18: 2. Philippine Native Animal Development | H18: =H19+H20 -> 500 | L18: =L19+L20 -> 500
A19: Native Chicken Distribtuion | B19: number | G19: 1000 | H19: =G19*0.5 -> 500 | K19: 1000 | L19: =K19*0.5 -> 500
A20: Duck Distribution | B20: number
A21: 1.2. Development, Maintenance, and Rehabilitation / Upgrading of Government Stock Farms and Other Facilities | D21: =D23 -> 2530 | E21: 40 | F21: 2200 | H21: =H22+H23+H24 -> 2780 | L21: =L22+L23+L24 -> 2780
A22: Goat (Meat type) | B22: number
A23: Goat (Dairy type) | B23: number | C23: 46 | D23: 2530 | E23: 40 | F23: 2200 | G23: 35 | H23: =G23*70 -> 2450 | K23: 35 | L23: =K23*70 -> 2450
A24: Sheep | B24: number | G24: 6 | H24: =G24*55 -> 330 | K24: 6 | L24: =K24*55 -> 330
A26: 2. Support to Prevention and Control of Economically Important Diseases | E26: 0 | F26: 0
A27: 1. Drug and Biologic Support | B27: number
A28: 2. Calibrated sentinelling and Repopulation | B28: number
A29: Piglets Distributed | B29: number
A30: Feeds Distributed | B30: number
A31: Test Kit Distributed | B31: number
A32: 3. Livestock Economic Enterprise Development (LEED)
A33: Chicken Multiplier Farm | B33: number
A34: Goat Multiplier Farm | B34: number
A35: Sheep Multiplier Farm | B35: number
A36: II. AGRICULTURAL MACHINERY, EQUIPMENT, FACILITES AND INFRASTRUCTURE PROGRAM | F36: =F37 -> 1000 | H36: =H37 -> 12500 | L36: =L37 -> 12500
A37: A. Agricultural Machinery, Equipment and Facilities Support Services Sub-Program | E37: 0 | F37: =SUM(F38:F49) -> 1000 | H37: =sum(H49:H58) -> 12500 | L37: =sum(L49:L58) -> 12500
A38: 1. Production Facilities Established
A39: 1.1 Livestock Economic Enterprise Development (LEED)
A40: Cattle Multiplier Farm | B40: number | F40: 0
A41: Chicken Multiplier Farm | B41: number
A42: Duck Multiplier Farm | B42: number
...

Sheet OAP
A1: DEPARTMENT OF AGRICULTURE-REGIONAL FIELD OFFICE NO. 02
A2: CY 2025 & FY 2026 PROGRAM ACCOMPLISHMENTS/STATUS AND FY 2027 PLAN AND BUDGET PROPOSAL
A3: ORGANIC AGRICULTURE PROGRAM
A4: PROVINCE: NUEVA VIZCAYA
A5: DISTRICT: LONE
A7: PROGRAM/SUBPROGRAM/ INDICATORS | B7: UNIT OF MEASURE | C7: FY 2025 GAA | E7: FY 2026 GAA | G7: FY 2027 PROPOSAL | M7: Remarks (Breakdown of Municipality Target for FY 2027 )
G8: TIER 1 | I8: TIER 2 | K8: TOTAL
C9: ANNUAL PHYSICAL TARGET | D9: BUDGET (Actual Obligation in ₱ '000) | E9: ACCOMPLISHMENT | G9: PHYSICAL TARGET | H9: ANNUAL BUDGET (₱ '000) | I9: PHYSICAL TARGET | J9: ANNUAL BUDGET (₱ '000) | K9: PHYSICAL TARGET | L9: ANNUAL BUDGET (₱ '000)
E10: PHYSICAL TARGET | F10: ANNUAL BUDGET (₱ '000)
A11: I. TECHNICAL AND SUPPORT SERVICES PROGRAM | D11: 1800 | F11: =F12+F45 -> 1000 | H11: =H12+H45 -> 1600 | L11: =L12+L45 -> 1600
A12: I.1. Production Support Services Sub-program | B12: number | D12: =SUM(D19:D43) -> 1800 | F12: =SUM(F19:F43) -> 1000 | H12: =SUM(H19:H43) -> 1600 | L12: =SUM(L19:L43) -> 1600
A13: A. On- station seeds production and distribution | B13: number
A14: a.1. Vegetables | B14: number
A15: Individual provided with vegetable seeds | B15: number
A16: Male | B16: number | C16: 20
A17: Female | B17: number | C17: 20
A18: Group | B18: number | C18: 2 | E18: 5 | G18: 4 | K18: 4
A19: Assorted Open-pollinated varieties | B19: kg | C19: 80 | D19: 800 | E19: 50 | F19: 500 | G19: 50 | H19: 600 | K19: 50 | L19: 600 | M19: Provincewide
A21: a.2. Rice | B21: number
A22: Individual provided with upland rice seeds | B22: number
A23: Male | B23: number | C23: 10
A24: Female | B24: number | C24: 10
A25: Group | B25: number | C25: 1 | E25: 3 | G25: 4 | K25: 4
A27: Upland rice | B27: kg | C27: 750 | D27: 500 | E27: 500 | F27: 500 | G27: 1000 | H27: 500 | K27: 1000 | L27: 500 | M27: Provincewide
A29: a.3. Corn
A30: Individual provided with OPV corn seeds | B30: number
A31: Male | B31: number | C31: 15
A32: Female | B32: number | C32: 15
A33: Group | B33: number | C33: 1
A35: OPV Corn | B35: number | C35: 800 | D35: 500
A36: a.3. Peanut | B36: Kg | G36: 200 | H36: 500 | K36: 200 | L36: 500 | M36: Provincewide
A39: B. Farm supplies distributed
A40: Seedling Trays (100 holes) | B40: Pieces
A41: UV Plastic 6mil UV polyethylene plastic film for green house (7mX90mx.006 inch) | B41: Rolls
A43: C. Establishment of Organic Seeds Centers | B43: number
A45: I.B. Extension Support, Education and Training Services Sub-Program | B45: number
A47: II. AGRICULTURAL, MACHIENERIES, FACILITIES AND INFRASTRUCTURE PROGAM | B47: number | D47: 5000 | F47: 0 | H47: =H49+H57 -> 10500 | L47: =L49+L57 -> 10500
A48: A. Agricultural and Fishery Machinery, Equipment and Facilities Support Services Sub-program | B48: number | D48: 3000 | F48: 0
A49: 1. Provision of Agricultural Equipment and Facilities | B49: number | H49: =H53 -> 7000 | L49: =L53 -> 7000
A50: 1.1 Provision of Shredder Machines | B50: number
...

Sheet HALAL
A1: DEPARTMENT OF AGRICULTURE-REGIONAL FIELD OFFICE NO. 02
A2: CY 2025 & FY 2026 PROGRAM ACCOMPLISHMENTS/STATUS AND FY 2027 PLAN AND BUDGET PROPOSAL
A3: HALAL DEVELOPMENT INDUSTRY PROGRAM
A4: PROVINCE: NUEVA VIZCAYA
A5: DISTRICT: LONE
A7: PROGRAM/SUBPROGRAM/ INDICATORS | B7: UNIT OF MEASURE | C7: FY 2025 GAA | E7: FY 2026 GAA | G7: FY 2027 PROPOSAL | M7: Remarks (Breakdown of Municipality Target for FY 2027 )
G8: TIER 1 | I8: TIER 2 | K8: TOTAL
C9: ANNUAL PHYSICAL TARGET | D9: BUDGET (Actual Obligation in ₱ '000) | E9: ACCOMPLISHMENT | G9: PHYSICAL TARGET | H9: ANNUAL BUDGET (₱ '000) | I9: PHYSICAL TARGET | J9: ANNUAL BUDGET (₱ '000) | K9: PHYSICAL TARGET | L9: ANNUAL BUDGET (₱ '000)
E10: PHYSICAL TARGET | F10: ANNUAL BUDGET (₱ '000)
A11: I. TECHNICAL AND SUPPORT SERVICES PROGRAM
A12: A. Extension Support, Education and Training Services
A13: 1. Advanced Training cum Production on Halal Farming Systems | E13: 1 | F13: 75
A14: Halal orientation conducted | B14: number | E14: 1
A15: Participants | B15: number | E15: 25
A16: 2. Halal Product Certification Assistance | E16: 4 | F16: 175 | I16: 1 | J16: 500 | K16: 1 | L16: 500 | M16: Kasibu
A17: Product for certification | B17: number
A18: 3. Assistance on the Production of DA Assisted Halal Certified Products
A19: Products assisted | B19: number
A20: 4. Training on Halal Compliance, Certification, and Export Requirements (Ube & Coffee) | B20: number | I20: 1 | J20: 50 | K20: 1 | L20: 50 | M20: Kasibu
A21: 5. Training on Postharvest Handling | B21: number | I21: 1 | J21: 50 | K21: 1 | L21: 50 | M21: Kasibu
A22: PRODUCTION SUPPORT SERVICES
A23: Provision of Coffee Drip Irrigation System | B23: number | I23: 5 | J23: 5500 | K23: 5 | L23: 5500 | M23: Kasibu, Kayapa, Ambaguio, Dupax Del Sur, Bagabag
A24: B. Field Program Management Activities (FPMA)
A25: 1. Halal Product Certification Assistance
A26: Hiring of | B26: number
A28: GRAND TOTAL | F28: =F13+F16 -> 250 | H28: 0 | J28: =sum(J16:J23) -> 6100 | L28: =sum(L16:L23) -> 6100
A30: Prepared by: | E30: In coordination with: | L30: Concurred by:
A35: BERNADETTE T. GALOSO | E35: MACARIO B. ANDAL, CPA | L35: ROSE MARY G. AQUINO, Ph.D.
A36: Chief, PMED | E36: Chief, Budget Section | L36: Regional Executive Director

Sheet FMR
A1: DEPARTMENT OF AGRICULTURE-REGIONAL FIELD OFFICE NO. 02
A2: CY 2025 & FY 2026 PROGRAM ACCOMPLISHMENTS/STATUS AND FY 2027 PLAN AND BUDGET PROPOSAL
A3: FARM-TO-MARKET ROAD DEVELOPMENT PROGRAM
A4: PROVINCE: NUEVA VIZCAYA
A5: DISTRICT: LONE
A7: MUNICIPALITY | B7: LOCATION (BARANGAY) | C7: NAME OF PROJECTS | D7: ESTIMATED LENGTH (KM) | E7: ESTIMATED AMOUNT (₱ '000)
A8: FY 2025 GAA
A9: Bagabag | B9: Baretbet-Pogonsino | C9: Concreting of Baretbet-Pogonsino Section FMR, Brgy. Baretbet-Pogonsino, Bagabag, Nueva Vizcaya | D9: 1 | E9: 15000
A10: Bagabag | B10: Murong, Bagabag | C10: Opening and Concreting of Tay-a-Santor FMR, Brgy. Murong, Bagabag, Nueva Vzicaya | D10: 1.333 | E10: 20000
A11: Bagabag | B11: Quirino - San Geronimo | C11: Opening and Concreting of FMR at Brgy. Quirino - San Geronimo , Bagabag, Nueva Vizcaya | D11: 2 | E11: 30000
A12: Bagabag | B12: Baretbet | C12: Upgrading of Baretbet- Dumayop-Masina FMR,Brgy. Baretbet, Bagabag, Nueva Vizcaya | D12: 1.333 | E12: 20000
A13: Bagabag | B13: Baretbet | C13: Upgrading/Concreting of Santiago Road FMR , Sitio Amballo North - Amballo South, Brgy. Baretbet, Bagabag, Nueva Vizcaya | D13: 2 | E13: 30000
A14: Solono | B14: Commonal | C14: Concreting of Brgy. Commonal FMR, Brgy. Commonal, Solono, Nueva Vizcaya | D14: 0.667 | E14: 10000
A15: Bambang | B15: Dinili- Calaocan | C15: Concreting of Brgy. Dinili FMR, Brgy. Calaocan, Bambang, Nueva Vizcaya | D15: 0.667 | E15: 10000
A16: Kayapa | B16: Cabayo- Balete, Kayapa, Nueva Vizcaya | C16: Concreting of Cabayo- Balete FMR, Brgy. Cabayo- Balete, Kayapa, Nueva Vizcaya | D16: 1 | E16: 15000
A17: Kasibu | B17: Nantawakan, Kasibu, Nueva Vizcaya | C17: Concreting of Nantawakan FMR, Brgy. Nantawakan, Kasibu, Nueva Vizcaya | D17: 0.667 | E17: 10000
A18: TOTAL | D18: =SUM(D9:D15) -> 9 | E18: =SUM(E9:E17) -> 160000
A19: FY 2026 GAA
A20: Bambang | B20: San Fernando | C20: Concreting of Mapatang San Fernando FMR, Brgy. San Fernando, Bambang, Nueva Vizcaya | D20: 2 | E20: 30000
A21: Bambang | B21: Barat | C21: Concreting of Brgy. Barat- Brgy. Macalanga-Brgy. Pallas-Brgy. Salinas FMR, Bambang, Nueva Vizcaya | D21: 1 | E21: 15000
A22: Sta. Fe | B22: Pallay Unib | C22: Concreting of Pallay Unib FMR, Brgy. Unib Sta. Fe Nueva Vizcaya | D22: 1 | E22: 15000
A23: Alfonso Castañeda | B23: Lublub | C23: Concreting of Purok 6 to Purok 10 FMR, Brgy. Lublub, Alfonso Castañeda, Nueva Vizcaya | D23: 1 | E23: 15000
A24: Santa Fe | B24: Baracbac | C24: Concreting of Purok 4, Brgy. Baracbac FMR, Brgy. Baracbac, Santa Fe, Nueva Vizcaya | D24: 1 | E24: 15000
A25: Santa Fe | B25: Calitlitan | C25: Concreting of Brgy. Calitlitan to Brgy. Buyasyas FMR, Brgy. Calitlitan, Aritao and Brgy. Buyasyas, | D25: 1 | E25: 15000
A26: Aritao | B26: Balite | C26: Concreting of Brgy. Balite FMR, Brgy. Balite, Aritao, Nueva Vizcaya | D26: 1 | E26: 15000
A27: Aritao | B27: Beti | C27: Concreting of Sitio Mabauang (Upper and Lower) FMR, Brgy. Beti, Aritao, Nueva Vizcaya | D27: 1 | E27: 15000
A28: Bayombong | B28: Busilac | C28: Concreting of Brgy. Busilac, Sitio Simmusu and Sitio Pacpaco, Purok 7 FMR, Brgy. Busilac, Bayombong, Nueva Vizcaya Nueva Vizcaya | D28: 1.667 | E28: 25000
A29: Bayombong | B29: Cabuaan | C29: Concreting of Brgy. Cabuaan, Ladao Road, Purok 4 FMR, Brgy. Cabuaan, Bayombong, Nueva Vizcaya | D29: 1.333 | E29: 20000
A30: Bayombong | B30: Magapuy | C30: Concreting of Brgy. Magapuy, Purok 6, Bantil Road FMR, Brgy. Magapuy, | D30: 1.33 | E30: 20000
A31: Dupax Del Sur | B31: Kimbutan | C31: Concreting of Kimbutan (Purok Gunot-Pinakdetan) FMR, Brgy. Kimbutan, Dupax del Sur, Nueva Vizcaya | D31: 1 | E31: 15000
... A34: Kayapa | B34: Pinayag | C34: Concreting of Pantal-Pinayag, Gubot, Latbang FMR, Brgy. Pinayag, Kayapa, Nueva Vizcaya | D34: 1 | E34: 15000
A35: TOTAL | D35: =SUM(D25:D34) -> 11.33 | E35: =SUM(E25:E34) -> 165000
A37: FY 2027 PROPOSAL (TIER I)
A38: Ambaguio | B38: Poblacion | C38: Construction of Natebwek-Bacwit FMR, Brgy. Poblacion, Ambaguio, Nueva Vizcaya | D38: 1.4 | E38: 21700
A39: Kayapa | B39: Babadi | C39: Concreting of Brgy Babadi (Ganza-Buhlangan) FMR, Brgy. Babadi, Kayapa, Nueva Vizcaya | D39: 1.7 | E39: 26350
A40: Kasibu | B40: Macalong | C40: Concreting of Brgy Macalong (Cell Site) FMR, Brgy Macalong, Kasibu, Nueva Vizcaya | D40: 1 | E40: 15500
A41: Alfonso Castaneda | B41: Lublub | C41: Concreting of Balintogon-Diwakwak FMR, Brgy. Lublub, Alfonso Castañeda, Nueva Vizcaya | D41: 1.8 | E41: 27900
A42: Dupax Del Sur | B42: Carolotan | C42: Concreting of Carolotan (Dalayap) - Ganao- Sanguit FMR, Brgy. Carolotan, Dupax del Sur, Nueva Vizcaya | D42: 3.1 | E42: 48050
A43: Sta. Fe | B43: Tactac | C43: Concreting of Tactac-Atbu FMR, Brgy. Atbu, Sta. Fe, Nueva Vizcaya | D43: 1 | E43: 15500
A44: SUBTOTAL | D44: =SUM(D38:D43) -> 10 | E44: =SUM(E38:E43) -> 155000
...

Sheet SAAD
A1: DEPARTMENT OF AGRICULTURE-REGIONAL FIELD OFFICE 02
A2: CY 2025 & FY 2026 PROGRAM ACCOMPLISHMENTS/STATUS AND FY 2027 PLAN AND BUDGET PROPOSAL
A3: SPECIAL AREA FOR AGRICULTURAL DEVELOPMENT (SAAD) PROGRAM
A4: PROVINCE: NUEVA VIZCAYA
A5: DISTRICT: LONE
A8: PROGRAM/SUBPROGRAM/ INDICATORS | B8: UNIT OF MEASURE | C8: FY 2025 GAA | E8: FY 2026 GAA | G8: FY 2027 PROPOSAL | M8: Remarks (Breakdown of Municipality Target for FY 2027 )
G9: TIER 1 | I9: TIER 2 | K9: TOTAL
C10: ANNUAL PHYSICAL TARGET | D10: BUDGET (Actual Obligation in ₱ '000) | E10: ACCOMPLISHMENT | G10: PHYSICAL TARGET | H10: ANNUAL BUDGET (₱ '000) | I10: PHYSICAL TARGET | J10: ANNUAL BUDGET (₱ '000) | K10: PHYSICAL TARGET | L10: ANNUAL BUDGET (₱ '000)
E11: PHYSICAL TARGET | F11: ANNUAL BUDGET (₱ '000)
A12: I. SOCIAL PREPARATION | D12: 450 | F12: 475 | H12: 619 | L12: 619
A13: A. Community Needs Assessment (CNA) | G13: 1 | K13: 1 | M13: Villaverde Amabguio
A14: a.1 Orientations, Meetings, Assessments and Consultation conducted | B14: number | E14: 2
A15: a.2 Beneficiary Needs Assessment/ Participatory Rural Appraisal (PRA) conducted | B15: group | C15: 2 | E15: 2
A16: B. Beneficiary Capacitation and General Development
A17: b.1 Capability Building activities conducted | B17: group | C17: 5 | E17: 7 | G17: 6 | K17: 6 | M17: Villaverde Amabguio
A18: C. Database and Profiling
A19: c.1 Beneficiary Profiling conducted | B19: group | C19: 5 | E19: 7 | G19: 6 | K19: 6 | M19: Villaverde Amabguio
A20: c.2 Database Uploading conducted | B20: group | C20: 5 | E20: 7 | G20: 6 | K20: 6 | M20: Villaverde Amabguio
A22: II. FOOD PRODUCTION AND LIVELIHOOD INTERVENTIONS | D22: =D23+D24 -> 6439 | F22: 4973 | H22: =H23+H24 -> 6268 | L22: =L23+L24 -> 6268
A23: 1. HVC-based Project distributed | B23: group | C23: 5 | D23: 6264 | E23: 5 | F23: 4573 | G23: 6 | H23: 6108 | K23: 6 | L23: 6108 | M23: Villaverde Amabguio
A24: 2. Specialized Trainings conducted | B24: number | C24: 5 | D24: 175 | E24: 10 | F24: 400 | G24: 2 | H24: 160 | K24: 2 | L24: 160 | M24: Villaverde Amabguio
A26: III. MARKETING ASSISTANCE AND ENTERPRISE DEVELOPMENT | D26: =D27+D28 -> 450 | F26: 475 | H26: 543 | L26: 543
A27: 1. Market-related trainings conducted | B27: number | C27: 4 | D27: 350 | E27: 10 | F27: 475 | G27: 5 | K27: 5 | M27: Villaverde Amabguio
A28: 2. Partially established CBEs | B28: group | D28: 100 | G28: 3 | K28: 3 | M28: Villaverde Amabguio
A30: IV. PROGRAM MANAGEMENT | D30: 0
A31: 4.1. Project Management Offices Maintained
A32: 4.1.1. Hiring/renewal of manpower
A33: A. RPMSO
A34: B. PPMSO
A35: 4.1.2 Office Oprating Requirements
A36: 4.2. Review and Planning Workshop
A37: A. Plan and Budget Preparation (PBP)
A38: B. Budget Execution Document (BED) Preparation
A39: 4.3. Monitoring and Evaluation
A40: 4.3.1. Conduct of Performance and Budget
A41: 4.3.2. Implementation of management information
A42: - Sub-project monitoring
... A46: 4.3.2. Regional Assessment
A48: GRAND TOTAL | D48: =D30+D26+D22+D12 -> 7339 | F48: =F30+F26+F22+F12 -> 5923 | H48: =H30+H26+H22+H12 -> 7430 | L48: =L30+L26+L22+L12 -> 7430
A49: Note: FY 2027 budget allocation for the Social Preparation and MAED is by component.
...

Sheet MCRA
A1: DEPARTMENT OF AGRICULTURE-REGIONAL FIELD OFFICE 02
A2: CY 2025 & FY 2026 PROGRAM ACCOMPLISHMENTS/STATUS AND FY 2027 PLAN AND BUDGET PROPOSAL
A3: MAINSTREAMING CLIMATE RESILIENT AGRICULTURE (MCRA) TO THE REGIONAL PROGRAMS AND PROJECTS
A4: PROVINCE: NUEVA VIZCAYA
A5: DISTRICT: LONE
A7: PROGRAM/SUBPROGRAM/ INDICATORS | B7: UNIT OF MEASURE | C7: FY 2025 GAA | E7: FY 2026 GAA | G7: FY 2027 PROPOSAL | M7: Remarks (Breakdown of Municipality Target for FY 2027 )
G8: TIER 1 | I8: TIER 2 | K8: TOTAL
C9: ANNUAL PHYSICAL TARGET | D9: BUDGET (Actual Obligation in ₱ '000) | E9: ACCOMPLISHMENT | G9: PHYSICAL TARGET | H9: ANNUAL BUDGET (₱ '000) | I9: PHYSICAL TARGET | J9: ANNUAL BUDGET (₱ '000) | K9: PHYSICAL TARGET | L9: ANNUAL BUDGET (₱ '000)
E10: PHYSICAL TARGET | F10: ANNUAL BUDGET (₱ '000)
A11: TECHNICAL AND SUPPORT SEVICES PROGRAM | D11: 0 | F11: =F12 -> 1075 | H11: 0 | J11: 0 | L11: 0
A12: I. Production Support Services Sub-Program | D12: 0 | F12: 1075 | H12: 0 | J12: 0 | L12: 0
A13: 1. Production and Livelihood Support to Farmers-Cooperators
A14: - Swine dispersal | B14: Number | E14: 55 | F14: 500
A15: - Ready to lay chicken with battery cage | B15: Number | E15: 500 | F15: 500
A16: - feeds and biologics | B16: lot | E16: 60 | F16: 200
A19: Technical and Scientific Equipment
A20: Automated Weather Station (AWS) established and agro climatic Advisory (ACAP) for Cagayan Valley | B20: Number
A21: II. Extension Support, Education and Training Services Sub-Program | D21: 0 | F21: 0 | H21: 0 | J21: 0 | L21: 0
A22: III. AGRICULTURAL MACHINERY, EQUIPMENT, FACILITES AND INFRASTRUCTURE PROGRAM | D22: 0 | F22: 0 | H22: 0 | J22: 0 | L22: 0
A23: 1. Agricultural Machinery, Equipment and Facilities Support Services Sub-Program
A24: Peletizer | B24: Number
A25: Farm production-related machinery and equipment distributed | B25: Number
A26: 2. Irrigation Network Services (INS) Sub-program
A27: Warehouse | B27: Number | C27: 1 | D27: =3149439.95/1000 -> 3149.4399
A28: GRAND TOTAL | D28: =SUM(D19:D27) -> 3149.4399 | F28: =F22+F11 -> 1075 | H28: =H22+H11 -> 0 | J28: =J22+J11 -> 0 | L28: =L22+L11 -> 0
A31: Prepared by: | B31: Reviewed by:
A36: JONAZON JEFF T. FACTORA | B36: BERNADETTE T. GALOSO
A37: Chief, Planning and Investment | B37: OIC-Chief, PMED
A38: Programming Section
A39: Prepared by: | E39: In coordination with: | L39: Concurred by:
A44: BERNADETTE T. GALOSO | E44: MACARIO B. ANDAL, CPA | L44: ROSE MARY G. AQUINO, Ph.D.
A45: Chief, PMED | E45: Chief, Budget Section | L45: Regional Executive Director

Sheet 4Ks
A1: DEPARTMENT OF AGRICULTURE-REGIONAL FIELD OFFICE 02
A2: CY 2025 & FY 2026 PROGRAM ACCOMPLISHMENTS/STATUS AND FY 2027 PLAN AND BUDGET PROPOSAL
A3: KABUHAYAN AT KAUNLARAN NG KABABAYANG KATUTUBO (4Ks) PROGRAM
A4: PROVINCE: NUEVA VIZCAYA
A5: DISTRICT: LONE
A7: PROGRAM/SUBPROGRAM/ INDICATORS | B7: UNIT OF MEASURE | C7: FY 2025 GAA | E7: FY 2026 GAA | G7: FY 2027 PROPOSAL | M7: Remarks (Breakdown of Municipality Target for FY 2027 )
G8: TIER 1 | I8: TIER 2 | K8: TOTAL
C9: ANNUAL PHYSICAL TARGET | D9: BUDGET (Actual Obligation in ₱ '000) | E9: ACCOMPLISHMENT | G9: PHYSICAL TARGET | H9: ANNUAL BUDGET (₱ '000) | I9: PHYSICAL TARGET | J9: ANNUAL BUDGET (₱ '000) | K9: PHYSICAL TARGET | L9: ANNUAL BUDGET (₱ '000)
E10: PHYSICAL TARGET | F10: ANNUAL BUDGET (₱ '000)
A11: I. PRODUCTION AND LIVELIHOOD COMPONENT | D11: =D12 -> 1907.461 | F11: =F12 -> 1893.15 | H11: =H12 -> 2036.166 | J11: =J12 | L11: =L12 -> 2036.166
A12: Provision of Agricultural Inputs and Livestock | D12: =D18 -> 1907.461 | F12: =F18 -> 1893.15 | H12: =H18 -> 2036.166 | J12: =J18 | L12: =L18 -> 2036.166
A13: 1. Corn and Cassava Related Activity
A14: GM Hybrid Corn Seeds | B14: no. of kg distributed | D14: -
A15: Inorganic Fertilizer | B15: no. of kg distributed | D15: -
A16: c. Cassava Seed Pieces | B16: no. of seedpieces distributed | C16: - | D16: -
A18: 2. High Value Crops Related Activity | D18: =SUM(D19:D31) -> 1907.461 | F18: =F23+F21+F20+F19 -> 1893.15 | H18: =H23+H21+H20+H19 -> 2036.166 | L18: =L23+L21+L20+L19 -> 2036.166
A19: Upland Vegetables | B19: no. of kg distributed | C19: 14 | D19: 533.2 | E19: 3.6 | F19: 217.2 | G19: 223.85 | H19: 687.83 | K19: 223.85 | L19: 687.83 | M19: Dupax Del Norte and Kayapa
A20: Lowland Vegetables | B20: no. of kg distributed | C20: 23 | D20: 136.711 | E20: 51.7 | F20: 145.95 | G20: 27.4 | H20: 148.336 | K20: 27.4 | L20: 148.336 | M20: Dupax Del Norte and Kayapa
A21: Fruit Bearing Trees | B21: no. of pcs distributed | C21: 2035 | D21: 377.55 | E21: 1000 | F21: 280
A22: Organic Fertilizer | B22: no. of kg distributed | G22: 2000 | H22: 20 | K22: 2000 | L22: 20 | M22: Dupax Del Norte and Kayapa
A23: Ube Planting Materials | B23: no. of kg distributed | C23: 2000 | D23: 600 | E23: 5000 | F23: 1250 | G23: 4000 | H23: 1200 | K23: 4000 | L23: 1200 | M23: Dupax Del Norte and Kayapa
A24: Ginger Planting Materials | B24: no. of kg distributed
A25: Taro/Galyang Planting Materials | B25: no. of kg distributed
A26: Banana Planting Materials | B26: no. of pcs distributed | C26: 500 | D26: 60
A27: 3. Livestock Related Activity | F27: =F28+F29+F30+F31 -> 860 | H27: =H28+H29+H30+H31 -> 0 | L27: =L28+L29+L30+L31 -> 0
A28: a. Native Chicken | B28: no. of head distributed | E28: 400 | F28: 240
A29: b. Duck | B29: no. of head distributed | E29: 400 | F29: 280
A30: a. Goat | B30: no. of head distributed | C30: 10 | D30: 80 | E30: 10 | F30: 100
A31: b. Carabao | B31: no. of head distributed | C31: 2 | D31: 120 | E31: 4 | F31: 240
A32: e. Native/Upgraded Pig | B32: no. of head distributed
A33: 4. Agricultural Machineries Tools and Equipment | F33: =F39+F40 -> 130 | H33: =H39+H40+H36+H37+H38+H41+H42 -> 452.8 | L33: =L39+L40+L36+L37+L38+L41+L42 -> 452.8
A34: a. Hand Tractor with Implement | B34: No. of units
A35: b. Motorized boat | B35: No. of units
A36: c. Micro-Tiller | B36: No. of units | G36: 4 | H36: 120 | K36: 4 | L36: 120 | M36: Dupax Del Norte and Kayapa
A37: d. Knapsack Sprayer | B37: No. of units | G37: 8 | H37: 20 | K37: 8 | L37: 20 | M37: Dupax Del Norte and Kayapa
A38: e. Grass Cutter | B38: No. of units | G38: 2 | H38: 50 | K38: 2 | L38: 50 | M38: Dupax Del Norte and Kayapa
A39: f. Garden Hose | B39: No. of rolls | E39: 20 | F39: 60
A40: g. Plastic Mulch | B40: No. of units | E40: 20 | F40: 70
A41: h. Garden Tools | B41: No. of pcs | G41: 70 | H41: 62.8 | K41: 70 | L41: 62.8 | M41: Dupax Del Norte and Kayapa
A42: i. Open Source Pump Set | B42: No. of units | G42: 2 | H42: 200 | K42: 2 | L42: 200 | M42: Dupax Del Norte and Kayapa
...

Sheet NSHP
A1: DEPARTMENT OF AGRICULTURE-REGIONAL FIELD OFFICE 02
A2: CY 2025 & FY 2026 PROGRAM ACCOMPLISHMENTS/STATUS AND FY 2027 PLAN AND BUDGET PROPOSAL
A3: NATIONAL SOIL HEALTH PROGRAM
A4: PROVINCE: NUEVA VIZCAYA
A5: DISTRICT: LONE
A7: PROGRAM/SUBPROGRAM/ INDICATORS | B7: UNIT OF MEASURE | C7: FY 2025 GAA | E7: FY 2026 GAA | G7: FY 2027 PROPOSAL | M7: Remarks (Breakdown of Municipality Target for FY 2027 )
G8: TIER 1 | I8: TIER 2 | K8: TOTAL
C9: ANNUAL PHYSICAL TARGET | D9: BUDGET (Actual Obligation in ₱ '000) | E9: ACCOMPLISHMENT | G9: PHYSICAL TARGET | H9: ANNUAL BUDGET (₱ '000) | I9: PHYSICAL TARGET | J9: ANNUAL BUDGET (₱ '000) | K9: PHYSICAL TARGET | L9: ANNUAL BUDGET (₱ '000)
E10: PHYSICAL TARGET | F10: ANNUAL BUDGET (₱ '000)
A11: National Soil Health Program (Tier II) | D11: =SUM(D12:D19) -> 550
A12: I. Operation of Regional Soil Laboratories in support to NSHP Activities | C12: 36 | D12: 480
A13: 1.1 Soil Analysis | B13: number of samples | C13: 10 | D13: 40 | E13: 37 | F13: 232
A14: 1.2 Fertilizer Analysis | B14: number of samples | C14: 20 | D14: 30 | E14: 10 | F14: 90
A15: 1.3 Plant Tissue Analysis | B15: number of samples | E15: 5 | F15: 90
A16: 1.4 Participation to Proficiency Testing | B16: Number of PT participated | F16: 0
A17: 1.5 STK Production/distribution | B17: number of STK Produced/ distributed | E17: 37 | F17: 53
A18: 1.6 Maintenance of Regulatory/Statutory issuances acquired | B18: number of regulatory/ statutory issuances acquired/ maintained | F18: 0
A20: II. Operation of Mobile Soil Laboratory
A21: 2.1 Soil Chemical Analysis (STK/Chemical) | B21: no. of sample analyzed | E21: 250 | F21: 175
A22: 2.2. Soil Physical Analysis | B22: no. of sample analyzed | E22: 38 | F22: 160
A23: 2.3 Soil Microbiological Analysis | B23: no. of sample analyzed | E23: 38 | F23: 160
A24: 2.4 Distribution of Soil Health card | B24: no. of Soil Health Card distributed | E24: 250 | F24: 80
A25: 2.5 Trainings conducted | B25: no. of training conducted | E25: 1 | F25: 250
A26: GRAND TOTAL | D26: =D11 -> 550 | F26: =SUM(F13:F25) -> 1290 | H26: 0 | J26: 0 | L26: 0
A27: *Program Implementation only started on FY 2025
A29: Prepared by: | E29: In coordination with: | L29: Concurred by:
A34: BERNADETTE T. GALOSO | E34: MACARIO B. ANDAL, CPA | L34: ROSE MARY G. AQUINO, Ph.D.
A35: Chief, PMED | E35: Chief, Budget Section | L35: Regional Executive Director

Sheet COLD STORAGE
A1: DEPARTMENT OF AGRICULTURE-REGIONAL FIELD OFFICE NO. 02
A2: CY 2025 & FY 2026 PROGRAM ACCOMPLISHMENTS/STATUS AND FY 2027 PLAN AND BUDGET PROPOSAL
A3: COLD STORAGE EXPANSION*
A4: PROVINCE: NUEVA VIZCAYA
A5: DISTRICT: LONE
A7: PROGRAM/SUBPROGRAM/ INDICATORS | B7: UNIT OF MEASURE | C7: FY 2025 GAA | E7: FY 2026 GAA | G7: FY 2027 PROPOSAL | M7: Remarks (Breakdown of Municipality Target for FY 2027 )
G8: TIER 1 | I8: TIER 2 | K8: TOTAL
C9: ANNUAL PHYSICAL TARGET | D9: BUDGET (Actual Obligation in ₱ '000) | E9: ACCOMPLISHMENT | G9: PHYSICAL TARGET | H9: ANNUAL BUDGET (₱ '000) | I9: PHYSICAL TARGET | J9: ANNUAL BUDGET (₱ '000) | K9: PHYSICAL TARGET | L9: ANNUAL BUDGET (₱ '000)
E10: PHYSICAL TARGET | F10: ANNUAL BUDGET (₱ '000)
A11: Postharvest Facility Establishment | D11: =SUM(D12:D17) -> 122500 | F11: 0 | H11: 0 | J11: 0 | L11: 0
A12: Onion cold storage | B12: number | C12: 2 | D12: 122500
A13: Participation to Proficiency Testing Program
A19: GRAND TOTAL | D19: =D11 -> 122500 | F19: 0 | H19: 0 | J19: 0 | L19: 0
A21: Prepared by: | E21: In coordination with: | L21: Concurred by:
A26: BERNADETTE T. GALOSO | E26: MACARIO B. ANDAL, CPA | L26: ROSE MARY G. AQUINO, Ph.D.
A27: Chief, PMED | E27: Chief, Budget Section | L27: Regional Executive Director

Sheet PRDP
A1: DEPARTMENT OF AGRICULTURE-REGIONAL FIELD OFFICE 02
A2: CY 2025 & FY 2026 PROGRAM ACCOMPLISHMENTS/STATUS AND FY 2027 PLAN AND BUDGET PROPOSAL
A3: PHILIPPINE RURAL DEVELOPMENT PROJECT*
A4: PROVINCE: NUEVA VIZCAYA
A5: DISTRICT: LONE
A7: MUNICIPALITY | B7: LOCATION (BARANGAY) | C7: NAME OF PROJECTS | D7: ESTIMATED LENGTH (KM) | E7: ESTIMATED AMOUNT (₱ '000)
A8: FY 2026 UNDER PROCUREMENT
A9: Kayapa | B9: Pangawan, Banao | C9: Upgrading of Pangawan-Banao Farm to Market Road | D9: 10.86 | E9: =334482000/1000 -> 334482
A10: FY 2026 PIPELINED/PROPOSAL
A11: Kasibu | B11: Tadji, Tukod | C11: Rehabilitation of Tadji-Tukod Farm to Market Road | D11: 9.94 | E11: =238756000/1000 -> 238756
A12: TOTAL | D12: =SUM(D8:D11) -> 20.8 | E12: =SUM(E8:E11) -> 573238
A15: Prepared by: | B15: Reviewed by: | C15: In coordination with: | D15: Concurred by:
A20: JONAZON JEFF T. FACTORA | B20: BERNADETTE T. GALOSO | C20: MACARIO B. ANDAL, CPA | D20: ROSE MARY G. AQUINO, Ph.D.
A21: Chief, Planning and Investment | B21: Chief, PMED | C21: Chief, Budget Section | D21: Regional Executive Director
A22: Programming Section
A24: Prepared by: | C24: In coordination with: | E24: Concurred by: | N24: Prepared by: | R24: In coordination with: | Y24: Concurred by:
A29: BERNADETTE T. GALOSO | C29: MACARIO B. ANDAL, CPA | E29: ROSE MARY G. AQUINO, Ph.D. | N29: BERNADETTE T. GALOSO | R29: MACARIO B. ANDAL, CPA | Y29: ROSE MARY G. AQUINO, Ph.D.
A30: Chief, PMED | C30: Chief, Budget Section | E30: Regional Executive Director | N30: Chief, PMED | R30: Chief, Budget Section | Y30: Regional Executive Director

Sheet GRAND TOTAL
A2: CY 2025, FY 2026, AND FY 2027 BUDGET SUMMARY (₱ '000)
A3: REGION 02
A4: NUEVA VIZCAYA PROVINCE
A5: LONE DISTRICT
A8: PROGRAM/PROJECT FUND SOURCE | B8: CY 2025 GAA | C8: FY 2026 GAA | D8: FY 2027 PROPOSAL | G8: Variance | H8: % Change (Increase/Decrease)
D9: TIER 1 | E9: TIER 2 | F9: TOTAL
A10: Operations
A11: National Rice Program | B11: =RICE!D59 -> 171657.09 | C11: =RICE!F59 -> 303557 | D11: =RICE!H59 -> 187930 | E11: =RICE!J59 -> 113686.1 | F11: =D11+E11 -> 301616.1 | G11: =F11-C11 -> -1940.9 | H11: =G11/C11*100 -> -0.63938568
A12: National Corn Program | B12: =CORN!D83 -> 16831.44 | C12: =CORN!F83 -> 69465 | D12: =CORN!H83 -> 5581 | E12: =CORN!J83 -> 156400 | F12: =D12+E12 -> 161981 | G12: =F12-C12 -> 92516 | H12: =G12/C12*100 -> 133.18362
A13: National High Value Crops Development Program | B13: =HVCDP!D801 -> 125655.82 | C13: =HVCDP!F801 -> 78350.29 | D13: =HVCDP!H801 -> 65180.71 | E13: =HVCDP!J801 -> 0 | F13: =D13+E13 -> 65180.71 | G13: =F13-C13 -> -13169.58 | H13: =G13/C13*100 -> -16.808591
A14: National Urban and Peri-Urban Agriculture Program | B14: =NUPAP!D63 -> 3626.7776 | C14: =NUPAP!F63 -> 5604.5 | D14: =NUPAP!H63 -> 0 | E14: =NUPAP!J63 -> 0 | F14: =D14+E14 -> 0 | G14: =F14-C14 -> -5604.5 | H14: =G14/C14*100 -> -100
A15: National Livestock Program | B15: =LIVESTOCK!D60 -> 3497.2 | C15: =LIVESTOCK!F60 -> 4133.83 | D15: =LIVESTOCK!H60 -> 16530 | E15: =LIVESTOCK!J60 -> 0 | F15: =D15+E15 -> 16530 | G15: =F15-C15 -> 12396.17 | H15: =G15/C15*100 -> 299.87131
A16: National Organic Agriculture Program | B16: =OAP!D61 -> 6800 | C16: =OAP!F61 -> 1000 | D16: =OAP!H61 -> 12100 | E16: =OAP!J61 -> 0 | F16: =D16+E16 -> 12100 | G16: =F16-C16 -> 11100 | H16: =G16/C16*100 -> 1110
A17: HALAL Program | B17: =HALAL!D28 | C17: =HALAL!F28 -> 250 | D17: =HALAL!H28 -> 0 | E17: =HALAL!J28 -> 6100 | F17: =D17+E17 -> 6100 | G17: =F17-C17 -> 5850 | H17: =G17/C17*100 -> 2340
A18: Locally Funded Projects
A19: Farm-to-Market Road (FMR) Development Program | B19: =FMR!E18 -> 160000 | C19: =FMR!E35 -> 165000 | D19: =FMR!E44 -> 155000 | E19: =FMR!E70 -> 563890 | F19: =D19+E19 -> 718890 | G19: =F19-C19 -> 553890 | H19: =G19/C19*100 -> 335.69091
A20: Special Area for Agricultural Development (SAAD) Program | B20: =SAAD!D48 -> 7339 | C20: =SAAD!F48 -> 5923 | D20: =SAAD!H48 -> 7430 | E20: =SAAD!J48 | F20: =D20+E20 -> 7430 | G20: =F20-C20 -> 1507 | H20: =G20/C20*100 -> 25.443188
A21: Kabuhayan at Kaunlaran ng Kababayang Katutubo (4Ks) Program | B21: 1907 | C21: ='4Ks'!F56 -> 2883.15 | D21: ='4Ks'!H56 -> 2488.966 | E21: 0 | F21: =D21+E21 -> 2488.966 | G21: =F21-C21 -> -394.184 | H21: =G21/C21*100 -> -13.671991
A22: Mainstreaming Climate Resilient Agriculture (MCRA) to the Regional Programs & Projects | B22: =MCRA!D28 -> 3149.4399 | C22: =MCRA!F28 -> 1075 | D22: 0 | E22: 0 | F22: =D22+E22 -> 0 | G22: =F22-C22 -> -1075 | H22: =G22/C22*100 -> -100
A23: National Soil Health Program* | B23: =NSHP!D26 -> 550 | C23: =NSHP!F26 -> 1290 | D23: 0 | E23: 0 | F23: =D23+E23 -> 0 | G23: =F23-C23 -> -1290 | H23: =G23/C23*100 -> -100
A24: Cold Storage Expansion* | B24: ='COLD STORAGE'!D19 -> 122500 | C24: ='COLD STORAGE'!F19 -> 0 | D24: ='COLD STORAGE'!H19 -> 0 | E24: ='COLD STORAGE'!J19 -> 0 | F24: =D24+E24 -> 0 | G24: =F24-C24 -> 0 | H24: 0
A25: Foreign Assisted Project
A26: Philippine Rural Development Projects** | B26: 0 | C26: =PRDP!E9 -> 334482 | D26: 0 | E26: 0 | F26: =D26+E26 -> 0 | G26: =F26-C26 -> -334482 | H26: =G26/C26*100 -> -100
A27: Philippine Rural Development Projects*** | B27: 0 | C27: =PRDP!E11 -> 238756 | D27: 0 | E27: 0 | F27: =D27+E27 -> 0 | G27: =F27-C27 -> -238756 | H27: =G27/C27*100 -> -100
A28: TOTAL | B28: =SUM(B10:B27) -> 623513.77 | C28: =SUM(C10:C27) -> 1211769.8 | D28: =SUM(D10:D27) -> 452240.68 | E28: =SUM(E10:E27) -> 840076.1 | F28: =D28+E28 -> 1292316.8 | G28: =F28-C28 -> 80547.006 | H28: =G28/C28*100 -> 6.6470552
A31: Prepared by:
A35: JONAZON JEFF T. FACTORA
A36: Chief, Planning and Investment
A37: Programming Section
A38: *Program Implementation started on FY 2025 | F38: 527086.78
A39: ** Under Procurement
A40: ***Pipelined/Proposal
A42: Prepared by: | D42: In coordination with: | G42: Concurred by:
A47: BERNADETTE T. GALOSO | D47: MACARIO B. ANDAL, CPA | G47: ROSE MARY G. AQUINO, Ph.D.
A48: Chief, PMED | D48: Chief, Budget Section | G48: Regional Executive Director
