Workbook
Name ABRA: OU!$A$38:$A$64
Name AGUSAN_DEL_NORTE: OU!$BX$38:$BX$49
Name AGUSAN_DEL_SUR: OU!$BY$38:$BY$51
Name AKLAN: OU!$AN$38:$AN$54
Name ALBAY: OU!$AH$38:$AH$55
Name ANTIQUE: OU!$AO$38:$AO$55
Name APAYAO: OU!$B$38:$B$44
Name ATI: OU!$Q$3
Name AURORA: OU!$Q$38:$Q$45
Name BAGUIO_CITY: OU!$G$38
Name BAR: OU!$R$3
Name BATAAN: OU!$R$38:$R$49
Name BATANES: OU!$L$38:$L$43
Name BATANGAS: OU!$X$38:$X$71
Name BENGUET: OU!$C$38:$C$50
Name BILIRAN: OU!$AX$38:$AX$45
Name BOHOL: OU!$AT$38:$AT$85
Name BPI: OU!$S$3
Name BSWM: OU!$T$3
Name BUKIDNON: OU!$BI$38:$BI$59
Name BULACAN: OU!$S$38:$S$61
Name BUTUAN_CITY: OU!$CC$38
Name CAGAYAN: OU!$M$38:$M$66
Name CAMARINES_NORTE: OU!$AI$38:$AI$49
Name CAMARINES_SUR: OU!$AJ$38:$AJ$74
Name CAMIGUIN: OU!$BJ$38:$BJ$42
Name CAPIZ: OU!$AP$38:$AP$54
Name CAR: OU!$A$3:$A$10
Name Cassava: PAPbyCommodity!$C$3:$C$7
Name Cassava_AMEFSS: PAPbyCommodity!$E$64:$E$85
Name Cassava_ESETS: PAPbyCommodity!$C$64:$C$74
Name Cassava_INS: PAPbyCommodity!$F$64:$F$69
Name Cassava_PSS: PAPbyCommodity!$B$64:$B$69
Name Cassava_RND: PAPbyCommodity!$D$64:$D$88
Name CATANDUANES: OU!$AK$38:$AK$48
Name CAVITE: OU!$Y$38:$Y$60
Name CEBU: OU!$AU$38:$AU$90
Name Corn: PAPbyCommodity!$B$3:$B$7
Name Corn_AMEFSS: PAPbyCommodity!$E$10:$E$63
Name Corn_ESETS: PAPbyCommodity!$C$10:$C$57
Name Corn_INS: PAPbyCommodity!$F$10:$F$21
Name Corn_PSS: PAPbyCommodity!$B$10:$B$42
Name Corn_RND: PAPbyCommodity!$D$10:$D$39
Name DAVAO_CITY: OU!$BR$38
Name DAVAO_DE_ORO: OU!$BQ$38:$BQ$48
Name DAVAO_DEL_NORTE: OU!$BN$38:$BN$48
Name DAVAO_DEL_SUR: OU!$BO$38:$BO$47
Name DAVAO_OCCIDENTAL: OU!$BS$38:$BS$42
Name DAVAO_ORIENTAL: OU!$BP$38:$BP$48
Name DINAGAT_ISLANDS: OU!$BZ$38:$BZ$44
Name DISTRICT: DISTRICT!$A$2:$H$1744
Name EASTERN_SAMAR: OU!$AY$38:$AY$63
Name GUIMARAS: OU!$AQ$38:$AQ$42
Name IFUGAO: OU!$D$38:$D$48
Name ILOCOS_NORTE: OU!$H$38:$H$60
Name ILOCOS_SUR: OU!$I$38:$I$71
Name ILOILO: OU!$AR$38:$AR$81
Name ISABELA: OU!$N$38:$N$74
Name ISABELA_CITY: OU!$BH$38
Name KALINGA: OU!$E$38:$E$45

Sheet PICS
B1: FY 2025 PLAN AND BUDGET PROPOSAL
B2: BASED ON NATIONAL EXPENDITURE PROGRAM (NEP)
B3: BED 2: PHYSICAL
B4: NAME OF OU | C4: ='CAPTURE SHEET - PHYSICAL'!C2 -> RFOII
B5: PRPOPOSAL/BEDS | C5: BED 2 - PHYSICAL
A6: 1 | B6: 2 | C6: 3 | D6: 4 | E6: 5 | F6: 6 | G6: 7 | H6: 8 | I6: 9 | J6: 10 | K6: 11 | L6: 12 | M6: 13 | N6: 14 | O6: 15 | P6: 16 | Q6: 17 | R6: 18 | S6: 19 | T6: 20 | U6: 21 | V6: 22 | W6: 23 | X6: 24
E7: QUARTER | F7: Values
E8: 1ST QTR | F8: 1ST QTR | G8: 1ST QTR | H8: 1ST QTR | I8: 1ST QTR | J8: 2ND QTR | K8: 2ND QTR | L8: 2ND QTR | M8: 2ND QTR | N8: 2ND QTR | O8: 3RD QTR | P8: 3RD QTR | Q8: 3RD QTR | R8: 3RD QTR | S8: 3RD QTR | T8: 4TH QTR | U8: 4TH QTR | V8: 4TH QTR | W8: 4TH QTR | X8: 4TH QTR
B9: PREXC SUB-PROGRAM | C9: PROVINCE | D9: ACTIVITY | E9: PHYSICAL TARGET | F9: GROUP BENEF | G9: Sum of FEMALE BENEFICIARIES | H9: Sum of MALE BENEFICIARIES | I9: ALLOCATION (Php'000) | J9: PHYSICAL TARGET | K9: GROUP BENEF | L9: Sum of FEMALE BENEFICIARIES | M9: Sum of MALE BENEFICIARIES | N9: ALLOCATION (Php'000) | O9: PHYSICAL TARGET | P9: GROUP BENEF | Q9: Sum of FEMALE BENEFICIARIES | R9: Sum of MALE BENEFICIARIES | S9: ALLOCATION (Php'000) | T9: PHYSICAL TARGET | U9: GROUP BENEF | V9: Sum of FEMALE BENEFICIARIES | W9: Sum of MALE BENEFICIARIES | X9: ALLOCATION (Php'000)
B10: PSS | E10: 3500 | F10: 2 | I10: 163 | J10: 1465794 | K10: 29 | N10: 268793 | O10: 8596967 | P10: 202 | S10: 508173.25 | T10: 835951 | U10: 22 | X10: 11310.75
A11: Cagayan | B11: PSS | C11: Cagayan
A12: CagayanSeed Production - White Corn Registered Seeds | B12: PSS | C12: Cagayan | D12: Seed Production - White Corn Registered Seeds | J12: 3000 | K12: 8 | N12: 150.5 | O12: 1000 | P12: 2 | S12: 50.5 | T12: 2000 | X12: 100
A13: CagayanRCPT - Yellow Corn seeds | B13: PSS | C13: Cagayan | D13: RCPT - Yellow Corn seeds | O13: 9000 | P13: 2 | S13: 6000
A14: CagayanRCPT - Inorganic fertilizer for YC seeds | B14: PSS | C14: Cagayan | D14: RCPT - Inorganic fertilizer for YC seeds | O14: 275000 | P14: 2 | S14: 12375
A15: CagayanBiofertilizer | B15: PSS | C15: Cagayan | D15: Biofertilizer | O15: 2000 | P15: 2 | S15: 1360
A16: CagayanSoil Ameliorant | B16: PSS | C16: Cagayan | D16: Soil Ameliorant | O16: 250000 | P16: 2 | S16: 5000
A17: CagayanYCPEP - Yellow Corn Hybrid seeds | B17: PSS | C17: Cagayan | D17: YCPEP - Yellow Corn Hybrid seeds | O17: 125010 | P17: 25 | S17: 83340
A18: CagayanYCPEP - Inorganic fertilizer for YC Hybrid seeds | B18: PSS | C18: Cagayan | D18: YCPEP - Inorganic fertilizer for YC Hybrid seeds | O18: 694500 | P18: 25 | S18: 31252.5
A19: CagayanCassava Production (seed pieces) | B19: PSS | C19: Cagayan | D19: Cassava Production (seed pieces) | O19: 130000 | P19: 3 | S19: 130
A20: CagayanCassava Procurement (seed pieces) | B20: PSS | C20: Cagayan | D20: Cassava Procurement (seed pieces) | O20: 240000 | P20: 2 | S20: 360
A21: CagayanInorganic fertilizer for Cassava | B21: PSS | C21: Cagayan | D21: Inorganic fertilizer for Cassava | O21: 3700 | P21: 5 | S21: 166.5
A22: Isabela | B22: PSS | C22: Isabela
A23: IsabelaSeed Production - White Corn Registered Seeds | B23: PSS | C23: Isabela | D23: Seed Production - White Corn Registered Seeds | J23: 4000 | K23: 13 | N23: 201 | T23: 4000 | U23: 4 | X23: 201
A24: IsabelaRCPT - Yellow Corn seeds | B24: PSS | C24: Isabela | D24: RCPT - Yellow Corn seeds | O24: 9000 | P24: 2 | S24: 6000
A25: IsabelaRCPT - Inorganic fertilizer for YC seeds | B25: PSS | C25: Isabela | D25: RCPT - Inorganic fertilizer for YC seeds | O25: 275000 | P25: 2 | S25: 12375
A26: IsabelaBiofertilizer | B26: PSS | C26: Isabela | D26: Biofertilizer | O26: 2000 | P26: 2 | S26: 1360
A27: IsabelaSoil Ameliorant | B27: PSS | C27: Isabela | D27: Soil Ameliorant | O27: 250000 | P27: 2 | S27: 5000
A28: IsabelaYCPEP - Yellow Corn Hybrid seeds | B28: PSS | C28: Isabela | D28: YCPEP - Yellow Corn Hybrid seeds | O28: 301140 | P28: 35 | S28: 200760
A29: IsabelaYCPEP - Inorganic fertilizer for YC Hybrid seeds | B29: PSS | C29: Isabela | D29: YCPEP - Inorganic fertilizer for YC Hybrid seeds | O29: 1673000 | P29: 35 | S29: 75285
A30: IsabelaCassava Production (seed pieces) | B30: PSS | C30: Isabela | D30: Cassava Production (seed pieces) | J30: 255000 | K30: 2 | N30: 255 | O30: 200000 | P30: 1 | S30: 200
A31: IsabelaCassava Procurement (seed pieces) | B31: PSS | C31: Isabela | D31: Cassava Procurement (seed pieces) | J31: 730000 | K31: 2 | N31: 1095 | O31: 2450000 | P31: 6 | S31: 3675 | T31: 500000 | U31: 1 | X31: 750
A32: IsabelaInorganic fertilizer for Cassava | B32: PSS | C32: Isabela | D32: Inorganic fertilizer for Cassava | J32: 9900 | K32: 4 | N32: 445.5 | O32: 26500 | P32: 7 | S32: 1192.5 | T32: 5000 | U32: 1 | X32: 225
A33: IsabelaSeed Procurement - Sorghum | B33: PSS | C33: Isabela | D33: Seed Procurement - Sorghum | T33: 20000 | U33: 1 | X33: 1750
A34: IsabelaInorganic fertilizer for Sorghum | B34: PSS | C34: Isabela | D34: Inorganic fertilizer for Sorghum | T34: 100000 | U34: 1 | X34: 4500
A35: IsabelaSeed Production - Soybean | B35: PSS | C35: Isabela | D35: Seed Production - Soybean | E35: 1000 | F35: 1 | I35: 50
A36: IsabelaInorganic fertilizer for Soybean | B36: PSS | C36: Isabela | D36: Inorganic fertilizer for Soybean | E36: 2500 | F36: 1 | I36: 113
A37: Nueva Vizcaya | B37: PSS | C37: Nueva_Vizcaya
A38: Nueva VizcayaSeed Production - White Corn Registered Seeds | B38: PSS | C38: Nueva_Vizcaya | D38: Seed Production - White Corn Registered Seeds | T38: 4000 | U38: 6 | X38: 201
A39: Nueva VizcayaYCPEP - Yellow Corn Hybrid seeds | B39: PSS | C39: Nueva_Vizcaya | D39: YCPEP - Yellow Corn Hybrid seeds | O39: 16200 | P39: 10 | S39: 10800
A40: Nueva VizcayaYCPEP - Inorganic fertilizer for YC Hybrid seeds | B40: PSS | C40: Nueva_Vizcaya | D40: YCPEP - Inorganic fertilizer for YC Hybrid seeds | O40: 90000 | P40: 10 | S40: 4050
...

Sheet HOW TO FILL OUT
A1: A. CAPTURE SHEET - FINANCIAL
A2: COLUMNS | B2: INSTRUCTIONS
A3: PRPOPOSAL/BEDS | B3: Select BED 1 for obligation and BED 3 for disbursement
A4: OU | B4: Select your respective OUs name
A5: SPECIFIC COMMODITY | B5: Select appropriate commodity to activate dropdown list for the "COMMODITY PREXC SUBPROGRAM" column.
A6: COMMODITY PREXC SUB-PROGRAM | B6: Select appropriate PREXC subprogram to activate the PAP list in the ACTIVITY column
A7: ACTIVITY | B7: Select target activity
A8: TAG- GAD | B8: Select "YES" for activities to be committed as GAD budget (total GAD budget should be at least 5% of the total budget of the OU)
A9: MONTH | B9: Select target month of obligation or disbursement
A10: MOOE (Php '000) | B10: Input corresponding MOOE budget for the activity. Should be a whole number and the same with the submitted BP 201 and BED 2 input
A11: CO (Php '000) | B11: Input corresponding CO budget for the activity. Should be a whole number and the same with the submitted BP 201 and BED 2 input
A14: B. CAPTURE SHEET - PHYSICAL
A15: Inputting for this capture sheet is per cluster beneficiary for PSS, AMEFSS, and INS PAPs
A16: COLUMNS | B16: INSTRUCTIONS
A17: PRPOPOSAL/BEDS | B17: Select BED 2 - Physical
A18: OU | B18: Select your respective OUs name to activate the list of provinces
A19: CLUSTER BENEFICIARY | B19: Input name of cluster beneficiary. One name per row. Do not put multiple names
A20: PROVINCE | B20: Select target province
A21: MUNICIPALITY | B21: Select target municipality
A22: SPECIFIC COMMODITY | B22: Select appropriate commodity to activate dropdown list for the "COMMODITY PREXC SUBPROGRAM" column.
A23: COMMODITY PREXC SUB-PROGRAM | B23: Select appropriate PREXC subprogram to activate the PAP list in the ACTIVITY column
A24: ACTIVITY | B24: Select target activity
A25: TAG-GAD | B25: Select "YES" for activities to be committed as GAD budget (total GAD budget should be at least 5% of the total budget of the OU)
A26: MONTH | B26: Select target month for accomplishment of PAP
A27: TARGET | B27: Input quantity
... A34: GROUP BENEFICIARIES | B34: Input "1" since the inputting will be per cluster beneficiaries
A37: C. DATA GENERATION
A38: 1. Click any of the green sheets (BED 1 and 3 Summary and BED 2 Summary).
A39: 2. On the Toolbar, click Data.
A40: 3. On the Data Tab, click Refresh All to update the generated data in the green sheets.
A42: D. DATA REVIEW/ CHECKING
A43: for BED13 Checking and BED13 vs BED2 sheets
A44: 1. Click any of the orange sheets (BED13 Checking and BED13 vs BED2 sheets).
A45: 2. On the Toolbar, click Data.
A46: 3. On the Data Tab, click Refresh All to update the generated data in the pivot table.
A47: 4. After refreshing the data:
A48: - In BED13 Checking, compare or check if the amount inputted per expense class (MOOE/CO) in BED 1 is tally with the BED 3. Also, check if the budget inputted per PAP is correct.
A49: - In BED2 Checking, check if your inputted physical targets is correct
A50: - In BED13 vs BED2 checking, compare or check if the amount inputted per PAP in BED 2 is tally with the inputted amount in BEDs1 and 3.

Sheet BED 1
A1: CY 2025 PLAN AND BUDGET PROPOSAL
A2: BASED ON GENERAL APPROPRIATIONS ACT (GAA)
A3: BED 1 OBLIGATION
D5: PROPOSAL/BEDS | E5: YEAR | F5: QUARTER | G5: MONTH | H5: Values
D6: BED 1 - OBLIGATION | BC6: BED 1 - OBLIGATION MOOE | BD6: BED 1 - OBLIGATION CO | BE6: BED 1 - OBLIGATION TOTAL | BF6: BED 3 - DISBURSEMENT | DQ6: BED 3 - DISBURSEMENT MOOE | DR6: BED 3 - DISBURSEMENT CO | DS6: BED 3 - DISBURSEMENT TOTAL
D7: 2025 | AZ7: 2025 MOOE | BA7: 2025 CO | BB7: 2025 TOTAL | BF7: 2025 | CY7: 2025 MOOE | CZ7: 2025 CO | DA7: 2025 TOTAL | DB7: 2026 | DN7: 2026 MOOE | DO7: 2026 CO | DP7: 2026 TOTAL
D8: 1ST QTR | M8: 1ST QTR MOOE | N8: 1ST QTR CO | O8: 1ST QTR TOTAL | P8: 2ND QTR | Y8: 2ND QTR MOOE | Z8: 2ND QTR CO | AA8: 2ND QTR TOTAL | AB8: 3RD QTR | AK8: 3RD QTR MOOE | AL8: 3RD QTR CO | AM8: 3RD QTR TOTAL | AN8: 4TH QTR | AW8: 4TH QTR MOOE | AX8: 4TH QTR CO | AY8: 4TH QTR TOTAL | BF8: 1ST QTR | BL8: 1ST QTR MOOE | BM8: 1ST QTR CO | BN8: 1ST QTR TOTAL | BO8: 2ND QTR | BX8: 2ND QTR MOOE | BY8: 2ND QTR CO | BZ8: 2ND QTR TOTAL | CA8: 3RD QTR | CJ8: 3RD QTR MOOE | CK8: 3RD QTR CO | CL8: 3RD QTR TOTAL | CM8: 4TH QTR | CV8: 4TH QTR MOOE | CW8: 4TH QTR CO | CX8: 4TH QTR TOTAL | DB8: 1ST QTR 2026 | DK8: 1ST QTR 2026 MOOE | DL8: 1ST QTR 2026 CO | DM8: 1ST QTR 2026 TOTAL
D9: JANUARY | G9: FEBRUARY | J9: MARCH | P9: APRIL | S9: MAY | V9: JUNE | AB9: JULY | AE9: AUGUST | AH9: SEPTEMBER | AN9: OCTOBER | AQ9: NOVEMBER | AT9: DECEMBER | BF9: FEBRUARY | BI9: MARCH | BO9: APRIL | BR9: MAY | BU9: JUNE | CA9: JULY | CD9: AUGUST | CG9: SEPTEMBER | CM9: OCTOBER | CP9: NOVEMBER | CS9: DECEMBER | DB9: FEBRUARY 2026 | DE9: JANUARY 2026 | DH9: MARCH 2026
A10: PREXC SUB-PROGRAM | B10: STRATEGY | C10: ACTIVITY | D10: MOOE | E10: CO | F10: TOTAL | G10: MOOE | H10: CO | I10: TOTAL | J10: MOOE | K10: CO | L10: TOTAL | P10: MOOE | Q10: CO | R10: TOTAL | S10: MOOE | T10: CO | U10: TOTAL | V10: MOOE | W10: CO | X10: TOTAL | AB10: MOOE | AC10: CO | AD10: TOTAL | AE10: MOOE | AF10: CO | AG10: TOTAL | AH10: MOOE | AI10: CO | AJ10: TOTAL | AN10: MOOE | AO10: CO | AP10: TOTAL | AQ10: MOOE | AR10: CO | AS10: TOTAL | AT10: MOOE | AU10: CO | AV10: TOTAL | BF10: MOOE | BG10: CO | BH10: TOTAL | BI10: MOOE | BJ10: CO | BK10: TOTAL | BO10: MOOE | BP10: CO | BQ10: TOTAL | BR10: MOOE | BS10: CO | BT10: TOTAL | BU10: MOOE | BV10: CO | BW10: TOTAL | CA10: MOOE | CB10: CO | CC10: TOTAL | CD10: MOOE | CE10: CO | CF10: TOTAL | CG10: MOOE | CH10: CO | CI10: TOTAL | CM10: MOOE | CN10: CO | CO10: TOTAL | CP10: MOOE | CQ10: CO | CR10: TOTAL | CS10: MOOE | CT10: CO | CU10: TOTAL | DB10: MOOE | DC10: CO | DD10: TOTAL | DE10: MOOE | DF10: CO | DG10: TOTAL | DH10: MOOE | DI10: CO | DJ10: TOTAL
A11: PSS
B12: OPV Seed Production
C13: Seed Production - White Corn Registered Seeds | J13: 1105 | L13: 1105 | M13: 1105 | O13: 1105 | AZ13: 1105 | BB13: 1105 | BC13: 1105 | BE13: 1105 | BR13: 1105 | BT13: 1105 | BX13: 1105 | BZ13: 1105 | CY13: 1105 | DA13: 1105 | DQ13: 1105 | DS13: 1105
B14: Corn Seed Reserve
C15: DRRM - White Corn Seed Procured OPV | J15: 1500 | L15: 1500 | M15: 1500 | O15: 1500 | AZ15: 1500 | BB15: 1500 | BC15: 1500 | BE15: 1500 | BR15: 1500 | BT15: 1500 | BX15: 1500 | BZ15: 1500 | CY15: 1500 | DA15: 1500 | DQ15: 1500 | DS15: 1500
C16: DRRM - Yellow Corn Seed Procured OPV | J16: 300 | L16: 300 | M16: 300 | O16: 300 | AZ16: 300 | BB16: 300 | BC16: 300 | BE16: 300 | BR16: 300 | BT16: 300 | BX16: 300 | BZ16: 300 | CY16: 300 | DA16: 300 | DQ16: 300 | DS16: 300
C17: DRRM - Yellow Corn Seed Procured Hybrid | P17: 250596 | R17: 250596 | Y17: 250596 | AA17: 250596 | AZ17: 250596 | BB17: 250596 | BC17: 250596 | BE17: 250596 | CA17: 250596 | CC17: 250596 | CJ17: 250596 | CL17: 250596 | CY17: 250596 | DA17: 250596 | DQ17: 250596 | DS17: 250596
B18: Recommended Corn Production Technology
C19: RCPT - Yellow Corn seeds | J19: 12000 | L19: 12000 | M19: 12000 | O19: 12000 | AZ19: 12000 | BB19: 12000 | BC19: 12000 | BE19: 12000 | CD19: 12000 | CF19: 12000 | CJ19: 12000 | CL19: 12000 | CY19: 12000 | DA19: 12000 | DQ19: 12000 | DS19: 12000
C20: RCPT - Inorganic fertilizer for YC seeds | P20: 17600 | R20: 17600 | Y20: 17600 | AA20: 17600 | AB20: 7150 | AD20: 7150 | AK20: 7150 | AM20: 7150 | AZ20: 24750 | BB20: 24750 | BC20: 24750 | BE20: 24750 | CA20: 17600 | CC20: 17600 | CJ20: 17600 | CL20: 17600 | CP20: 7150 | CR20: 7150 | CV20: 7150 | CX20: 7150 | CY20: 24750 | DA20: 24750 | DQ20: 24750 | DS20: 24750
B21: Soil amendments
C22: Biofertilizer | J22: 2720 | L22: 2720 | M22: 2720 | O22: 2720 | AZ22: 2720 | BB22: 2720 | BC22: 2720 | BE22: 2720 | CA22: 2720 | CC22: 2720 | CJ22: 2720 | CL22: 2720 | CY22: 2720 | DA22: 2720 | DQ22: 2720 | DS22: 2720
C23: Soil Ameliorant | J23: 7000 | L23: 7000 | M23: 7000 | O23: 7000 | AB23: 3000 | AD23: 3000 | AK23: 3000 | AM23: 3000 | AZ23: 10000 | BB23: 10000 | BC23: 10000 | BE23: 10000 | CA23: 7000 | CC23: 7000 | CJ23: 7000 | CL23: 7000 | CP23: 3000 | CR23: 3000 | CV23: 3000 | CX23: 3000 | CY23: 10000 | DA23: 10000 | DQ23: 10000 | DS23: 10000
B24: Yellow Corn Production Enhancement Project
C25: YCPEP - Yellow Corn Hybrid seeds | P25: 324000 | R25: 324000 | Y25: 324000 | AA25: 324000 | AZ25: 324000 | BB25: 324000 | BC25: 324000 | BE25: 324000 | CD25: 324000 | CF25: 324000 | CJ25: 324000 | CL25: 324000 | CY25: 324000 | DA25: 324000 | DQ25: 324000 | DS25: 324000
C26: YCPEP - Inorganic fertilizer for YC Hybrid seeds | J26: 86400 | L26: 86400 | M26: 86400 | O26: 86400 | AB26: 35100 | AD26: 35100 | AK26: 35100 | AM26: 35100 | AZ26: 121500 | BB26: 121500 | BC26: 121500 | BE26: 121500 | CA26: 86400 | CC26: 86400 | CJ26: 86400 | CL26: 86400 | CP26: 35100 | CR26: 35100 | CV26: 35100 | CX26: 35100 | CY26: 121500 | DA26: 121500 | DQ26: 121500 | DS26: 121500
B27: Pest and Disease Management
C28: DRRM - Agricultural chemicals (Insecticide in liters) | J28: 6000 | L28: 6000 | M28: 6000 | O28: 6000 | AZ28: 6000 | BB28: 6000 | BC28: 6000 | BE28: 6000 | BU28: 6000 | BW28: 6000 | BX28: 6000 | BZ28: 6000 | CY28: 6000 | DA28: 6000 | DQ28: 6000 | DS28: 6000
C29: DRRM - Agricultural chemicals (Rodenticides) | J29: 1500 | L29: 1500 | M29: 1500 | O29: 1500 | AZ29: 1500 | BB29: 1500 | BC29: 1500 | BE29: 1500 | BU29: 1500 | BW29: 1500 | BX29: 1500 | BZ29: 1500 | CY29: 1500 | DA29: 1500 | DQ29: 1500 | DS29: 1500
C30: DRRM - Agricultural chemicals (Pheromone lure) | J30: 2750 | L30: 2750 | M30: 2750 | O30: 2750 | AZ30: 2750 | BB30: 2750 | BC30: 2750 | BE30: 2750 | BU30: 2750 | BW30: 2750 | BX30: 2750 | BZ30: 2750 | CY30: 2750 | DA30: 2750 | DQ30: 2750 | DS30: 2750
C31: DRRM - Agricultural chemicals (Streptomycin) | J31: 4000 | L31: 4000 | M31: 4000 | O31: 4000 | AZ31: 4000 | BB31: 4000 | BC31: 4000 | BE31: 4000 | CA31: 4000 | CC31: 4000 | CJ31: 4000 | CL31: 4000 | CY31: 4000 | DA31: 4000 | DQ31: 4000 | DS31: 4000
B32: Cassava Production Enhancement Project
C33: Cassava Production (seed pieces) | J33: 975 | L33: 975 | M33: 975 | O33: 975 | AZ33: 975 | BB33: 975 | BC33: 975 | BE33: 975 | BR33: 975 | BT33: 975 | BX33: 975 | BZ33: 975 | CY33: 975 | DA33: 975 | DQ33: 975 | DS33: 975
C34: Cassava Procurement (seed pieces) | J34: 7500 | L34: 7500 | M34: 7500 | O34: 7500 | AZ34: 7500 | BB34: 7500 | BC34: 7500 | BE34: 7500 | CA34: 7500 | CC34: 7500 | CJ34: 7500 | CL34: 7500 | CY34: 7500 | DA34: 7500 | DQ34: 7500 | DS34: 7500
C35: Inorganic fertilizer for Cassava | J35: 1913.6 | L35: 1913.6 | M35: 1913.6 | O35: 1913.6 | AB35: 777.4 | AD35: 777.4 | AK35: 777.4 | AM35: 777.4 | AZ35: 2691 | BB35: 2691 | BC35: 2691 | BE35: 2691 | CA35: 1913.6 | CC35: 1913.6 | CJ35: 1913.6 | CL35: 1913.6 | CP35: 777.4 | CR35: 777.4 | CV35: 777.4 | CX35: 777.4 | CY35: 2691 | DA35: 2691 | DQ35: 2691 | DS35: 2691
B36: Sorghum Production Enhancement Project
C37: Seed Procurement - Sorghum | J37: 1750 | L37: 1750 | M37: 1750 | O37: 1750 | AZ37: 1750 | BB37: 1750 | BC37: 1750 | BE37: 1750 | CA37: 1750 | CC37: 1750 | CJ37: 1750 | CL37: 1750 | CY37: 1750 | DA37: 1750 | DQ37: 1750 | DS37: 1750
C38: Inorganic fertilizer for Sorghum | J38: 3800 | L38: 3800 | M38: 3800 | O38: 3800 | AB38: 700 | AD38: 700 | AK38: 700 | AM38: 700 | AZ38: 4500 | BB38: 4500 | BC38: 4500 | BE38: 4500 | CA38: 3800 | CC38: 3800 | CJ38: 3800 | CL38: 3800 | CP38: 700 | CR38: 700 | CV38: 700 | CX38: 700 | CY38: 4500 | DA38: 4500 | DQ38: 4500 | DS38: 4500
B39: Soybean Production Enhancement Project
C40: Seed Production - Soybean | G40: 50 | I40: 50 | M40: 50 | O40: 50 | AZ40: 50 | BB40: 50 | BC40: 50 | BE40: 50 | BR40: 50 | BT40: 50 | BX40: 50 | BZ40: 50 | CY40: 50 | DA40: 50 | DQ40: 50 | DS40: 50
C41: Inorganic fertilizer for Soybean | G41: 113 | I41: 113 | M41: 113 | O41: 113 | AZ41: 113 | BB41: 113 | BC41: 113 | BE41: 113 | BR41: 113 | BT41: 113 | BX41: 113 | BZ41: 113 | CY41: 113 | DA41: 113 | DQ41: 113 | DS41: 113
...

Sheet BED 3
A1: CY 2025 PLAN AND BUDGET PROPOSAL
A2: BASED ON GENERAL APPROPRIATIONS ACT (GAA)
A3: BED 3 DISBURSEMENT
D5: PROPOSAL/BEDS | E5: YEAR | F5: QUARTER | G5: MONTH | H5: Values
D6: BED 1 - OBLIGATION | BC6: BED 1 - OBLIGATION MOOE | BD6: BED 1 - OBLIGATION CO | BE6: BED 1 - OBLIGATION TOTAL | BF6: BED 3 - DISBURSEMENT | DQ6: BED 3 - DISBURSEMENT MOOE | DR6: BED 3 - DISBURSEMENT CO | DS6: BED 3 - DISBURSEMENT TOTAL
D7: 2025 | AZ7: 2025 MOOE | BA7: 2025 CO | BB7: 2025 TOTAL | BF7: 2025 | CY7: 2025 MOOE | CZ7: 2025 CO | DA7: 2025 TOTAL | DB7: 2026 | DN7: 2026 MOOE | DO7: 2026 CO | DP7: 2026 TOTAL
D8: 1ST QTR | M8: 1ST QTR MOOE | N8: 1ST QTR CO | O8: 1ST QTR TOTAL | P8: 2ND QTR | Y8: 2ND QTR MOOE | Z8: 2ND QTR CO | AA8: 2ND QTR TOTAL | AB8: 3RD QTR | AK8: 3RD QTR MOOE | AL8: 3RD QTR CO | AM8: 3RD QTR TOTAL | AN8: 4TH QTR | AW8: 4TH QTR MOOE | AX8: 4TH QTR CO | AY8: 4TH QTR TOTAL | BF8: 1ST QTR | BL8: 1ST QTR MOOE | BM8: 1ST QTR CO | BN8: 1ST QTR TOTAL | BO8: 2ND QTR | BX8: 2ND QTR MOOE | BY8: 2ND QTR CO | BZ8: 2ND QTR TOTAL | CA8: 3RD QTR | CJ8: 3RD QTR MOOE | CK8: 3RD QTR CO | CL8: 3RD QTR TOTAL | CM8: 4TH QTR | CV8: 4TH QTR MOOE | CW8: 4TH QTR CO | CX8: 4TH QTR TOTAL | DB8: 1ST QTR 2026 | DK8: 1ST QTR 2026 MOOE | DL8: 1ST QTR 2026 CO | DM8: 1ST QTR 2026 TOTAL
D9: JANUARY | G9: FEBRUARY | J9: MARCH | P9: APRIL | S9: MAY | V9: JUNE | AB9: JULY | AE9: AUGUST | AH9: SEPTEMBER | AN9: OCTOBER | AQ9: NOVEMBER | AT9: DECEMBER | BF9: FEBRUARY | BI9: MARCH | BO9: APRIL | BR9: MAY | BU9: JUNE | CA9: JULY | CD9: AUGUST | CG9: SEPTEMBER | CM9: OCTOBER | CP9: NOVEMBER | CS9: DECEMBER | DB9: FEBRUARY 2026 | DE9: JANUARY 2026 | DH9: MARCH 2026
A10: PREXC SUB-PROGRAM | B10: STRATEGY | C10: ACTIVITY | D10: MOOE | E10: CO | F10: TOTAL | G10: MOOE | H10: CO | I10: TOTAL | J10: MOOE | K10: CO | L10: TOTAL | P10: MOOE | Q10: CO | R10: TOTAL | S10: MOOE | T10: CO | U10: TOTAL | V10: MOOE | W10: CO | X10: TOTAL | AB10: MOOE | AC10: CO | AD10: TOTAL | AE10: MOOE | AF10: CO | AG10: TOTAL | AH10: MOOE | AI10: CO | AJ10: TOTAL | AN10: MOOE | AO10: CO | AP10: TOTAL | AQ10: MOOE | AR10: CO | AS10: TOTAL | AT10: MOOE | AU10: CO | AV10: TOTAL | BF10: MOOE | BG10: CO | BH10: TOTAL | BI10: MOOE | BJ10: CO | BK10: TOTAL | BO10: MOOE | BP10: CO | BQ10: TOTAL | BR10: MOOE | BS10: CO | BT10: TOTAL | BU10: MOOE | BV10: CO | BW10: TOTAL | CA10: MOOE | CB10: CO | CC10: TOTAL | CD10: MOOE | CE10: CO | CF10: TOTAL | CG10: MOOE | CH10: CO | CI10: TOTAL | CM10: MOOE | CN10: CO | CO10: TOTAL | CP10: MOOE | CQ10: CO | CR10: TOTAL | CS10: MOOE | CT10: CO | CU10: TOTAL | DB10: MOOE | DC10: CO | DD10: TOTAL | DE10: MOOE | DF10: CO | DG10: TOTAL | DH10: MOOE | DI10: CO | DJ10: TOTAL
A11: PSS
B12: OPV Seed Production
C13: Seed Production - White Corn Registered Seeds | J13: 1105 | L13: 1105 | M13: 1105 | O13: 1105 | AZ13: 1105 | BB13: 1105 | BC13: 1105 | BE13: 1105 | BR13: 1105 | BT13: 1105 | BX13: 1105 | BZ13: 1105 | CY13: 1105 | DA13: 1105 | DQ13: 1105 | DS13: 1105
B14: Corn Seed Reserve
C15: DRRM - White Corn Seed Procured OPV | J15: 1500 | L15: 1500 | M15: 1500 | O15: 1500 | AZ15: 1500 | BB15: 1500 | BC15: 1500 | BE15: 1500 | BR15: 1500 | BT15: 1500 | BX15: 1500 | BZ15: 1500 | CY15: 1500 | DA15: 1500 | DQ15: 1500 | DS15: 1500
C16: DRRM - Yellow Corn Seed Procured OPV | J16: 300 | L16: 300 | M16: 300 | O16: 300 | AZ16: 300 | BB16: 300 | BC16: 300 | BE16: 300 | BR16: 300 | BT16: 300 | BX16: 300 | BZ16: 300 | CY16: 300 | DA16: 300 | DQ16: 300 | DS16: 300
C17: DRRM - Yellow Corn Seed Procured Hybrid | P17: 250596 | R17: 250596 | Y17: 250596 | AA17: 250596 | AZ17: 250596 | BB17: 250596 | BC17: 250596 | BE17: 250596 | CA17: 250596 | CC17: 250596 | CJ17: 250596 | CL17: 250596 | CY17: 250596 | DA17: 250596 | DQ17: 250596 | DS17: 250596
B18: Recommended Corn Production Technology
C19: RCPT - Yellow Corn seeds | J19: 12000 | L19: 12000 | M19: 12000 | O19: 12000 | AZ19: 12000 | BB19: 12000 | BC19: 12000 | BE19: 12000 | CD19: 12000 | CF19: 12000 | CJ19: 12000 | CL19: 12000 | CY19: 12000 | DA19: 12000 | DQ19: 12000 | DS19: 12000
C20: RCPT - Inorganic fertilizer for YC seeds | P20: 17600 | R20: 17600 | Y20: 17600 | AA20: 17600 | AB20: 7150 | AD20: 7150 | AK20: 7150 | AM20: 7150 | AZ20: 24750 | BB20: 24750 | BC20: 24750 | BE20: 24750 | CA20: 17600 | CC20: 17600 | CJ20: 17600 | CL20: 17600 | CP20: 7150 | CR20: 7150 | CV20: 7150 | CX20: 7150 | CY20: 24750 | DA20: 24750 | DQ20: 24750 | DS20: 24750
B21: Soil amendments
C22: Biofertilizer | J22: 2720 | L22: 2720 | M22: 2720 | O22: 2720 | AZ22: 2720 | BB22: 2720 | BC22: 2720 | BE22: 2720 | CA22: 2720 | CC22: 2720 | CJ22: 2720 | CL22: 2720 | CY22: 2720 | DA22: 2720 | DQ22: 2720 | DS22: 2720
C23: Soil Ameliorant | J23: 7000 | L23: 7000 | M23: 7000 | O23: 7000 | AB23: 3000 | AD23: 3000 | AK23: 3000 | AM23: 3000 | AZ23: 10000 | BB23: 10000 | BC23: 10000 | BE23: 10000 | CA23: 7000 | CC23: 7000 | CJ23: 7000 | CL23: 7000 | CP23: 3000 | CR23: 3000 | CV23: 3000 | CX23: 3000 | CY23: 10000 | DA23: 10000 | DQ23: 10000 | DS23: 10000
B24: Yellow Corn Production Enhancement Project
C25: YCPEP - Yellow Corn Hybrid seeds | P25: 324000 | R25: 324000 | Y25: 324000 | AA25: 324000 | AZ25: 324000 | BB25: 324000 | BC25: 324000 | BE25: 324000 | CD25: 324000 | CF25: 324000 | CJ25: 324000 | CL25: 324000 | CY25: 324000 | DA25: 324000 | DQ25: 324000 | DS25: 324000
C26: YCPEP - Inorganic fertilizer for YC Hybrid seeds | J26: 86400 | L26: 86400 | M26: 86400 | O26: 86400 | AB26: 35100 | AD26: 35100 | AK26: 35100 | AM26: 35100 | AZ26: 121500 | BB26: 121500 | BC26: 121500 | BE26: 121500 | CA26: 86400 | CC26: 86400 | CJ26: 86400 | CL26: 86400 | CP26: 35100 | CR26: 35100 | CV26: 35100 | CX26: 35100 | CY26: 121500 | DA26: 121500 | DQ26: 121500 | DS26: 121500
B27: Pest and Disease Management
C28: DRRM - Agricultural chemicals (Insecticide in liters) | J28: 6000 | L28: 6000 | M28: 6000 | O28: 6000 | AZ28: 6000 | BB28: 6000 | BC28: 6000 | BE28: 6000 | BU28: 6000 | BW28: 6000 | BX28: 6000 | BZ28: 6000 | CY28: 6000 | DA28: 6000 | DQ28: 6000 | DS28: 6000
C29: DRRM - Agricultural chemicals (Rodenticides) | J29: 1500 | L29: 1500 | M29: 1500 | O29: 1500 | AZ29: 1500 | BB29: 1500 | BC29: 1500 | BE29: 1500 | BU29: 1500 | BW29: 1500 | BX29: 1500 | BZ29: 1500 | CY29: 1500 | DA29: 1500 | DQ29: 1500 | DS29: 1500
C30: DRRM - Agricultural chemicals (Pheromone lure) | J30: 2750 | L30: 2750 | M30: 2750 | O30: 2750 | AZ30: 2750 | BB30: 2750 | BC30: 2750 | BE30: 2750 | BU30: 2750 | BW30: 2750 | BX30: 2750 | BZ30: 2750 | CY30: 2750 | DA30: 2750 | DQ30: 2750 | DS30: 2750
C31: DRRM - Agricultural chemicals (Streptomycin) | J31: 4000 | L31: 4000 | M31: 4000 | O31: 4000 | AZ31: 4000 | BB31: 4000 | BC31: 4000 | BE31: 4000 | CA31: 4000 | CC31: 4000 | CJ31: 4000 | CL31: 4000 | CY31: 4000 | DA31: 4000 | DQ31: 4000 | DS31: 4000
B32: Cassava Production Enhancement Project
C33: Cassava Production (seed pieces) | J33: 975 | L33: 975 | M33: 975 | O33: 975 | AZ33: 975 | BB33: 975 | BC33: 975 | BE33: 975 | BR33: 975 | BT33: 975 | BX33: 975 | BZ33: 975 | CY33: 975 | DA33: 975 | DQ33: 975 | DS33: 975
C34: Cassava Procurement (seed pieces) | J34: 7500 | L34: 7500 | M34: 7500 | O34: 7500 | AZ34: 7500 | BB34: 7500 | BC34: 7500 | BE34: 7500 | CA34: 7500 | CC34: 7500 | CJ34: 7500 | CL34: 7500 | CY34: 7500 | DA34: 7500 | DQ34: 7500 | DS34: 7500
C35: Inorganic fertilizer for Cassava | J35: 1913.6 | L35: 1913.6 | M35: 1913.6 | O35: 1913.6 | AB35: 777.4 | AD35: 777.4 | AK35: 777.4 | AM35: 777.4 | AZ35: 2691 | BB35: 2691 | BC35: 2691 | BE35: 2691 | CA35: 1913.6 | CC35: 1913.6 | CJ35: 1913.6 | CL35: 1913.6 | CP35: 777.4 | CR35: 777.4 | CV35: 777.4 | CX35: 777.4 | CY35: 2691 | DA35: 2691 | DQ35: 2691 | DS35: 2691
B36: Sorghum Production Enhancement Project
C37: Seed Procurement - Sorghum | J37: 1750 | L37: 1750 | M37: 1750 | O37: 1750 | AZ37: 1750 | BB37: 1750 | BC37: 1750 | BE37: 1750 | CA37: 1750 | CC37: 1750 | CJ37: 1750 | CL37: 1750 | CY37: 1750 | DA37: 1750 | DQ37: 1750 | DS37: 1750
C38: Inorganic fertilizer for Sorghum | J38: 3800 | L38: 3800 | M38: 3800 | O38: 3800 | AB38: 700 | AD38: 700 | AK38: 700 | AM38: 700 | AZ38: 4500 | BB38: 4500 | BC38: 4500 | BE38: 4500 | CA38: 3800 | CC38: 3800 | CJ38: 3800 | CL38: 3800 | CP38: 700 | CR38: 700 | CV38: 700 | CX38: 700 | CY38: 4500 | DA38: 4500 | DQ38: 4500 | DS38: 4500
B39: Soybean Production Enhancement Project
C40: Seed Production - Soybean | G40: 50 | I40: 50 | M40: 50 | O40: 50 | AZ40: 50 | BB40: 50 | BC40: 50 | BE40: 50 | BR40: 50 | BT40: 50 | BX40: 50 | BZ40: 50 | CY40: 50 | DA40: 50 | DQ40: 50 | DS40: 50
C41: Inorganic fertilizer for Soybean | G41: 113 | I41: 113 | M41: 113 | O41: 113 | AZ41: 113 | BB41: 113 | BC41: 113 | BE41: 113 | BR41: 113 | BT41: 113 | BX41: 113 | BZ41: 113 | CY41: 113 | DA41: 113 | DQ41: 113 | DS41: 113
...

Sheet BED 2 SUMMARY (by PAP)
A1: CY 2025 PLAN AND BUDGET PROPOSAL
A2: BASED ON GENERAL APPROPRIATIONS ACT (GAA)
A3: BED 2: PHYSICAL
A4: NAME OF OU: | B4: ='CAPTURE SHEET - PHYSICAL'!C2 -> RFOII
A5: PRPOPOSAL/BEDS | B5: BED 2 - PHYSICAL
D7: YEAR | E7: QUARTER | F7: MONTH | G7: Values
D8: 2025 | CV8: 2025 PHYSICAL TARGET | CW8: 2025 MALE BENEF | CX8: 2025 FEMALE BENEF | CY8: 2025 AEW BENEF | CZ8: 2025 INDIV TOTAL | DA8: 2025 GROUP BENEF | DB8: Total PHYSICAL TARGET | DC8: Total MALE BENEF | DD8: Total FEMALE BENEF | DE8: Total AEW BENEF | DF8: Total INDIV TOTAL | DG8: Total GROUP BENEF
D9: 1ST QTR | V9: 1ST QTR PHYSICAL TARGET | W9: 1ST QTR MALE BENEF | X9: 1ST QTR FEMALE BENEF | Y9: 1ST QTR AEW BENEF | Z9: 1ST QTR INDIV TOTAL | AA9: 1ST QTR GROUP BENEF | AB9: 2ND QTR | AT9: 2ND QTR PHYSICAL TARGET | AU9: 2ND QTR MALE BENEF | AV9: 2ND QTR FEMALE BENEF | AW9: 2ND QTR AEW BENEF | AX9: 2ND QTR INDIV TOTAL | AY9: 2ND QTR GROUP BENEF | AZ9: 3RD QTR | BR9: 3RD QTR PHYSICAL TARGET | BS9: 3RD QTR MALE BENEF | BT9: 3RD QTR FEMALE BENEF | BU9: 3RD QTR AEW BENEF | BV9: 3RD QTR INDIV TOTAL | BW9: 3RD QTR GROUP BENEF | BX9: 4TH QTR | CP9: 4TH QTR PHYSICAL TARGET | CQ9: 4TH QTR MALE BENEF | CR9: 4TH QTR FEMALE BENEF | CS9: 4TH QTR AEW BENEF | CT9: 4TH QTR INDIV TOTAL | CU9: 4TH QTR GROUP BENEF
D10: JANUARY | J10: FEBRUARY | P10: MARCH | AB10: APRIL | AH10: MAY | AN10: JUNE | AZ10: JULY | BF10: AUGUST | BL10: SEPTEMBER | BX10: OCTOBER | CD10: NOVEMBER | CJ10: DECEMBER
A11: PREXC SUB-PROGRAM | B11: STRATEGY | C11: ACTIVITY | D11: PHYSICAL TARGET | E11: MALE BENEF | F11: FEMALE BENEF | G11: AEW BENEF | H11: INDIV TOTAL | I11: GROUP BENEF | J11: PHYSICAL TARGET | K11: MALE BENEF | L11: FEMALE BENEF | M11: AEW BENEF | N11: INDIV TOTAL | O11: GROUP BENEF | P11: PHYSICAL TARGET | Q11: MALE BENEF | R11: FEMALE BENEF | S11: AEW BENEF | T11: INDIV TOTAL | U11: GROUP BENEF | AB11: PHYSICAL TARGET | AC11: MALE BENEF | AD11: FEMALE BENEF | AE11: AEW BENEF | AF11: INDIV TOTAL | AG11: GROUP BENEF | AH11: PHYSICAL TARGET | AI11: MALE BENEF | AJ11: FEMALE BENEF | AK11: AEW BENEF | AL11: INDIV TOTAL | AM11: GROUP BENEF | AN11: PHYSICAL TARGET | AO11: MALE BENEF | AP11: FEMALE BENEF | AQ11: AEW BENEF | AR11: INDIV TOTAL | AS11: GROUP BENEF | AZ11: PHYSICAL TARGET | BA11: MALE BENEF | BB11: FEMALE BENEF | BC11: AEW BENEF | BD11: INDIV TOTAL | BE11: GROUP BENEF | BF11: PHYSICAL TARGET | BG11: MALE BENEF | BH11: FEMALE BENEF | BI11: AEW BENEF | BJ11: INDIV TOTAL | BK11: GROUP BENEF | BL11: PHYSICAL TARGET | BM11: MALE BENEF | BN11: FEMALE BENEF | BO11: AEW BENEF | BP11: INDIV TOTAL | BQ11: GROUP BENEF | BX11: PHYSICAL TARGET | BY11: MALE BENEF | BZ11: FEMALE BENEF | CA11: AEW BENEF | CB11: INDIV TOTAL | CC11: GROUP BENEF | CD11: PHYSICAL TARGET | CE11: MALE BENEF | CF11: FEMALE BENEF | CG11: AEW BENEF | CH11: INDIV TOTAL | CI11: GROUP BENEF | CJ11: PHYSICAL TARGET | CK11: MALE BENEF | CL11: FEMALE BENEF | CM11: AEW BENEF | CN11: INDIV TOTAL | CO11: GROUP BENEF
A12: PSS | J12: 3500 | N12: 0 | O12: 2 | V12: 3500 | Z12: 0 | AA12: 2 | AH12: 88000 | AL12: 0 | AN12: 1377794 | AR12: 0 | AS12: 29 | AT12: 1465794 | AX12: 0 | AY12: 29 | AZ12: 2083016 | BD12: 0 | BE12: 24 | BF12: 4220601 | BJ12: 0 | BK12: 163 | BL12: 2293350 | BP12: 0 | BQ12: 15 | BR12: 8596967 | BV12: 0 | BW12: 202 | BX12: 511001 | CB12: 0 | CC12: 6 | CD12: 324950 | CH12: 0 | CI12: 16 | CP12: 835951 | CT12: 0 | CU12: 22 | CV12: 10902212 | CZ12: 0 | DA12: 255 | DB12: 10902212 | DF12: 0 | DG12: 255
B13: OPV Seed Production
C14: Seed Production - White Corn Registered Seeds | AN14: 7000 | AR14: 0 | AS14: 21 | AT14: 7000 | AX14: 0 | AY14: 21 | AZ14: 1000 | BD14: 0 | BE14: 2 | BR14: 1000 | BV14: 0 | BW14: 2 | BX14: 6000 | CB14: 0 | CC14: 4 | CD14: 8000 | CH14: 0 | CI14: 12 | CP14: 14000 | CT14: 0 | CU14: 16 | CV14: 22000 | CZ14: 0 | DA14: 39 | DB14: 22000 | DF14: 0 | DG14: 39
B15: Corn Seed Reserve
C16: DRRM - White Corn Seed Procured OPV | AH16: 15000 | AL16: 0 | AT16: 15000 | AX16: 0 | CV16: 15000 | CZ16: 0 | DB16: 15000 | DF16: 0
C17: DRRM - Yellow Corn Seed Procured OPV | AH17: 3000 | AL17: 0 | AT17: 3000 | AX17: 0 | CV17: 3000 | CZ17: 0 | DB17: 3000 | DF17: 0
C18: DRRM - Yellow Corn Seed Procured Hybrid | AN18: 375894 | AR18: 0 | AT18: 375894 | AX18: 0 | CV18: 375894 | CZ18: 0 | DB18: 375894 | DF18: 0
B19: Recommended Corn Production Technology
C20: RCPT - Yellow Corn seeds | AZ20: 18000 | BD20: 0 | BE20: 4 | BR20: 18000 | BV20: 0 | BW20: 4 | CV20: 18000 | CZ20: 0 | DA20: 4 | DB20: 18000 | DF20: 0 | DG20: 4
C21: RCPT - Inorganic fertilizer for YC seeds | AZ21: 550000 | BD21: 0 | BE21: 4 | BR21: 550000 | BV21: 0 | BW21: 4 | CV21: 550000 | CZ21: 0 | DA21: 4 | DB21: 550000 | DF21: 0 | DG21: 4
B22: Soil amendments
C23: Biofertilizer | AZ23: 4000 | BD23: 0 | BE23: 4 | BR23: 4000 | BV23: 0 | BW23: 4 | CV23: 4000 | CZ23: 0 | DA23: 4 | DB23: 4000 | DF23: 0 | DG23: 4
C24: Soil Ameliorant | AZ24: 500000 | BD24: 0 | BE24: 4 | BR24: 500000 | BV24: 0 | BW24: 4 | CV24: 500000 | CZ24: 0 | DA24: 4 | DB24: 500000 | DF24: 0 | DG24: 4
B25: Yellow Corn Production Enhancement Project
C26: YCPEP - Yellow Corn Hybrid seeds | BF26: 486000 | BJ26: 0 | BK26: 76 | BR26: 486000 | BV26: 0 | BW26: 76 | CV26: 486000 | CZ26: 0 | DA26: 76 | DB26: 486000 | DF26: 0 | DG26: 76
C27: YCPEP - Inorganic fertilizer for YC Hybrid seeds | BF27: 2700000 | BJ27: 0 | BK27: 76 | BR27: 2700000 | BV27: 0 | BW27: 76 | CV27: 2700000 | CZ27: 0 | DA27: 76 | DB27: 2700000 | DF27: 0 | DG27: 76
B28: Pest and Disease Management
C29: DRRM - Agricultural chemicals (Insecticide in liters) | AH29: 5000 | AL29: 0 | AT29: 5000 | AX29: 0 | CV29: 5000 | CZ29: 0 | DB29: 5000 | DF29: 0
C30: DRRM - Agricultural chemicals (Rodenticides) | AH30: 50000 | AL30: 0 | AT30: 50000 | AX30: 0 | CV30: 50000 | CZ30: 0 | DB30: 50000 | DF30: 0
C31: DRRM - Agricultural chemicals (Pheromone lure) | AH31: 5000 | AL31: 0 | AT31: 5000 | AX31: 0 | CV31: 5000 | CZ31: 0 | DB31: 5000 | DF31: 0
C32: DRRM - Agricultural chemicals (Streptomycin) | AH32: 10000 | AL32: 0 | AT32: 10000 | AX32: 0 | CV32: 10000 | CZ32: 0 | DB32: 10000 | DF32: 0
B33: Cassava Production Enhancement Project
C34: Cassava Production (seed pieces) | AN34: 255000 | AR34: 0 | AS34: 2 | AT34: 255000 | AX34: 0 | AY34: 2 | AZ34: 200000 | BD34: 0 | BE34: 1 | BF34: 325000 | BJ34: 0 | BK34: 4 | BR34: 525000 | BV34: 0 | BW34: 5 | CD34: 195000 | CH34: 0 | CI34: 1 | CP34: 195000 | CT34: 0 | CU34: 1 | CV34: 975000 | CZ34: 0 | DA34: 8 | DB34: 975000 | DF34: 0 | DG34: 8
C35: Cassava Procurement (seed pieces) | AN35: 730000 | AR35: 0 | AS35: 2 | AT35: 730000 | AX35: 0 | AY35: 2 | AZ35: 800000 | BD35: 0 | BE35: 2 | BF35: 700000 | BJ35: 0 | BK35: 2 | BL35: 2270000 | BP35: 0 | BQ35: 7 | BR35: 3770000 | BV35: 0 | BW35: 11 | BX35: 500000 | CB35: 0 | CC35: 1 | CP35: 500000 | CT35: 0 | CU35: 1 | CV35: 5000000 | CZ35: 0 | DA35: 14 | DB35: 5000000 | DF35: 0 | DG35: 14
C36: Inorganic fertilizer for Cassava | AN36: 9900 | AR36: 0 | AS36: 4 | AT36: 9900 | AX36: 0 | AY36: 4 | AZ36: 10000 | BD36: 0 | BE36: 3 | BF36: 9600 | BJ36: 0 | BK36: 5 | BL36: 23350 | BP36: 0 | BQ36: 8 | BR36: 42950 | BV36: 0 | BW36: 16 | BX36: 5000 | CB36: 0 | CC36: 1 | CD36: 1950 | CH36: 0 | CI36: 1 | CP36: 6950 | CT36: 0 | CU36: 2 | CV36: 59800 | CZ36: 0 | DA36: 22 | DB36: 59800 | DF36: 0 | DG36: 22
B37: Sorghum Production Enhancement Project
C38: Seed Procurement - Sorghum | CD38: 20000 | CH38: 0 | CI38: 1 | CP38: 20000 | CT38: 0 | CU38: 1 | CV38: 20000 | CZ38: 0 | DA38: 1 | DB38: 20000 | DF38: 0 | DG38: 1
C39: Inorganic fertilizer for Sorghum | CD39: 100000 | CH39: 0 | CI39: 1 | CP39: 100000 | CT39: 0 | CU39: 1 | CV39: 100000 | CZ39: 0 | DA39: 1 | DB39: 100000 | DF39: 0 | DG39: 1
B40: Soybean Production Enhancement Project
C41: Seed Production - Soybean | J41: 1000 | N41: 0 | O41: 1 | V41: 1000 | Z41: 0 | AA41: 1 | CV41: 1000 | CZ41: 0 | DA41: 1 | DB41: 1000 | DF41: 0 | DG41: 1
...

Sheet BED13 Checking
D5: PRPOPOSAL/BEDS | E5: Values
D6: PROPOSAL | G6: BED 1 - OBLIGATION | J6: BED 3 - DISBURSEMENT | N6: vs BED 1 | R6: vs BED 3 | V6: BED 1 vs BED 3
A7: PREXC SUB-PROGRAM | B7: STRATEGY | C7: ACTIVITY | D7: MOOE | E7: CO | F7: TOTAL | G7: MOOE | H7: CO | I7: TOTAL | J7: MOOE | K7: CO | L7: TOTAL | N7: MOOE | O7: CO | P7: TOTAL | R7: MOOE | S7: CO | T7: TOTAL | V7: MOOE | W7: CO | X7: TOTAL
A8: PSS | D8: 780300 | E8: 8140 | F8: 788440 | G8: 780300 | H8: 8140 | I8: 788440 | J8: 780300 | K8: 8140 | L8: 788440 | N8: =+D8-G8 -> 0 | O8: =+E8-H8 -> 0 | P8: =+F8-I8 -> 0 | R8: =+D8-J8 -> 0 | S8: =+E8-K8 -> 0 | T8: =+F8-L8 -> 0 | V8: =+G8-J8 -> 0 | W8: =+H8-K8 -> 0 | X8: =+I8-L8 -> 0
B9: OPV Seed Production | D9: 1106 | F9: 1106 | G9: 1105 | I9: 1105 | J9: 1105 | L9: 1105 | N9: =+D9-G9 -> 1 | O9: =+E9-H9 -> 0 | P9: =+F9-I9 -> 1 | R9: =+D9-J9 -> 1 | S9: =+E9-K9 -> 0 | T9: =+F9-L9 -> 1 | V9: =+G9-J9 -> 0 | W9: =+H9-K9 -> 0 | X9: =+I9-L9 -> 0
C10: Seed Production - White Corn Registered Seeds | D10: 1106 | F10: 1106 | G10: 1105 | I10: 1105 | J10: 1105 | L10: 1105 | N10: =+D10-G10 -> 1 | O10: =+E10-H10 -> 0 | P10: =+F10-I10 -> 1 | R10: =+D10-J10 -> 1 | S10: =+E10-K10 -> 0 | T10: =+F10-L10 -> 1 | V10: =+G10-J10 -> 0 | W10: =+H10-K10 -> 0 | X10: =+I10-L10 -> 0
B11: Corn Seed Reserve | D11: 252396 | F11: 252396 | G11: 252396 | I11: 252396 | J11: 252396 | L11: 252396 | N11: =+D11-G11 -> 0 | O11: =+E11-H11 -> 0 | P11: =+F11-I11 -> 0 | R11: =+D11-J11 -> 0 | S11: =+E11-K11 -> 0 | T11: =+F11-L11 -> 0 | V11: =+G11-J11 -> 0 | W11: =+H11-K11 -> 0 | X11: =+I11-L11 -> 0
C12: DRRM - White Corn Seed Procured OPV | D12: 1500 | F12: 1500 | G12: 1500 | I12: 1500 | J12: 1500 | L12: 1500 | N12: =+D12-G12 -> 0 | O12: =+E12-H12 -> 0 | P12: =+F12-I12 -> 0 | R12: =+D12-J12 -> 0 | S12: =+E12-K12 -> 0 | T12: =+F12-L12 -> 0 | V12: =+G12-J12 -> 0 | W12: =+H12-K12 -> 0 | X12: =+I12-L12 -> 0
C13: DRRM - Yellow Corn Seed Procured OPV | D13: 300 | F13: 300 | G13: 300 | I13: 300 | J13: 300 | L13: 300 | N13: =+D13-G13 -> 0 | O13: =+E13-H13 -> 0 | P13: =+F13-I13 -> 0 | R13: =+D13-J13 -> 0 | S13: =+E13-K13 -> 0 | T13: =+F13-L13 -> 0 | V13: =+G13-J13 -> 0 | W13: =+H13-K13 -> 0 | X13: =+I13-L13 -> 0
C14: DRRM - Yellow Corn Seed Procured Hybrid | D14: 250596 | F14: 250596 | G14: 250596 | I14: 250596 | J14: 250596 | L14: 250596 | N14: =+D14-G14 -> 0 | O14: =+E14-H14 -> 0 | P14: =+F14-I14 -> 0 | R14: =+D14-J14 -> 0 | S14: =+E14-K14 -> 0 | T14: =+F14-L14 -> 0 | V14: =+G14-J14 -> 0 | W14: =+H14-K14 -> 0 | X14: =+I14-L14 -> 0
B15: Recommended Corn Production Technology | D15: 36750 | F15: 36750 | G15: 36750 | I15: 36750 | J15: 36750 | L15: 36750 | N15: =+D15-G15 -> 0 | O15: =+E15-H15 -> 0 | P15: =+F15-I15 -> 0 | R15: =+D15-J15 -> 0 | S15: =+E15-K15 -> 0 | T15: =+F15-L15 -> 0 | V15: =+G15-J15 -> 0 | W15: =+H15-K15 -> 0 | X15: =+I15-L15 -> 0
C16: RCPT - Yellow Corn seeds | D16: 12000 | F16: 12000 | G16: 12000 | I16: 12000 | J16: 12000 | L16: 12000 | N16: =+D16-G16 -> 0 | O16: =+E16-H16 -> 0 | P16: =+F16-I16 -> 0 | R16: =+D16-J16 -> 0 | S16: =+E16-K16 -> 0 | T16: =+F16-L16 -> 0 | V16: =+G16-J16 -> 0 | W16: =+H16-K16 -> 0 | X16: =+I16-L16 -> 0
C17: RCPT - Inorganic fertilizer for YC seeds | D17: 24750 | F17: 24750 | G17: 24750 | I17: 24750 | J17: 24750 | L17: 24750 | N17: =+D17-G17 -> 0 | O17: =+E17-H17 -> 0 | P17: =+F17-I17 -> 0 | R17: =+D17-J17 -> 0 | S17: =+E17-K17 -> 0 | T17: =+F17-L17 -> 0 | V17: =+G17-J17 -> 0 | W17: =+H17-K17 -> 0 | X17: =+I17-L17 -> 0
B18: Soil amendments | D18: 12720 | F18: 12720 | G18: 12720 | I18: 12720 | J18: 12720 | L18: 12720 | N18: =+D18-G18 -> 0 | O18: =+E18-H18 -> 0 | P18: =+F18-I18 -> 0 | R18: =+D18-J18 -> 0 | S18: =+E18-K18 -> 0 | T18: =+F18-L18 -> 0 | V18: =+G18-J18 -> 0 | W18: =+H18-K18 -> 0 | X18: =+I18-L18 -> 0
C19: Biofertilizer | D19: 2720 | F19: 2720 | G19: 2720 | I19: 2720 | J19: 2720 | L19: 2720 | N19: =+D19-G19 -> 0 | O19: =+E19-H19 -> 0 | P19: =+F19-I19 -> 0 | R19: =+D19-J19 -> 0 | S19: =+E19-K19 -> 0 | T19: =+F19-L19 -> 0 | V19: =+G19-J19 -> 0 | W19: =+H19-K19 -> 0 | X19: =+I19-L19 -> 0
C20: Soil Ameliorant | D20: 10000 | F20: 10000 | G20: 10000 | I20: 10000 | J20: 10000 | L20: 10000 | N20: =+D20-G20 -> 0 | O20: =+E20-H20 -> 0 | P20: =+F20-I20 -> 0 | R20: =+D20-J20 -> 0 | S20: =+E20-K20 -> 0 | T20: =+F20-L20 -> 0 | V20: =+G20-J20 -> 0 | W20: =+H20-K20 -> 0 | X20: =+I20-L20 -> 0
B21: Yellow Corn Production Enhancement Project | D21: 445500 | F21: 445500 | G21: 445500 | I21: 445500 | J21: 445500 | L21: 445500 | N21: =+D21-G21 -> 0 | O21: =+E21-H21 -> 0 | P21: =+F21-I21 -> 0 | R21: =+D21-J21 -> 0 | S21: =+E21-K21 -> 0 | T21: =+F21-L21 -> 0 | V21: =+G21-J21 -> 0 | W21: =+H21-K21 -> 0 | X21: =+I21-L21 -> 0
C22: YCPEP - Yellow Corn Hybrid seeds | D22: 324000 | F22: 324000 | G22: 324000 | I22: 324000 | J22: 324000 | L22: 324000 | N22: =+D22-G22 -> 0 | O22: =+E22-H22 -> 0 | P22: =+F22-I22 -> 0 | R22: =+D22-J22 -> 0 | S22: =+E22-K22 -> 0 | T22: =+F22-L22 -> 0 | V22: =+G22-J22 -> 0 | W22: =+H22-K22 -> 0 | X22: =+I22-L22 -> 0
C23: YCPEP - Inorganic fertilizer for YC Hybrid seeds | D23: 121500 | F23: 121500 | G23: 121500 | I23: 121500 | J23: 121500 | L23: 121500 | N23: =+D23-G23 -> 0 | O23: =+E23-H23 -> 0 | P23: =+F23-I23 -> 0 | R23: =+D23-J23 -> 0 | S23: =+E23-K23 -> 0 | T23: =+F23-L23 -> 0 | V23: =+G23-J23 -> 0 | W23: =+H23-K23 -> 0 | X23: =+I23-L23 -> 0
B24: Pest and Disease Management | D24: 14250 | F24: 14250 | G24: 14250 | I24: 14250 | J24: 14250 | L24: 14250 | N24: =+D24-G24 -> 0 | O24: =+E24-H24 -> 0 | P24: =+F24-I24 -> 0 | R24: =+D24-J24 -> 0 | S24: =+E24-K24 -> 0 | T24: =+F24-L24 -> 0 | V24: =+G24-J24 -> 0 | W24: =+H24-K24 -> 0 | X24: =+I24-L24 -> 0
C25: DRRM - Agricultural chemicals (Insecticide in liters) | D25: 6000 | F25: 6000 | G25: 6000 | I25: 6000 | J25: 6000 | L25: 6000 | N25: =+D25-G25 -> 0 | O25: =+E25-H25 -> 0 | P25: =+F25-I25 -> 0 | R25: =+D25-J25 -> 0 | S25: =+E25-K25 -> 0 | T25: =+F25-L25 -> 0 | V25: =+G25-J25 -> 0 | W25: =+H25-K25 -> 0 | X25: =+I25-L25 -> 0
C26: DRRM - Agricultural chemicals (Rodenticides) | D26: 1500 | F26: 1500 | G26: 1500 | I26: 1500 | J26: 1500 | L26: 1500 | N26: =+D26-G26 -> 0 | O26: =+E26-H26 -> 0 | P26: =+F26-I26 -> 0 | R26: =+D26-J26 -> 0 | S26: =+E26-K26 -> 0 | T26: =+F26-L26 -> 0 | V26: =+G26-J26 -> 0 | W26: =+H26-K26 -> 0 | X26: =+I26-L26 -> 0
C27: DRRM - Agricultural chemicals (Pheromone lure) | D27: 2750 | F27: 2750 | G27: 2750 | I27: 2750 | J27: 2750 | L27: 2750 | N27: =+D27-G27 -> 0 | O27: =+E27-H27 -> 0 | P27: =+F27-I27 -> 0 | R27: =+D27-J27 -> 0 | S27: =+E27-K27 -> 0 | T27: =+F27-L27 -> 0 | V27: =+G27-J27 -> 0 | W27: =+H27-K27 -> 0 | X27: =+I27-L27 -> 0
C28: DRRM - Agricultural chemicals (Streptomycin) | D28: 4000 | F28: 4000 | G28: 4000 | I28: 4000 | J28: 4000 | L28: 4000 | N28: =+D28-G28 -> 0 | O28: =+E28-H28 -> 0 | P28: =+F28-I28 -> 0 | R28: =+D28-J28 -> 0 | S28: =+E28-K28 -> 0 | T28: =+F28-L28 -> 0 | V28: =+G28-J28 -> 0 | W28: =+H28-K28 -> 0 | X28: =+I28-L28 -> 0
B29: Cassava Production Enhancement Project | D29: 11166 | F29: 11166 | G29: 11166 | I29: 11166 | J29: 11166 | L29: 11166 | N29: =+D29-G29 -> 0 | O29: =+E29-H29 -> 0 | P29: =+F29-I29 -> 0 | R29: =+D29-J29 -> 0 | S29: =+E29-K29 -> 0 | T29: =+F29-L29 -> 0 | V29: =+G29-J29 -> 0 | W29: =+H29-K29 -> 0 | X29: =+I29-L29 -> 0
C30: Cassava Production (seed pieces) | D30: 975 | F30: 975 | G30: 975 | I30: 975 | J30: 975 | L30: 975 | N30: =+D30-G30 -> 0 | O30: =+E30-H30 -> 0 | P30: =+F30-I30 -> 0 | R30: =+D30-J30 -> 0 | S30: =+E30-K30 -> 0 | T30: =+F30-L30 -> 0 | V30: =+G30-J30 -> 0 | W30: =+H30-K30 -> 0 | X30: =+I30-L30 -> 0
C31: Cassava Procurement (seed pieces) | D31: 7500 | F31: 7500 | G31: 7500 | I31: 7500 | J31: 7500 | L31: 7500 | N31: =+D31-G31 -> 0 | O31: =+E31-H31 -> 0 | P31: =+F31-I31 -> 0 | R31: =+D31-J31 -> 0 | S31: =+E31-K31 -> 0 | T31: =+F31-L31 -> 0 | V31: =+G31-J31 -> 0 | W31: =+H31-K31 -> 0 | X31: =+I31-L31 -> 0
C32: Inorganic fertilizer for Cassava | D32: 2691 | F32: 2691 | G32: 2691 | I32: 2691 | J32: 2691 | L32: 2691 | N32: =+D32-G32 -> 0 | O32: =+E32-H32 -> 0 | P32: =+F32-I32 -> 0 | R32: =+D32-J32 -> 0 | S32: =+E32-K32 -> 0 | T32: =+F32-L32 -> 0 | V32: =+G32-J32 -> 0 | W32: =+H32-K32 -> 0 | X32: =+I32-L32 -> 0
B33: Sorghum Production Enhancement Project | D33: 6250 | F33: 6250 | G33: 6250 | I33: 6250 | J33: 6250 | L33: 6250 | N33: =+D33-G33 -> 0 | O33: =+E33-H33 -> 0 | P33: =+F33-I33 -> 0 | R33: =+D33-J33 -> 0 | S33: =+E33-K33 -> 0 | T33: =+F33-L33 -> 0 | V33: =+G33-J33 -> 0 | W33: =+H33-K33 -> 0 | X33: =+I33-L33 -> 0
C34: Seed Procurement - Sorghum | D34: 1750 | F34: 1750 | G34: 1750 | I34: 1750 | J34: 1750 | L34: 1750 | N34: =+D34-G34 -> 0 | O34: =+E34-H34 -> 0 | P34: =+F34-I34 -> 0 | R34: =+D34-J34 -> 0 | S34: =+E34-K34 -> 0 | T34: =+F34-L34 -> 0 | V34: =+G34-J34 -> 0 | W34: =+H34-K34 -> 0 | X34: =+I34-L34 -> 0
C35: Inorganic fertilizer for Sorghum | D35: 4500 | F35: 4500 | G35: 4500 | I35: 4500 | J35: 4500 | L35: 4500 | N35: =+D35-G35 -> 0 | O35: =+E35-H35 -> 0 | P35: =+F35-I35 -> 0 | R35: =+D35-J35 -> 0 | S35: =+E35-K35 -> 0 | T35: =+F35-L35 -> 0 | V35: =+G35-J35 -> 0 | W35: =+H35-K35 -> 0 | X35: =+I35-L35 -> 0
B36: Soybean Production Enhancement Project | D36: 162 | F36: 162 | G36: 163 | I36: 163 | J36: 163 | L36: 163 | N36: =+D36-G36 -> -1 | O36: =+E36-H36 -> 0 | P36: =+F36-I36 -> -1 | R36: =+D36-J36 -> -1 | S36: =+E36-K36 -> 0 | T36: =+F36-L36 -> -1 | V36: =+G36-J36 -> 0 | W36: =+H36-K36 -> 0 | X36: =+I36-L36 -> 0
C37: Seed Production - Soybean | D37: 50 | F37: 50 | G37: 50 | I37: 50 | J37: 50 | L37: 50 | N37: =+D37-G37 -> 0 | O37: =+E37-H37 -> 0 | P37: =+F37-I37 -> 0 | R37: =+D37-J37 -> 0 | S37: =+E37-K37 -> 0 | T37: =+F37-L37 -> 0 | V37: =+G37-J37 -> 0 | W37: =+H37-K37 -> 0 | X37: =+I37-L37 -> 0
C38: Inorganic fertilizer for Soybean | D38: 112 | F38: 112 | G38: 113 | I38: 113 | J38: 113 | L38: 113 | N38: =+D38-G38 -> -1 | O38: =+E38-H38 -> 0 | P38: =+F38-I38 -> -1 | R38: =+D38-J38 -> -1 | S38: =+E38-K38 -> 0 | T38: =+F38-L38 -> -1 | V38: =+G38-J38 -> 0 | W38: =+H38-K38 -> 0 | X38: =+I38-L38 -> 0
B39: DA Facilities Management | E39: 8140 | F39: 8140 | H39: 8140 | I39: 8140 | K39: 8140 | L39: 8140 | N39: =+D39-G39 -> 0 | O39: =+E39-H39 -> 0 | P39: =+F39-I39 -> 0 | R39: =+D39-J39 -> 0 | S39: =+E39-K39 -> 0 | T39: =+F39-L39 -> 0 | V39: =+G39-J39 -> 0 | W39: =+H39-K39 -> 0 | X39: =+I39-L39 -> 0
C40: DA Stations - Hand tractor with corn planter | E40: 1200 | F40: 1200 | H40: 1200 | I40: 1200 | K40: 1200 | L40: 1200 | N40: =+D40-G40 -> 0 | O40: =+E40-H40 -> 0 | P40: =+F40-I40 -> 0 | R40: =+D40-J40 -> 0 | S40: =+E40-K40 -> 0 | T40: =+F40-L40 -> 0 | V40: =+G40-J40 -> 0 | W40: =+H40-K40 -> 0 | X40: =+I40-L40 -> 0
C41: DA Stations - Silage Chopper | E41: 240 | F41: 240 | H41: 240 | I41: 240 | K41: 240 | L41: 240 | N41: =+D41-G41 -> 0 | O41: =+E41-H41 -> 0 | P41: =+F41-I41 -> 0 | R41: =+D41-J41 -> 0 | S41: =+E41-K41 -> 0 | T41: =+F41-L41 -> 0 | V41: =+G41-J41 -> 0 | W41: =+H41-K41 -> 0 | X41: =+I41-L41 -> 0
C42: DA Stations - Corn Mill | E42: 1200 | F42: 1200 | H42: 1200 | I42: 1200 | K42: 1200 | L42: 1200 | N42: =+D42-G42 -> 0 | O42: =+E42-H42 -> 0 | P42: =+F42-I42 -> 0 | R42: =+D42-J42 -> 0 | S42: =+E42-K42 -> 0 | T42: =+F42-L42 -> 0 | V42: =+G42-J42 -> 0 | W42: =+H42-K42 -> 0 | X42: =+I42-L42 -> 0
C43: DA Stations - Pelletizing Machine | E43: 300 | F43: 300 | H43: 300 | I43: 300 | K43: 300 | L43: 300 | N43: =+D43-G43 -> 0 | O43: =+E43-H43 -> 0 | P43: =+F43-I43 -> 0 | R43: =+D43-J43 -> 0 | S43: =+E43-K43 -> 0 | T43: =+F43-L43 -> 0 | V43: =+G43-J43 -> 0 | W43: =+H43-K43 -> 0 | X43: =+I43-L43 -> 0
C44: DA Stations - Light Cargo Truck | E44: 2100 | F44: 2100 | H44: 2100 | I44: 2100 | K44: 2100 | L44: 2100 | N44: =+D44-G44 -> 0 | O44: =+E44-H44 -> 0 | P44: =+F44-I44 -> 0 | R44: =+D44-J44 -> 0 | S44: =+E44-K44 -> 0 | T44: =+F44-L44 -> 0 | V44: =+G44-J44 -> 0 | W44: =+H44-K44 -> 0 | X44: =+I44-L44 -> 0
...

Sheet BED2 checking
A1: FY 2025 PLAN AND BUDGET PROPOSAL
A2: BASED ON NATIONAL EXPENDITURE PROGRAM (NEP)
A3: BED 2: PHYSICAL
A4: NAME OF OU | B4: ='CAPTURE SHEET - PHYSICAL'!C2 -> RFOII
D7: PRPOPOSAL/BEDS | E7: Values
D8: PROPOSAL | H8: BED 2 - PHYSICAL
A9: PREXC SUB-PROGRAM | B9: ACTIVITY | C9: PROVINCE | D9: PHYSICAL TARGET | E9: GROUP BENEF | F9: Sum of TOTAL INDIV | G9: ALLOCATION (Php'000) | H9: PHYSICAL TARGET | I9: GROUP BENEF | J9: Sum of TOTAL INDIV | K9: ALLOCATION (Php'000) | M9: PHYSICAL TARGET | N9: GROUP BENEF | O9: Sum of TOTAL INDIV | P9: ALLOCATION (Php'000)
A10: PSS | B10: Seed Production - White Corn Registered Seeds | C10: Cagayan | D10: 6000 | E10: 10 | H10: 6000 | I10: 10 | J10: 0 | K10: 301 | M10: =+D10-H10 -> 0 | N10: =+E10-I10 -> 0 | O10: =+F10-J10 -> 0 | P10: =+G10-K10 -> -301
C11: Isabela | D11: 8000 | E11: 17 | H11: 8000 | I11: 17 | J11: 0 | K11: 402 | M11: =+D11-H11 -> 0 | N11: =+E11-I11 -> 0 | O11: =+F11-J11 -> 0 | P11: =+G11-K11 -> -402
C12: Nueva_Vizcaya | D12: 4000 | E12: 6 | H12: 4000 | I12: 6 | J12: 0 | K12: 201 | M12: =+D12-H12 -> 0 | N12: =+E12-I12 -> 0 | O12: =+F12-J12 -> 0 | P12: =+G12-K12 -> -201
C13: Quirino | D13: 4000 | E13: 6 | H13: 4000 | I13: 6 | J13: 0 | K13: 201 | M13: =+D13-H13 -> 0 | N13: =+E13-I13 -> 0 | O13: =+F13-J13 -> 0 | P13: =+G13-K13 -> -201
C14: Regional_Office | G14: 1106 | M14: =+D14-H14 -> 0 | N14: =+E14-I14 -> 0 | O14: =+F14-J14 -> 0 | P14: =+G14-K14 -> 1106
B15: Seed Production - White Corn Registered Seeds Total | D15: 22000 | E15: 39 | G15: 1106 | H15: 22000 | I15: 39 | J15: 0 | K15: 1105 | M15: =+D15-H15 -> 0 | N15: =+E15-I15 -> 0 | O15: =+F15-J15 -> 0 | P15: =+G15-K15 -> 1
B16: DRRM - White Corn Seed Procured OPV | C16: Regional_Office | D16: 15000 | G16: 1500 | H16: 15000 | J16: 0 | K16: 1500 | M16: =+D16-H16 -> 0 | N16: =+E16-I16 -> 0 | O16: =+F16-J16 -> 0 | P16: =+G16-K16 -> 0
B17: DRRM - White Corn Seed Procured OPV Total | D17: 15000 | G17: 1500 | H17: 15000 | J17: 0 | K17: 1500 | M17: =+D17-H17 -> 0 | N17: =+E17-I17 -> 0 | O17: =+F17-J17 -> 0 | P17: =+G17-K17 -> 0
B18: RCPT - Yellow Corn seeds | C18: Cagayan | D18: 9000 | E18: 2 | G18: 6000 | H18: 9000 | I18: 2 | J18: 0 | K18: 6000 | M18: =+D18-H18 -> 0 | N18: =+E18-I18 -> 0 | O18: =+F18-J18 -> 0 | P18: =+G18-K18 -> 0
C19: Isabela | D19: 9000 | E19: 2 | G19: 6000 | H19: 9000 | I19: 2 | J19: 0 | K19: 6000 | M19: =+D19-H19 -> 0 | N19: =+E19-I19 -> 0 | O19: =+F19-J19 -> 0 | P19: =+G19-K19 -> 0
B20: RCPT - Yellow Corn seeds Total | D20: 18000 | E20: 4 | G20: 12000 | H20: 18000 | I20: 4 | J20: 0 | K20: 12000 | M20: =+D20-H20 -> 0 | N20: =+E20-I20 -> 0 | O20: =+F20-J20 -> 0 | P20: =+G20-K20 -> 0
B21: RCPT - Inorganic fertilizer for YC seeds | C21: Cagayan | D21: 275000 | E21: 2 | G21: 12375 | H21: 275000 | I21: 2 | J21: 0 | K21: 12375 | M21: =+D21-H21 -> 0 | N21: =+E21-I21 -> 0 | O21: =+F21-J21 -> 0 | P21: =+G21-K21 -> 0
C22: Isabela | D22: 275000 | E22: 2 | G22: 12375 | H22: 275000 | I22: 2 | J22: 0 | K22: 12375 | M22: =+D22-H22 -> 0 | N22: =+E22-I22 -> 0 | O22: =+F22-J22 -> 0 | P22: =+G22-K22 -> 0
B23: RCPT - Inorganic fertilizer for YC seeds Total | D23: 550000 | E23: 4 | G23: 24750 | H23: 550000 | I23: 4 | J23: 0 | K23: 24750 | M23: =+D23-H23 -> 0 | N23: =+E23-I23 -> 0 | O23: =+F23-J23 -> 0 | P23: =+G23-K23 -> 0
B24: Biofertilizer | C24: Cagayan | D24: 2000 | E24: 2 | G24: 1360 | H24: 2000 | I24: 2 | J24: 0 | K24: 1360 | M24: =+D24-H24 -> 0 | N24: =+E24-I24 -> 0 | O24: =+F24-J24 -> 0 | P24: =+G24-K24 -> 0
C25: Isabela | D25: 2000 | E25: 2 | G25: 1360 | H25: 2000 | I25: 2 | J25: 0 | K25: 1360 | M25: =+D25-H25 -> 0 | N25: =+E25-I25 -> 0 | O25: =+F25-J25 -> 0 | P25: =+G25-K25 -> 0
B26: Biofertilizer Total | D26: 4000 | E26: 4 | G26: 2720 | H26: 4000 | I26: 4 | J26: 0 | K26: 2720 | M26: =+D26-H26 -> 0 | N26: =+E26-I26 -> 0 | O26: =+F26-J26 -> 0 | P26: =+G26-K26 -> 0
B27: Soil Ameliorant | C27: Cagayan | D27: 250000 | E27: 2 | G27: 5000 | H27: 250000 | I27: 2 | J27: 0 | K27: 5000 | M27: =+D27-H27 -> 0 | N27: =+E27-I27 -> 0 | O27: =+F27-J27 -> 0 | P27: =+G27-K27 -> 0
C28: Isabela | D28: 250000 | E28: 2 | G28: 5000 | H28: 250000 | I28: 2 | J28: 0 | K28: 5000 | M28: =+D28-H28 -> 0 | N28: =+E28-I28 -> 0 | O28: =+F28-J28 -> 0 | P28: =+G28-K28 -> 0
B29: Soil Ameliorant Total | D29: 500000 | E29: 4 | G29: 10000 | H29: 500000 | I29: 4 | J29: 0 | K29: 10000 | M29: =+D29-H29 -> 0 | N29: =+E29-I29 -> 0 | O29: =+F29-J29 -> 0 | P29: =+G29-K29 -> 0
B30: YCPEP - Yellow Corn Hybrid seeds | C30: Cagayan | D30: 125010 | E30: 25 | G30: 83340 | H30: 125010 | I30: 25 | J30: 0 | K30: 83340 | M30: =+D30-H30 -> 0 | N30: =+E30-I30 -> 0 | O30: =+F30-J30 -> 0 | P30: =+G30-K30 -> 0
C31: Isabela | D31: 301140 | E31: 35 | G31: 200760 | H31: 301140 | I31: 35 | J31: 0 | K31: 200760 | M31: =+D31-H31 -> 0 | N31: =+E31-I31 -> 0 | O31: =+F31-J31 -> 0 | P31: =+G31-K31 -> 0
C32: Nueva_Vizcaya | D32: 16200 | E32: 9 | G32: 10800 | H32: 16200 | I32: 10 | J32: 0 | K32: 10800 | M32: =+D32-H32 -> 0 | N32: =+E32-I32 -> -1 | O32: =+F32-J32 -> 0 | P32: =+G32-K32 -> 0
C33: Quirino | D33: 43650 | E33: 6 | G33: 29100 | H33: 43650 | I33: 6 | J33: 0 | K33: 29100 | M33: =+D33-H33 -> 0 | N33: =+E33-I33 -> 0 | O33: =+F33-J33 -> 0 | P33: =+G33-K33 -> 0
B34: YCPEP - Yellow Corn Hybrid seeds Total | D34: 486000 | E34: 75 | G34: 324000 | H34: 486000 | I34: 76 | J34: 0 | K34: 324000 | M34: =+D34-H34 -> 0 | N34: =+E34-I34 -> -1 | O34: =+F34-J34 -> 0 | P34: =+G34-K34 -> 0
B35: YCPEP - Inorganic fertilizer for YC Hybrid seeds | C35: Cagayan | D35: 694500 | E35: 25 | G35: 31252.5 | H35: 694500 | I35: 25 | J35: 0 | K35: 31252.5 | M35: =+D35-H35 -> 0 | N35: =+E35-I35 -> 0 | O35: =+F35-J35 -> 0 | P35: =+G35-K35 -> 0
C36: Isabela | D36: 1673000 | E36: 35 | G36: 75285 | H36: 1673000 | I36: 35 | J36: 0 | K36: 75285 | M36: =+D36-H36 -> 0 | N36: =+E36-I36 -> 0 | O36: =+F36-J36 -> 0 | P36: =+G36-K36 -> 0
C37: Nueva_Vizcaya | D37: 90000 | E37: 9 | G37: 4050 | H37: 90000 | I37: 10 | J37: 0 | K37: 4050 | M37: =+D37-H37 -> 0 | N37: =+E37-I37 -> -1 | O37: =+F37-J37 -> 0 | P37: =+G37-K37 -> 0
C38: Quirino | D38: 242500 | E38: 6 | G38: 10912.5 | H38: 242500 | I38: 6 | J38: 0 | K38: 10912.5 | M38: =+D38-H38 -> 0 | N38: =+E38-I38 -> 0 | O38: =+F38-J38 -> 0 | P38: =+G38-K38 -> 0
B39: YCPEP - Inorganic fertilizer for YC Hybrid seeds Total | D39: 2700000 | E39: 75 | G39: 121500 | H39: 2700000 | I39: 76 | J39: 0 | K39: 121500 | M39: =+D39-H39 -> 0 | N39: =+E39-I39 -> -1 | O39: =+F39-J39 -> 0 | P39: =+G39-K39 -> 0
B40: DRRM - Yellow Corn Seed Procured OPV | C40: Regional_Office | D40: 3000 | G40: 300 | H40: 3000 | J40: 0 | K40: 300 | M40: =+D40-H40 -> 0 | N40: =+E40-I40 -> 0 | O40: =+F40-J40 -> 0 | P40: =+G40-K40 -> 0
B41: DRRM - Yellow Corn Seed Procured OPV Total | D41: 3000 | G41: 300 | H41: 3000 | J41: 0 | K41: 300 | M41: =+D41-H41 -> 0 | N41: =+E41-I41 -> 0 | O41: =+F41-J41 -> 0 | P41: =+G41-K41 -> 0
B42: DRRM - Yellow Corn Seed Procured Hybrid | C42: Regional_Office | D42: 375894 | G42: 250596 | H42: 375894 | J42: 0 | K42: 250596 | M42: =+D42-H42 -> 0 | N42: =+E42-I42 -> 0 | O42: =+F42-J42 -> 0 | P42: =+G42-K42 -> 0
...

Sheet BED13 vs BED2 checking
A1: FY 2025 PLAN AND BUDGET PROPOSAL | I1: FY 2025 PLAN AND BUDGET PROPOSAL
A2: BASED ON NATIONAL EXPENDITURE PROGRAM (NEP) | I2: BASED ON NATIONAL EXPENDITURE PROGRAM (NEP)
A3: BED 2: PHYSICAL | I3: BED 1 OBLIGATION AND BED 3 DISBURSEMENT
A4: NAME OF OU | I4: NAME OF OU
A5: PRPOPOSAL/BEDS | B5: BED 2 - PHYSICAL
I6: Sum of TOTAL (Php '000) | M6: PRPOPOSAL/BEDS
A7: PREXC SUB-PROGRAM | B7: STRATEGY | C7: ACTIVITY | D7: ALLOCATION (Php'000) | I7: PREXC SUB-PROGRAM | J7: STRATEGY | K7: ACTIVITY | L7: MONTH | M7: BED 1 - OBLIGATION | N7: BED 3 - DISBURSEMENT
A8: PSS | D8: 788440 | I8: PSS | M8: 788440 | N8: 788440
B9: OPV Seed Production | J9: OPV Seed Production | M9: 1105 | N9: 1105
C10: Seed Production - White Corn Registered Seeds | D10: 1105 | K10: Seed Production - White Corn Registered Seeds | M10: 1105 | N10: 1105
B11: Corn Seed Reserve | L11: MARCH | M11: 1105
C12: DRRM - White Corn Seed Procured OPV | D12: 1500 | L12: MAY | N12: 1105
C13: DRRM - Yellow Corn Seed Procured OPV | D13: 300 | J13: Corn Seed Reserve | M13: 252396 | N13: 252396
C14: DRRM - Yellow Corn Seed Procured Hybrid | D14: 250596 | K14: DRRM - White Corn Seed Procured OPV | M14: 1500 | N14: 1500
B15: Recommended Corn Production Technology | L15: MARCH | M15: 1500
C16: RCPT - Yellow Corn seeds | D16: 12000 | L16: MAY | N16: 1500
C17: RCPT - Inorganic fertilizer for YC seeds | D17: 24750 | K17: DRRM - Yellow Corn Seed Procured OPV | M17: 300 | N17: 300
B18: Soil amendments | L18: MARCH | M18: 300
C19: Biofertilizer | D19: 2720 | L19: MAY | N19: 300
C20: Soil Ameliorant | D20: 10000 | K20: DRRM - Yellow Corn Seed Procured Hybrid | M20: 250596 | N20: 250596
B21: Yellow Corn Production Enhancement Project | L21: APRIL | M21: 250596
C22: YCPEP - Yellow Corn Hybrid seeds | D22: 324000 | L22: JULY | N22: 250596
C23: YCPEP - Inorganic fertilizer for YC Hybrid seeds | D23: 121500 | J23: Recommended Corn Production Technology | M23: 36750 | N23: 36750
B24: Pest and Disease Management | K24: RCPT - Yellow Corn seeds | M24: 12000 | N24: 12000
C25: DRRM - Agricultural chemicals (Insecticide in liters) | D25: 6000 | L25: MARCH | M25: 12000
C26: DRRM - Agricultural chemicals (Rodenticides) | D26: 1500 | L26: AUGUST | N26: 12000
C27: DRRM - Agricultural chemicals (Pheromone lure) | D27: 2750 | K27: RCPT - Inorganic fertilizer for YC seeds | M27: 24750 | N27: 24750
C28: DRRM - Agricultural chemicals (Streptomycin) | D28: 4000 | L28: APRIL | M28: 17600
B29: Cassava Production Enhancement Project | L29: JULY | M29: 7150 | N29: 17600
C30: Cassava Production (seed pieces) | D30: 975 | L30: NOVEMBER | N30: 7150
C31: Cassava Procurement (seed pieces) | D31: 7500 | J31: Soil amendments | M31: 12720 | N31: 12720
C32: Inorganic fertilizer for Cassava | D32: 2691 | K32: Biofertilizer | M32: 2720 | N32: 2720
B33: Sorghum Production Enhancement Project | L33: MARCH | M33: 2720
C34: Seed Procurement - Sorghum | D34: 1750 | L34: JULY | N34: 2720
C35: Inorganic fertilizer for Sorghum | D35: 4500 | K35: Soil Ameliorant | M35: 10000 | N35: 10000
B36: Soybean Production Enhancement Project | L36: MARCH | M36: 7000
C37: Seed Production - Soybean | D37: 50 | L37: JULY | M37: 3000 | N37: 7000
C38: Inorganic fertilizer for Soybean | D38: 113 | L38: NOVEMBER | N38: 3000
B39: DA Facilities Management | J39: Yellow Corn Production Enhancement Project | M39: 445500 | N39: 445500
C40: DA Stations - Hand tractor with corn planter | D40: 1200 | K40: YCPEP - Yellow Corn Hybrid seeds | M40: 324000 | N40: 324000
...

Sheet comments
A1: FY 2025 PLAN AND BUDGET PROPOSAL
A2: BASED ON NATIONAL EXPENDITURE PROGRAM (NEP)
A3: BED 2: PHYSICAL
A4: NAME OF OU | B4: ='[1]CAPTURE SHEET - PHYSICAL'!C2 -> RFOII
A8: Yung mga Group Benef po sa PSS, pakilagyan ng number of individual for group
A9: PREXC SUB-PROGRAM | B9: ACTIVITY | C9: PROVINCE
A10: PSS | B10: Seed Production - White Corn Registered Seeds | C10: Cagayan
A11: PSS | B11: Seed Production - White Corn Registered Seeds | C11: Isabela
A12: PSS | B12: Seed Production - White Corn Registered Seeds | C12: Nueva_Vizcaya
A13: PSS | B13: Seed Production - White Corn Registered Seeds | C13: Quirino | D13: Nagbawas po kayo benef sa Quirino? | E13: edited
A14: PSS | B14: Seed Production - White Corn Registered Seeds | C14: Regional_Office
A15: PSS | B15: Seed Production - White Corn Registered Seeds Total
A16: PSS | B16: DRRM - White Corn Seed Procured OPV | C16: Regional_Office
A17: PSS | B17: DRRM - White Corn Seed Procured OPV Total
A18: PSS | B18: RCPT - Yellow Corn seeds | C18: Cagayan
A19: PSS | B19: RCPT - Yellow Corn seeds | C19: Isabela
A20: PSS | B20: RCPT - Yellow Corn seeds Total
