Workbook

Sheet BY INTERVENTION
A1: DEPARTMENT OF AGRICULTURE
A2: FY 2027 Plan and Budget Proposals (PBP)
A3: ACCOMPLISHED BY: DA RFO2
A5: Indicative Geographic and Intervention Targeting of FY 2027 Budget Proposals
A7: Region | B7: Province | C7: City/ Municipality | D7: LGU-Identified Co-Investment Intervention (2026 MAFIF & Meeting with Mindanao LCEs) | E7: DA OU's FY 2027 Proposed Allocation corresponding to the intervention in column 4 (if any) | G7: Additional FY 2027 Intervention Entry of the DA OU (if not reflected in Column 4) (specify the type of intervention) | H7: DA OU's FY 2027 Proposed Allocation corresponding to the intervention in Column 7 | J7: DA Operating Unit / Agency with Corresponding FY 2027 Proposal
E8: TIER 1 ('000) | F8: TIER 2 ('000) | H8: TIER 1 ('000) | I8: TIER 2 ('000)
A9: (1) | B9: (2) | C9: (3) | D9: (4) | E9: (5) | F9: (6) | G9: (7) | H9: (8) | I9: (9) | J9: (10) | AA9: Inferred Commodity/Industry
A10: Region 2 | B10: Batanes | C10: Basco | D10: Construction of Chinteb-Chahayan FMR, Brgy. San Antonio, Basco, Batanes | F10: 19500 | J10: DA-FMRDP | AA10: =_xlfn.IFS(J10="DA-FMRDP","Farm-to-Market Road",J10="DA-RFO2 RICE","Rice",J10="DA-RFO2 Rice Program","Rice",J10="DA-RFO2 CORN","Corn",J10="DA-RFO2 Corn Program","Corn",J10="DA-RFO2 HVCDP","High Value Crops (Vegetables/Fruits/Rootcrops)",J10="DA-RFO2 HVCDP Export","High Value Export Crops (Dragon Fruit/Ube/Okra/Banana)",J10="DA-RFO2 HVCDP Coffee","Coffee (HVCDP)",J10="DA-RFO2 LIVESTOCK","Livestock (Cattle/Carabao/Swine/Poultry)",J10="DA-RFO2 SAAD","Various Commodities (SAAD)",J10="DA-RFO2 4K","Various Commodities (4Ks)",J10="DA-RFO2 4KS","Various Commodities (4Ks)",J10="DA-RFO2 HALAL","Halal Food Products",J10="DA-RFO2 OAP","Organic Agriculture",J10="DA-RFO2 NUPAP","Vegetables (NUPAP/Urban Agri)",TRUE,IF(ISNUMBER(SEARCH("FMR",D10)),"Farm-to-Market Road",IF(ISNUMBER(SEARCH("RICE",D10)),"Rice",IF(ISNUMBER(SEARCH("CORN",D10)),"Corn",IF(ISNUMBER(SEARCH("HVCDP COFFEE",D10)),"Coffee (HVCDP)",IF(ISNUMBER(SEARCH("HVCDP EXPORT",D10)),"High Value Export Crops (Dragon Fruit/Ube/Okra/Banana)",IF(ISNUMBER(SEARCH("HVCDP",D10)),"High Value Crops (Vegetables/Fruits/Rootcrops)",IF(ISNUMBER(SEARCH("LIVESTOCK",D10)),"Livestock (Cattle/Carabao/Swine/Poultry)",IF(ISNUMBER(SEARCH("SAAD",D10)),"Various Commodities (SAAD)",IF(ISNUMBER(SEARCH("4KS",D10)),"Various Commodities (4Ks)",IF(ISNUMBER(SEARCH("4K",D10)),"Various Commodities (4Ks)",IF(ISNUMBER(SEARCH("HALAL",D10)),"Halal Food Products",IF(ISNUMBER(SEARCH("OAP",D10)),"Organic Agriculture",IF(ISNUMBER(SEARCH("NUPAP",D10)),"Vegetables (NUPAP/Urban Agri)","")))))))))))))) -> Farm-to-Market Road
A11: Region 2 | B11: Batanes | C11: Basco | D11: Construction of Sapuno-Malakdang FMR, Brgy. Kayvaluganan, Basco, Batanes | F11: 21500 | J11: DA-FMRDP | AA11: =_xlfn.IFS(J11="DA-FMRDP","Farm-to-Market Road",J11="DA-RFO2 RICE","Rice",J11="DA-RFO2 Rice Program","Rice",J11="DA-RFO2 CORN","Corn",J11="DA-RFO2 Corn Program","Corn",J11="DA-RFO2 HVCDP","High Value Crops (Vegetables/Fruits/Rootcrops)",J11="DA-RFO2 HVCDP Export","High Value Export Crops (Dragon Fruit/Ube/Okra/Banana)",J11="DA-RFO2 HVCDP Coffee","Coffee (HVCDP)",J11="DA-RFO2 LIVESTOCK","Livestock (Cattle/Carabao/Swine/Poultry)",J11="DA-RFO2 SAAD","Various Commodities (SAAD)",J11="DA-RFO2 4K","Various Commodities (4Ks)",J11="DA-RFO2 4KS","Various Commodities (4Ks)",J11="DA-RFO2 HALAL","Halal Food Products",J11="DA-RFO2 OAP","Organic Agriculture",J11="DA-RFO2 NUPAP","Vegetables (NUPAP/Urban Agri)",TRUE,IF(ISNUMBER(SEARCH("FMR",D11)),"Farm-to-Market Road",IF(ISNUMBER(SEARCH("RICE",D11)),"Rice",IF(ISNUMBER(SEARCH("CORN",D11)),"Corn",IF(ISNUMBER(SEARCH("HVCDP COFFEE",D11)),"Coffee (HVCDP)",IF(ISNUMBER(SEARCH("HVCDP EXPORT",D11)),"High Value Export Crops (Dragon Fruit/Ube/Okra/Banana)",IF(ISNUMBER(SEARCH("HVCDP",D11)),"High Value Crops (Vegetables/Fruits/Rootcrops)",IF(ISNUMBER(SEARCH("LIVESTOCK",D11)),"Livestock (Cattle/Carabao/Swine/Poultry)",IF(ISNUMBER(SEARCH("SAAD",D11)),"Various Commodities (SAAD)",IF(ISNUMBER(SEARCH("4KS",D11)),"Various Commodities (4Ks)",IF(ISNUMBER(SEARCH("4K",D11)),"Various Commodities (4Ks)",IF(ISNUMBER(SEARCH("HALAL",D11)),"Halal Food Products",IF(ISNUMBER(SEARCH("OAP",D11)),"Organic Agriculture",IF(ISNUMBER(SEARCH("NUPAP",D11)),"Vegetables (NUPAP/Urban Agri)","")))))))))))))) -> Farm-to-Market Road
A12: Region 2 | B12: Batanes | C12: Basco | D12: FMR Construction/Concreting | E12: 32500 | J12: DA-FMRDP | AA12: =_xlfn.IFS(J12="DA-FMRDP","Farm-to-Market Road",J12="DA-RFO2 RICE","Rice",J12="DA-RFO2 Rice Program","Rice",J12="DA-RFO2 CORN","Corn",J12="DA-RFO2 Corn Program","Corn",J12="DA-RFO2 HVCDP","High Value Crops (Vegetables/Fruits/Rootcrops)",J12="DA-RFO2 HVCDP Export","High Value Export Crops (Dragon Fruit/Ube/Okra/Banana)",J12="DA-RFO2 HVCDP Coffee","Coffee (HVCDP)",J12="DA-RFO2 LIVESTOCK","Livestock (Cattle/Carabao/Swine/Poultry)",J12="DA-RFO2 SAAD","Various Commodities (SAAD)",J12="DA-RFO2 4K","Various Commodities (4Ks)",J12="DA-RFO2 4KS","Various Commodities (4Ks)",J12="DA-RFO2 HALAL","Halal Food Products",J12="DA-RFO2 OAP","Organic Agriculture",J12="DA-RFO2 NUPAP","Vegetables (NUPAP/Urban Agri)",TRUE,IF(ISNUMBER(SEARCH("FMR",D12)),"Farm-to-Market Road",IF(ISNUMBER(SEARCH("RICE",D12)),"Rice",IF(ISNUMBER(SEARCH("CORN",D12)),"Corn",IF(ISNUMBER(SEARCH("HVCDP COFFEE",D12)),"Coffee (HVCDP)",IF(ISNUMBER(SEARCH("HVCDP EXPORT",D12)),"High Value Export Crops (Dragon Fruit/Ube/Okra/Banana)",IF(ISNUMBER(SEARCH("HVCDP",D12)),"High Value Crops (Vegetables/Fruits/Rootcrops)",IF(ISNUMBER(SEARCH("LIVESTOCK",D12)),"Livestock (Cattle/Carabao/Swine/Poultry)",IF(ISNUMBER(SEARCH("SAAD",D12)),"Various Commodities (SAAD)",IF(ISNUMBER(SEARCH("4KS",D12)),"Various Commodities (4Ks)",IF(ISNUMBER(SEARCH("4K",D12)),"Various Commodities (4Ks)",IF(ISNUMBER(SEARCH("HALAL",D12)),"Halal Food Products",IF(ISNUMBER(SEARCH("OAP",D12)),"Organic Agriculture",IF(ISNUMBER(SEARCH("NUPAP",D12)),"Vegetables (NUPAP/Urban Agri)","")))))))))))))) -> Farm-to-Market Road
A13: Region 2 | B13: Batanes | C13: Basco | D13: HVC-based Project distributed - SAAD Program | E13: 1555 | J13: DA-RFO2 SAAD | AA13: =_xlfn.IFS(J13="DA-FMRDP","Farm-to-Market Road",J13="DA-RFO2 RICE","Rice",J13="DA-RFO2 Rice Program","Rice",J13="DA-RFO2 CORN","Corn",J13="DA-RFO2 Corn Program","Corn",J13="DA-RFO2 HVCDP","High Value Crops (Vegetables/Fruits/Rootcrops)",J13="DA-RFO2 HVCDP Export","High Value Export Crops (Dragon Fruit/Ube/Okra/Banana)",J13="DA-RFO2 HVCDP Coffee","Coffee (HVCDP)",J13="DA-RFO2 LIVESTOCK","Livestock (Cattle/Carabao/Swine/Poultry)",J13="DA-RFO2 SAAD","Various Commodities (SAAD)",J13="DA-RFO2 4K","Various Commodities (4Ks)",J13="DA-RFO2 4KS","Various Commodities (4Ks)",J13="DA-RFO2 HALAL","Halal Food Products",J13="DA-RFO2 OAP","Organic Agriculture",J13="DA-RFO2 NUPAP","Vegetables (NUPAP/Urban Agri)",TRUE,IF(ISNUMBER(SEARCH("FMR",D13)),"Farm-to-Market Road",IF(ISNUMBER(SEARCH("RICE",D13)),"Rice",IF(ISNUMBER(SEARCH("CORN",D13)),"Corn",IF(ISNUMBER(SEARCH("HVCDP COFFEE",D13)),"Coffee (HVCDP)",IF(ISNUMBER(SEARCH("HVCDP EXPORT",D13)),"High Value Export Crops (Dragon Fruit/Ube/Okra/Banana)",IF(ISNUMBER(SEARCH("HVCDP",D13)),"High Value Crops (Vegetables/Fruits/Rootcrops)",IF(ISNUMBER(SEARCH("LIVESTOCK",D13)),"Livestock (Cattle/Carabao/Swine/Poultry)",IF(ISNUMBER(SEARCH("SAAD",D13)),"Various Commodities (SAAD)",IF(ISNUMBER(SEARCH("4KS",D13)),"Various Commodities (4Ks)",IF(ISNUMBER(SEARCH("4K",D13)),"Various Commodities (4Ks)",IF(ISNUMBER(SEARCH("HALAL",D13)),"Halal Food Products",IF(ISNUMBER(SEARCH("OAP",D13)),"Organic Agriculture",IF(ISNUMBER(SEARCH("NUPAP",D13)),"Vegetables (NUPAP/Urban Agri)","")))))))))))))) -> Various Commodities (SAAD)
A14: Region 2 | B14: Batanes | C14: Basco | D14: Organic Fertizer - HVCDP | E14: 120 | J14: DA-RFO2 HVCDP | AA14: =_xlfn.IFS(J14="DA-FMRDP","Farm-to-Market Road",J14="DA-RFO2 RICE","Rice",J14="DA-RFO2 Rice Program","Rice",J14="DA-RFO2 CORN","Corn",J14="DA-RFO2 Corn Program","Corn",J14="DA-RFO2 HVCDP","High Value Crops (Vegetables/Fruits/Rootcrops)",J14="DA-RFO2 HVCDP Export","High Value Export Crops (Dragon Fruit/Ube/Okra/Banana)",J14="DA-RFO2 HVCDP Coffee","Coffee (HVCDP)",J14="DA-RFO2 LIVESTOCK","Livestock (Cattle/Carabao/Swine/Poultry)",J14="DA-RFO2 SAAD","Various Commodities (SAAD)",J14="DA-RFO2 4K","Various Commodities (4Ks)",J14="DA-RFO2 4KS","Various Commodities (4Ks)",J14="DA-RFO2 HALAL","Halal Food Products",J14="DA-RFO2 OAP","Organic Agriculture",J14="DA-RFO2 NUPAP","Vegetables (NUPAP/Urban Agri)",TRUE,IF(ISNUMBER(SEARCH("FMR",D14)),"Farm-to-Market Road",IF(ISNUMBER(SEARCH("RICE",D14)),"Rice",IF(ISNUMBER(SEARCH("CORN",D14)),"Corn",IF(ISNUMBER(SEARCH("HVCDP COFFEE",D14)),"Coffee (HVCDP)",IF(ISNUMBER(SEARCH("HVCDP EXPORT",D14)),"High Value Export Crops (Dragon Fruit/Ube/Okra/Banana)",IF(ISNUMBER(SEARCH("HVCDP",D14)),"High Value Crops (Vegetables/Fruits/Rootcrops)",IF(ISNUMBER(SEARCH("LIVESTOCK",D14)),"Livestock (Cattle/Carabao/Swine/Poultry)",IF(ISNUMBER(SEARCH("SAAD",D14)),"Various Commodities (SAAD)",IF(ISNUMBER(SEARCH("4KS",D14)),"Various Commodities (4Ks)",IF(ISNUMBER(SEARCH("4K",D14)),"Various Commodities (4Ks)",IF(ISNUMBER(SEARCH("HALAL",D14)),"Halal Food Products",IF(ISNUMBER(SEARCH("OAP",D14)),"Organic Agriculture",IF(ISNUMBER(SEARCH("NUPAP",D14)),"Vegetables (NUPAP/Urban Agri)","")))))))))))))) -> High Value Crops (Vegetables/Fruits/Rootcrops)
A15: Region 2 | B15: Batanes | C15: Basco | D15: Seeds - HVCDP | E15: 7000 | J15: DA-RFO2 HVCDP | AA15: =_xlfn.IFS(J15="DA-FMRDP","Farm-to-Market Road",J15="DA-RFO2 RICE","Rice",J15="DA-RFO2 Rice Program","Rice",J15="DA-RFO2 CORN","Corn",J15="DA-RFO2 Corn Program","Corn",J15="DA-RFO2 HVCDP","High Value Crops (Vegetables/Fruits/Rootcrops)",J15="DA-RFO2 HVCDP Export","High Value Export Crops (Dragon Fruit/Ube/Okra/Banana)",J15="DA-RFO2 HVCDP Coffee","Coffee (HVCDP)",J15="DA-RFO2 LIVESTOCK","Livestock (Cattle/Carabao/Swine/Poultry)",J15="DA-RFO2 SAAD","Various Commodities (SAAD)",J15="DA-RFO2 4K","Various Commodities (4Ks)",J15="DA-RFO2 4KS","Various Commodities (4Ks)",J15="DA-RFO2 HALAL","Halal Food Products",J15="DA-RFO2 OAP","Organic Agriculture",J15="DA-RFO2 NUPAP","Vegetables (NUPAP/Urban Agri)",TRUE,IF(ISNUMBER(SEARCH("FMR",D15)),"Farm-to-Market Road",IF(ISNUMBER(SEARCH("RICE",D15)),"Rice",IF(ISNUMBER(SEARCH("CORN",D15)),"Corn",IF(ISNUMBER(SEARCH("HVCDP COFFEE",D15)),"Coffee (HVCDP)",IF(ISNUMBER(SEARCH("HVCDP EXPORT",D15)),"High Value Export Crops (Dragon Fruit/Ube/Okra/Banana)",IF(ISNUMBER(SEARCH("HVCDP",D15)),"High Value Crops (Vegetables/Fruits/Rootcrops)",IF(ISNUMBER(SEARCH("LIVESTOCK",D15)),"Livestock (Cattle/Carabao/Swine/Poultry)",IF(ISNUMBER(SEARCH("SAAD",D15)),"Various Commodities (SAAD)",IF(ISNUMBER(SEARCH("4KS",D15)),"Various Commodities (4Ks)",IF(ISNUMBER(SEARCH("4K",D15)),"Various Commodities (4Ks)",IF(ISNUMBER(SEARCH("HALAL",D15)),"Halal Food Products",IF(ISNUMBER(SEARCH("OAP",D15)),"Organic Agriculture",IF(ISNUMBER(SEARCH("NUPAP",D15)),"Vegetables (NUPAP/Urban Agri)","")))))))))))))) -> High Value Crops (Vegetables/Fruits/Rootcrops)
A16: Region 2 | B16: Batanes | C16: Itbayat | D16: Buying, Consolidation, and Packaging Centers | J16: DA-RFO2 | AA16: =_xlfn.IFS(J16="DA-FMRDP","Farm-to-Market Road",J16="DA-RFO2 RICE","Rice",J16="DA-RFO2 Rice Program","Rice",J16="DA-RFO2 CORN","Corn",J16="DA-RFO2 Corn Program","Corn",J16="DA-RFO2 HVCDP","High Value Crops (Vegetables/Fruits/Rootcrops)",J16="DA-RFO2 HVCDP Export","High Value Export Crops (Dragon Fruit/Ube/Okra/Banana)",J16="DA-RFO2 HVCDP Coffee","Coffee (HVCDP)",J16="DA-RFO2 LIVESTOCK","Livestock (Cattle/Carabao/Swine/Poultry)",J16="DA-RFO2 SAAD","Various Commodities (SAAD)",J16="DA-RFO2 4K","Various Commodities (4Ks)",J16="DA-RFO2 4KS","Various Commodities (4Ks)",J16="DA-RFO2 HALAL","Halal Food Products",J16="DA-RFO2 OAP","Organic Agriculture",J16="DA-RFO2 NUPAP","Vegetables (NUPAP/Urban Agri)",TRUE,IF(ISNUMBER(SEARCH("FMR",D16)),"Farm-to-Market Road",IF(ISNUMBER(SEARCH("RICE",D16)),"Rice",IF(ISNUMBER(SEARCH("CORN",D16)),"Corn",IF(ISNUMBER(SEARCH("HVCDP COFFEE",D16)),"Coffee (HVCDP)",IF(ISNUMBER(SEARCH("HVCDP EXPORT",D16)),"High Value Export Crops (Dragon Fruit/Ube/Okra/Banana)",IF(ISNUMBER(SEARCH("HVCDP",D16)),"High Value Crops (Vegetables/Fruits/Rootcrops)",IF(ISNUMBER(SEARCH("LIVESTOCK",D16)),"Livestock (Cattle/Carabao/Swine/Poultry)",IF(ISNUMBER(SEARCH("SAAD",D16)),"Various Commodities (SAAD)",IF(ISNUMBER(SEARCH("4KS",D16)),"Various Commodities (4Ks)",IF(ISNUMBER(SEARCH("4K",D16)),"Various Commodities (4Ks)",IF(ISNUMBER(SEARCH("HALAL",D16)),"Halal Food Products",IF(ISNUMBER(SEARCH("OAP",D16)),"Organic Agriculture",IF(ISNUMBER(SEARCH("NUPAP",D16)),"Vegetables (NUPAP/Urban Agri)",""))))))))))))))
A17: Region 2 | B17: Batanes | C17: Itbayat | D17: Construction of Aran-an-Kaysaysakan, Raele FMR, Brgy. Raele, Itbayat, Batanes | F17: 23400 | J17: DA-FMRDP | AA17: =_xlfn.IFS(J17="DA-FMRDP","Farm-to-Market Road",J17="DA-RFO2 RICE","Rice",J17="DA-RFO2 Rice Program","Rice",J17="DA-RFO2 CORN","Corn",J17="DA-RFO2 Corn Program","Corn",J17="DA-RFO2 HVCDP","High Value Crops (Vegetables/Fruits/Rootcrops)",J17="DA-RFO2 HVCDP Export","High Value Export Crops (Dragon Fruit/Ube/Okra/Banana)",J17="DA-RFO2 HVCDP Coffee","Coffee (HVCDP)",J17="DA-RFO2 LIVESTOCK","Livestock (Cattle/Carabao/Swine/Poultry)",J17="DA-RFO2 SAAD","Various Commodities (SAAD)",J17="DA-RFO2 4K","Various Commodities (4Ks)",J17="DA-RFO2 4KS","Various Commodities (4Ks)",J17="DA-RFO2 HALAL","Halal Food Products",J17="DA-RFO2 OAP","Organic Agriculture",J17="DA-RFO2 NUPAP","Vegetables (NUPAP/Urban Agri)",TRUE,IF(ISNUMBER(SEARCH("FMR",D17)),"Farm-to-Market Road",IF(ISNUMBER(SEARCH("RICE",D17)),"Rice",IF(ISNUMBER(SEARCH("CORN",D17)),"Corn",IF(ISNUMBER(SEARCH("HVCDP COFFEE",D17)),"Coffee (HVCDP)",IF(ISNUMBER(SEARCH("HVCDP EXPORT",D17)),"High Value Export Crops (Dragon Fruit/Ube/Okra/Banana)",IF(ISNUMBER(SEARCH("HVCDP",D17)),"High Value Crops (Vegetables/Fruits/Rootcrops)",IF(ISNUMBER(SEARCH("LIVESTOCK",D17)),"Livestock (Cattle/Carabao/Swine/Poultry)",IF(ISNUMBER(SEARCH("SAAD",D17)),"Various Commodities (SAAD)",IF(ISNUMBER(SEARCH("4KS",D17)),"Various Commodities (4Ks)",IF(ISNUMBER(SEARCH("4K",D17)),"Various Commodities (4Ks)",IF(ISNUMBER(SEARCH("HALAL",D17)),"Halal Food Products",IF(ISNUMBER(SEARCH("OAP",D17)),"Organic Agriculture",IF(ISNUMBER(SEARCH("NUPAP",D17)),"Vegetables (NUPAP/Urban Agri)","")))))))))))))) -> Farm-to-Market Road
A18: Region 2 | B18: Batanes | C18: Itbayat | D18: Construction of Camaya-Ripused, Sta. Lucia FMR, Brgy. Sta. Lucia, Itbayat, Batanes | F18: 25700 | J18: DA-FMRDP | AA18: =_xlfn.IFS(J18="DA-FMRDP","Farm-to-Market Road",J18="DA-RFO2 RICE","Rice",J18="DA-RFO2 Rice Program","Rice",J18="DA-RFO2 CORN","Corn",J18="DA-RFO2 Corn Program","Corn",J18="DA-RFO2 HVCDP","High Value Crops (Vegetables/Fruits/Rootcrops)",J18="DA-RFO2 HVCDP Export","High Value Export Crops (Dragon Fruit/Ube/Okra/Banana)",J18="DA-RFO2 HVCDP Coffee","Coffee (HVCDP)",J18="DA-RFO2 LIVESTOCK","Livestock (Cattle/Carabao/Swine/Poultry)",J18="DA-RFO2 SAAD","Various Commodities (SAAD)",J18="DA-RFO2 4K","Various Commodities (4Ks)",J18="DA-RFO2 4KS","Various Commodities (4Ks)",J18="DA-RFO2 HALAL","Halal Food Products",J18="DA-RFO2 OAP","Organic Agriculture",J18="DA-RFO2 NUPAP","Vegetables (NUPAP/Urban Agri)",TRUE,IF(ISNUMBER(SEARCH("FMR",D18)),"Farm-to-Market Road",IF(ISNUMBER(SEARCH("RICE",D18)),"Rice",IF(ISNUMBER(SEARCH("CORN",D18)),"Corn",IF(ISNUMBER(SEARCH("HVCDP COFFEE",D18)),"Coffee (HVCDP)",IF(ISNUMBER(SEARCH("HVCDP EXPORT",D18)),"High Value Export Crops (Dragon Fruit/Ube/Okra/Banana)",IF(ISNUMBER(SEARCH("HVCDP",D18)),"High Value Crops (Vegetables/Fruits/Rootcrops)",IF(ISNUMBER(SEARCH("LIVESTOCK",D18)),"Livestock (Cattle/Carabao/Swine/Poultry)",IF(ISNUMBER(SEARCH("SAAD",D18)),"Various Commodities (SAAD)",IF(ISNUMBER(SEARCH("4KS",D18)),"Various Commodities (4Ks)",IF(ISNUMBER(SEARCH("4K",D18)),"Various Commodities (4Ks)",IF(ISNUMBER(SEARCH("HALAL",D18)),"Halal Food Products",IF(ISNUMBER(SEARCH("OAP",D18)),"Organic Agriculture",IF(ISNUMBER(SEARCH("NUPAP",D18)),"Vegetables (NUPAP/Urban Agri)","")))))))))))))) -> Farm-to-Market Road
A19: Region 2 | B19: Batanes | C19: Itbayat | D19: FMR Construction/Concreting | E19: 35000 | J19: DA-FMRDP | AA19: =_xlfn.IFS(J19="DA-FMRDP","Farm-to-Market Road",J19="DA-RFO2 RICE","Rice",J19="DA-RFO2 Rice Program","Rice",J19="DA-RFO2 CORN","Corn",J19="DA-RFO2 Corn Program","Corn",J19="DA-RFO2 HVCDP","High Value Crops (Vegetables/Fruits/Rootcrops)",J19="DA-RFO2 HVCDP Export","High Value Export Crops (Dragon Fruit/Ube/Okra/Banana)",J19="DA-RFO2 HVCDP Coffee","Coffee (HVCDP)",J19="DA-RFO2 LIVESTOCK","Livestock (Cattle/Carabao/Swine/Poultry)",J19="DA-RFO2 SAAD","Various Commodities (SAAD)",J19="DA-RFO2 4K","Various Commodities (4Ks)",J19="DA-RFO2 4KS","Various Commodities (4Ks)",J19="DA-RFO2 HALAL","Halal Food Products",J19="DA-RFO2 OAP","Organic Agriculture",J19="DA-RFO2 NUPAP","Vegetables (NUPAP/Urban Agri)",TRUE,IF(ISNUMBER(SEARCH("FMR",D19)),"Farm-to-Market Road",IF(ISNUMBER(SEARCH("RICE",D19)),"Rice",IF(ISNUMBER(SEARCH("CORN",D19)),"Corn",IF(ISNUMBER(SEARCH("HVCDP COFFEE",D19)),"Coffee (HVCDP)",IF(ISNUMBER(SEARCH("HVCDP EXPORT",D19)),"High Value Export Crops (Dragon Fruit/Ube/Okra/Banana)",IF(ISNUMBER(SEARCH("HVCDP",D19)),"High Value Crops (Vegetables/Fruits/Rootcrops)",IF(ISNUMBER(SEARCH("LIVESTOCK",D19)),"Livestock (Cattle/Carabao/Swine/Poultry)",IF(ISNUMBER(SEARCH("SAAD",D19)),"Various Commodities (SAAD)",IF(ISNUMBER(SEARCH("4KS",D19)),"Various Commodities (4Ks)",IF(ISNUMBER(SEARCH("4K",D19)),"Various Commodities (4Ks)",IF(ISNUMBER(SEARCH("HALAL",D19)),"Halal Food Products",IF(ISNUMBER(SEARCH("OAP",D19)),"Organic Agriculture",IF(ISNUMBER(SEARCH("NUPAP",D19)),"Vegetables (NUPAP/Urban Agri)","")))))))))))))) -> Farm-to-Market Road
A20: Region 2 | B20: Batanes | C20: Itbayat | D20: HVC-based Project distributed - SAAD Program | E20: 1555 | J20: DA-RFO2 SAAD | AA20: =_xlfn.IFS(J20="DA-FMRDP","Farm-to-Market Road",J20="DA-RFO2 RICE","Rice",J20="DA-RFO2 Rice Program","Rice",J20="DA-RFO2 CORN","Corn",J20="DA-RFO2 Corn Program","Corn",J20="DA-RFO2 HVCDP","High Value Crops (Vegetables/Fruits/Rootcrops)",J20="DA-RFO2 HVCDP Export","High Value Export Crops (Dragon Fruit/Ube/Okra/Banana)",J20="DA-RFO2 HVCDP Coffee","Coffee (HVCDP)",J20="DA-RFO2 LIVESTOCK","Livestock (Cattle/Carabao/Swine/Poultry)",J20="DA-RFO2 SAAD","Various Commodities (SAAD)",J20="DA-RFO2 4K","Various Commodities (4Ks)",J20="DA-RFO2 4KS","Various Commodities (4Ks)",J20="DA-RFO2 HALAL","Halal Food Products",J20="DA-RFO2 OAP","Organic Agriculture",J20="DA-RFO2 NUPAP","Vegetables (NUPAP/Urban Agri)",TRUE,IF(ISNUMBER(SEARCH("FMR",D20)),"Farm-to-Market Road",IF(ISNUMBER(SEARCH("RICE",D20)),"Rice",IF(ISNUMBER(SEARCH("CORN",D20)),"Corn",IF(ISNUMBER(SEARCH("HVCDP COFFEE",D20)),"Coffee (HVCDP)",IF(ISNUMBER(SEARCH("HVCDP EXPORT",D20)),"High Value Export Crops (Dragon Fruit/Ube/Okra/Banana)",IF(ISNUMBER(SEARCH("HVCDP",D20)),"High Value Crops (Vegetables/Fruits/Rootcrops)",IF(ISNUMBER(SEARCH("LIVESTOCK",D20)),"Livestock (Cattle/Carabao/Swine/Poultry)",IF(ISNUMBER(SEARCH("SAAD",D20)),"Various Commodities (SAAD)",IF(ISNUMBER(SEARCH("4KS",D20)),"Various Commodities (4Ks)",IF(ISNUMBER(SEARCH("4K",D20)),"Various Commodities (4Ks)",IF(ISNUMBER(SEARCH("HALAL",D20)),"Halal Food Products",IF(ISNUMBER(SEARCH("OAP",D20)),"Organic Agriculture",IF(ISNUMBER(SEARCH("NUPAP",D20)),"Vegetables (NUPAP/Urban Agri)","")))))))))))))) -> Various Commodities (SAAD)
A21: Region 2 | B21: Batanes | C21: Itbayat | D21: Organic Fertizer - HVCDP | E21: 120 | J21: DA-RFO2 HVCDP | AA21: =_xlfn.IFS(J21="DA-FMRDP","Farm-to-Market Road",J21="DA-RFO2 RICE","Rice",J21="DA-RFO2 Rice Program","Rice",J21="DA-RFO2 CORN","Corn",J21="DA-RFO2 Corn Program","Corn",J21="DA-RFO2 HVCDP","High Value Crops (Vegetables/Fruits/Rootcrops)",J21="DA-RFO2 HVCDP Export","High Value Export Crops (Dragon Fruit/Ube/Okra/Banana)",J21="DA-RFO2 HVCDP Coffee","Coffee (HVCDP)",J21="DA-RFO2 LIVESTOCK","Livestock (Cattle/Carabao/Swine/Poultry)",J21="DA-RFO2 SAAD","Various Commodities (SAAD)",J21="DA-RFO2 4K","Various Commodities (4Ks)",J21="DA-RFO2 4KS","Various Commodities (4Ks)",J21="DA-RFO2 HALAL","Halal Food Products",J21="DA-RFO2 OAP","Organic Agriculture",J21="DA-RFO2 NUPAP","Vegetables (NUPAP/Urban Agri)",TRUE,IF(ISNUMBER(SEARCH("FMR",D21)),"Farm-to-Market Road",IF(ISNUMBER(SEARCH("RICE",D21)),"Rice",IF(ISNUMBER(SEARCH("CORN",D21)),"Corn",IF(ISNUMBER(SEARCH("HVCDP COFFEE",D21)),"Coffee (HVCDP)",IF(ISNUMBER(SEARCH("HVCDP EXPORT",D21)),"High Value Export Crops (Dragon Fruit/Ube/Okra/Banana)",IF(ISNUMBER(SEARCH("HVCDP",D21)),"High Value Crops (Vegetables/Fruits/Rootcrops)",IF(ISNUMBER(SEARCH("LIVESTOCK",D21)),"Livestock (Cattle/Carabao/Swine/Poultry)",IF(ISNUMBER(SEARCH("SAAD",D21)),"Various Commodities (SAAD)",IF(ISNUMBER(SEARCH("4KS",D21)),"Various Commodities (4Ks)",IF(ISNUMBER(SEARCH("4K",D21)),"Various Commodities (4Ks)",IF(ISNUMBER(SEARCH("HALAL",D21)),"Halal Food Products",IF(ISNUMBER(SEARCH("OAP",D21)),"Organic Agriculture",IF(ISNUMBER(SEARCH("NUPAP",D21)),"Vegetables (NUPAP/Urban Agri)","")))))))))))))) -> High Value Crops (Vegetables/Fruits/Rootcrops)
A22: Region 2 | B22: Batanes | C22: Itbayat | D22: Potable Water Supply Systems | J22: DA-RFO2 | AA22: =_xlfn.IFS(J22="DA-FMRDP","Farm-to-Market Road",J22="DA-RFO2 RICE","Rice",J22="DA-RFO2 Rice Program","Rice",J22="DA-RFO2 CORN","Corn",J22="DA-RFO2 Corn Program","Corn",J22="DA-RFO2 HVCDP","High Value Crops (Vegetables/Fruits/Rootcrops)",J22="DA-RFO2 HVCDP Export","High Value Export Crops (Dragon Fruit/Ube/Okra/Banana)",J22="DA-RFO2 HVCDP Coffee","Coffee (HVCDP)",J22="DA-RFO2 LIVESTOCK","Livestock (Cattle/Carabao/Swine/Poultry)",J22="DA-RFO2 SAAD","Various Commodities (SAAD)",J22="DA-RFO2 4K","Various Commodities (4Ks)",J22="DA-RFO2 4KS","Various Commodities (4Ks)",J22="DA-RFO2 HALAL","Halal Food Products",J22="DA-RFO2 OAP","Organic Agriculture",J22="DA-RFO2 NUPAP","Vegetables (NUPAP/Urban Agri)",TRUE,IF(ISNUMBER(SEARCH("FMR",D22)),"Farm-to-Market Road",IF(ISNUMBER(SEARCH("RICE",D22)),"Rice",IF(ISNUMBER(SEARCH("CORN",D22)),"Corn",IF(ISNUMBER(SEARCH("HVCDP COFFEE",D22)),"Coffee (HVCDP)",IF(ISNUMBER(SEARCH("HVCDP EXPORT",D22)),"High Value Export Crops (Dragon Fruit/Ube/Okra/Banana)",IF(ISNUMBER(SEARCH("HVCDP",D22)),"High Value Crops (Vegetables/Fruits/Rootcrops)",IF(ISNUMBER(SEARCH("LIVESTOCK",D22)),"Livestock (Cattle/Carabao/Swine/Poultry)",IF(ISNUMBER(SEARCH("SAAD",D22)),"Various Commodities (SAAD)",IF(ISNUMBER(SEARCH("4KS",D22)),"Various Commodities (4Ks)",IF(ISNUMBER(SEARCH("4K",D22)),"Various Commodities (4Ks)",IF(ISNUMBER(SEARCH("HALAL",D22)),"Halal Food Products",IF(ISNUMBER(SEARCH("OAP",D22)),"Organic Agriculture",IF(ISNUMBER(SEARCH("NUPAP",D22)),"Vegetables (NUPAP/Urban Agri)",""))))))))))))))
A23: Region 2 | B23: Batanes | C23: Itbayat | D23: Rice Processing Centers | J23: DA-RFO2 | AA23: =_xlfn.IFS(J23="DA-FMRDP","Farm-to-Market Road",J23="DA-RFO2 RICE","Rice",J23="DA-RFO2 Rice Program","Rice",J23="DA-RFO2 CORN","Corn",J23="DA-RFO2 Corn Program","Corn",J23="DA-RFO2 HVCDP","High Value Crops (Vegetables/Fruits/Rootcrops)",J23="DA-RFO2 HVCDP Export","High Value Export Crops (Dragon Fruit/Ube/Okra/Banana)",J23="DA-RFO2 HVCDP Coffee","Coffee (HVCDP)",J23="DA-RFO2 LIVESTOCK","Livestock (Cattle/Carabao/Swine/Poultry)",J23="DA-RFO2 SAAD","Various Commodities (SAAD)",J23="DA-RFO2 4K","Various Commodities (4Ks)",J23="DA-RFO2 4KS","Various Commodities (4Ks)",J23="DA-RFO2 HALAL","Halal Food Products",J23="DA-RFO2 OAP","Organic Agriculture",J23="DA-RFO2 NUPAP","Vegetables (NUPAP/Urban Agri)",TRUE,IF(ISNUMBER(SEARCH("FMR",D23)),"Farm-to-Market Road",IF(ISNUMBER(SEARCH("RICE",D23)),"Rice",IF(ISNUMBER(SEARCH("CORN",D23)),"Corn",IF(ISNUMBER(SEARCH("HVCDP COFFEE",D23)),"Coffee (HVCDP)",IF(ISNUMBER(SEARCH("HVCDP EXPORT",D23)),"High Value Export Crops (Dragon Fruit/Ube/Okra/Banana)",IF(ISNUMBER(SEARCH("HVCDP",D23)),"High Value Crops (Vegetables/Fruits/Rootcrops)",IF(ISNUMBER(SEARCH("LIVESTOCK",D23)),"Livestock (Cattle/Carabao/Swine/Poultry)",IF(ISNUMBER(SEARCH("SAAD",D23)),"Various Commodities (SAAD)",IF(ISNUMBER(SEARCH("4KS",D23)),"Various Commodities (4Ks)",IF(ISNUMBER(SEARCH("4K",D23)),"Various Commodities (4Ks)",IF(ISNUMBER(SEARCH("HALAL",D23)),"Halal Food Products",IF(ISNUMBER(SEARCH("OAP",D23)),"Organic Agriculture",IF(ISNUMBER(SEARCH("NUPAP",D23)),"Vegetables (NUPAP/Urban Agri)","")))))))))))))) -> Rice
A24: Region 2 | B24: Batanes | C24: Itbayat | D24: Seeds - HVCDP | E24: 7000 | J24: DA-RFO2 HVCDP | AA24: =_xlfn.IFS(J24="DA-FMRDP","Farm-to-Market Road",J24="DA-RFO2 RICE","Rice",J24="DA-RFO2 Rice Program","Rice",J24="DA-RFO2 CORN","Corn",J24="DA-RFO2 Corn Program","Corn",J24="DA-RFO2 HVCDP","High Value Crops (Vegetables/Fruits/Rootcrops)",J24="DA-RFO2 HVCDP Export","High Value Export Crops (Dragon Fruit/Ube/Okra/Banana)",J24="DA-RFO2 HVCDP Coffee","Coffee (HVCDP)",J24="DA-RFO2 LIVESTOCK","Livestock (Cattle/Carabao/Swine/Poultry)",J24="DA-RFO2 SAAD","Various Commodities (SAAD)",J24="DA-RFO2 4K","Various Commodities (4Ks)",J24="DA-RFO2 4KS","Various Commodities (4Ks)",J24="DA-RFO2 HALAL","Halal Food Products",J24="DA-RFO2 OAP","Organic Agriculture",J24="DA-RFO2 NUPAP","Vegetables (NUPAP/Urban Agri)",TRUE,IF(ISNUMBER(SEARCH("FMR",D24)),"Farm-to-Market Road",IF(ISNUMBER(SEARCH("RICE",D24)),"Rice",IF(ISNUMBER(SEARCH("CORN",D24)),"Corn",IF(ISNUMBER(SEARCH("HVCDP COFFEE",D24)),"Coffee (HVCDP)",IF(ISNUMBER(SEARCH("HVCDP EXPORT",D24)),"High Value Export Crops (Dragon Fruit/Ube/Okra/Banana)",IF(ISNUMBER(SEARCH("HVCDP",D24)),"High Value Crops (Vegetables/Fruits/Rootcrops)",IF(ISNUMBER(SEARCH("LIVESTOCK",D24)),"Livestock (Cattle/Carabao/Swine/Poultry)",IF(ISNUMBER(SEARCH("SAAD",D24)),"Various Commodities (SAAD)",IF(ISNUMBER(SEARCH("4KS",D24)),"Various Commodities (4Ks)",IF(ISNUMBER(SEARCH("4K",D24)),"Various Commodities (4Ks)",IF(ISNUMBER(SEARCH("HALAL",D24)),"Halal Food Products",IF(ISNUMBER(SEARCH("OAP",D24)),"Organic Agriculture",IF(ISNUMBER(SEARCH("NUPAP",D24)),"Vegetables (NUPAP/Urban Agri)","")))))))))))))) -> High Value Crops (Vegetables/Fruits/Rootcrops)
A25: Region 2 | B25: Batanes | C25: Ivana | D25: Construction of Nakurang-Tukon-Chatujian, Brgy Radiwan FMR Phase IV, Brgy. Radiwan, Ivana, Batanes | F25: 48000 | J25: DA-FMRDP | AA25: =_xlfn.IFS(J25="DA-FMRDP","Farm-to-Market Road",J25="DA-RFO2 RICE","Rice",J25="DA-RFO2 Rice Program","Rice",J25="DA-RFO2 CORN","Corn",J25="DA-RFO2 Corn Program","Corn",J25="DA-RFO2 HVCDP","High Value Crops (Vegetables/Fruits/Rootcrops)",J25="DA-RFO2 HVCDP Export","High Value Export Crops (Dragon Fruit/Ube/Okra/Banana)",J25="DA-RFO2 HVCDP Coffee","Coffee (HVCDP)",J25="DA-RFO2 LIVESTOCK","Livestock (Cattle/Carabao/Swine/Poultry)",J25="DA-RFO2 SAAD","Various Commodities (SAAD)",J25="DA-RFO2 4K","Various Commodities (4Ks)",J25="DA-RFO2 4KS","Various Commodities (4Ks)",J25="DA-RFO2 HALAL","Halal Food Products",J25="DA-RFO2 OAP","Organic Agriculture",J25="DA-RFO2 NUPAP","Vegetables (NUPAP/Urban Agri)",TRUE,IF(ISNUMBER(SEARCH("FMR",D25)),"Farm-to-Market Road",IF(ISNUMBER(SEARCH("RICE",D25)),"Rice",IF(ISNUMBER(SEARCH("CORN",D25)),"Corn",IF(ISNUMBER(SEARCH("HVCDP COFFEE",D25)),"Coffee (HVCDP)",IF(ISNUMBER(SEARCH("HVCDP EXPORT",D25)),"High Value Export Crops (Dragon Fruit/Ube/Okra/Banana)",IF(ISNUMBER(SEARCH("HVCDP",D25)),"High Value Crops (Vegetables/Fruits/Rootcrops)",IF(ISNUMBER(SEARCH("LIVESTOCK",D25)),"Livestock (Cattle/Carabao/Swine/Poultry)",IF(ISNUMBER(SEARCH("SAAD",D25)),"Various Commodities (SAAD)",IF(ISNUMBER(SEARCH("4KS",D25)),"Various Commodities (4Ks)",IF(ISNUMBER(SEARCH("4K",D25)),"Various Commodities (4Ks)",IF(ISNUMBER(SEARCH("HALAL",D25)),"Halal Food Products",IF(ISNUMBER(SEARCH("OAP",D25)),"Organic Agriculture",IF(ISNUMBER(SEARCH("NUPAP",D25)),"Vegetables (NUPAP/Urban Agri)","")))))))))))))) -> Farm-to-Market Road
A26: Region 2 | B26: Batanes | C26: Ivana | D26: Construction of Sivukot-Aramain, Brgy Tuhel FMR, Brgy. Tubel, Ivana, Batanes | F26: 39120 | J26: DA-FMRDP | AA26: =_xlfn.IFS(J26="DA-FMRDP","Farm-to-Market Road",J26="DA-RFO2 RICE","Rice",J26="DA-RFO2 Rice Program","Rice",J26="DA-RFO2 CORN","Corn",J26="DA-RFO2 Corn Program","Corn",J26="DA-RFO2 HVCDP","High Value Crops (Vegetables/Fruits/Rootcrops)",J26="DA-RFO2 HVCDP Export","High Value Export Crops (Dragon Fruit/Ube/Okra/Banana)",J26="DA-RFO2 HVCDP Coffee","Coffee (HVCDP)",J26="DA-RFO2 LIVESTOCK","Livestock (Cattle/Carabao/Swine/Poultry)",J26="DA-RFO2 SAAD","Various Commodities (SAAD)",J26="DA-RFO2 4K","Various Commodities (4Ks)",J26="DA-RFO2 4KS","Various Commodities (4Ks)",J26="DA-RFO2 HALAL","Halal Food Products",J26="DA-RFO2 OAP","Organic Agriculture",J26="DA-RFO2 NUPAP","Vegetables (NUPAP/Urban Agri)",TRUE,IF(ISNUMBER(SEARCH("FMR",D26)),"Farm-to-Market Road",IF(ISNUMBER(SEARCH("RICE",D26)),"Rice",IF(ISNUMBER(SEARCH("CORN",D26)),"Corn",IF(ISNUMBER(SEARCH("HVCDP COFFEE",D26)),"Coffee (HVCDP)",IF(ISNUMBER(SEARCH("HVCDP EXPORT",D26)),"High Value Export Crops (Dragon Fruit/Ube/Okra/Banana)",IF(ISNUMBER(SEARCH("HVCDP",D26)),"High Value Crops (Vegetables/Fruits/Rootcrops)",IF(ISNUMBER(SEARCH("LIVESTOCK",D26)),"Livestock (Cattle/Carabao/Swine/Poultry)",IF(ISNUMBER(SEARCH("SAAD",D26)),"Various Commodities (SAAD)",IF(ISNUMBER(SEARCH("4KS",D26)),"Various Commodities (4Ks)",IF(ISNUMBER(SEARCH("4K",D26)),"Various Commodities (4Ks)",IF(ISNUMBER(SEARCH("HALAL",D26)),"Halal Food Products",IF(ISNUMBER(SEARCH("OAP",D26)),"Organic Agriculture",IF(ISNUMBER(SEARCH("NUPAP",D26)),"Vegetables (NUPAP/Urban Agri)","")))))))))))))) -> Farm-to-Market Road
A27: Region 2 | B27: Batanes | C27: Ivana | D27: FMR Construction/Concreting | E27: 12500 | J27: DA-FMRDP | AA27: =_xlfn.IFS(J27="DA-FMRDP","Farm-to-Market Road",J27="DA-RFO2 RICE","Rice",J27="DA-RFO2 Rice Program","Rice",J27="DA-RFO2 CORN","Corn",J27="DA-RFO2 Corn Program","Corn",J27="DA-RFO2 HVCDP","High Value Crops (Vegetables/Fruits/Rootcrops)",J27="DA-RFO2 HVCDP Export","High Value Export Crops (Dragon Fruit/Ube/Okra/Banana)",J27="DA-RFO2 HVCDP Coffee","Coffee (HVCDP)",J27="DA-RFO2 LIVESTOCK","Livestock (Cattle/Carabao/Swine/Poultry)",J27="DA-RFO2 SAAD","Various Commodities (SAAD)",J27="DA-RFO2 4K","Various Commodities (4Ks)",J27="DA-RFO2 4KS","Various Commodities (4Ks)",J27="DA-RFO2 HALAL","Halal Food Products",J27="DA-RFO2 OAP","Organic Agriculture",J27="DA-RFO2 NUPAP","Vegetables (NUPAP/Urban Agri)",TRUE,IF(ISNUMBER(SEARCH("FMR",D27)),"Farm-to-Market Road",IF(ISNUMBER(SEARCH("RICE",D27)),"Rice",IF(ISNUMBER(SEARCH("CORN",D27)),"Corn",IF(ISNUMBER(SEARCH("HVCDP COFFEE",D27)),"Coffee (HVCDP)",IF(ISNUMBER(SEARCH("HVCDP EXPORT",D27)),"High Value Export Crops (Dragon Fruit/Ube/Okra/Banana)",IF(ISNUMBER(SEARCH("HVCDP",D27)),"High Value Crops (Vegetables/Fruits/Rootcrops)",IF(ISNUMBER(SEARCH("LIVESTOCK",D27)),"Livestock (Cattle/Carabao/Swine/Poultry)",IF(ISNUMBER(SEARCH("SAAD",D27)),"Various Commodities (SAAD)",IF(ISNUMBER(SEARCH("4KS",D27)),"Various Commodities (4Ks)",IF(ISNUMBER(SEARCH("4K",D27)),"Various Commodities (4Ks)",IF(ISNUMBER(SEARCH("HALAL",D27)),"Halal Food Products",IF(ISNUMBER(SEARCH("OAP",D27)),"Organic Agriculture",IF(ISNUMBER(SEARCH("NUPAP",D27)),"Vegetables (NUPAP/Urban Agri)","")))))))))))))) -> Farm-to-Market Road
A28: Region 2 | B28: Batanes | C28: Ivana | D28: HVC-based Project distributed - SAAD Program | E28: 1555 | J28: DA-RFO2 SAAD | AA28: =_xlfn.IFS(J28="DA-FMRDP","Farm-to-Market Road",J28="DA-RFO2 RICE","Rice",J28="DA-RFO2 Rice Program","Rice",J28="DA-RFO2 CORN","Corn",J28="DA-RFO2 Corn Program","Corn",J28="DA-RFO2 HVCDP","High Value Crops (Vegetables/Fruits/Rootcrops)",J28="DA-RFO2 HVCDP Export","High Value Export Crops (Dragon Fruit/Ube/Okra/Banana)",J28="DA-RFO2 HVCDP Coffee","Coffee (HVCDP)",J28="DA-RFO2 LIVESTOCK","Livestock (Cattle/Carabao/Swine/Poultry)",J28="DA-RFO2 SAAD","Various Commodities (SAAD)",J28="DA-RFO2 4K","Various Commodities (4Ks)",J28="DA-RFO2 4KS","Various Commodities (4Ks)",J28="DA-RFO2 HALAL","Halal Food Products",J28="DA-RFO2 OAP","Organic Agriculture",J28="DA-RFO2 NUPAP","Vegetables (NUPAP/Urban Agri)",TRUE,IF(ISNUMBER(SEARCH("FMR",D28)),"Farm-to-Market Road",IF(ISNUMBER(SEARCH("RICE",D28)),"Rice",IF(ISNUMBER(SEARCH("CORN",D28)),"Corn",IF(ISNUMBER(SEARCH("HVCDP COFFEE",D28)),"Coffee (HVCDP)",IF(ISNUMBER(SEARCH("HVCDP EXPORT",D28)),"High Value Export Crops (Dragon Fruit/Ube/Okra/Banana)",IF(ISNUMBER(SEARCH("HVCDP",D28)),"High Value Crops (Vegetables/Fruits/Rootcrops)",IF(ISNUMBER(SEARCH("LIVESTOCK",D28)),"Livestock (Cattle/Carabao/Swine/Poultry)",IF(ISNUMBER(SEARCH("SAAD",D28)),"Various Commodities (SAAD)",IF(ISNUMBER(SEARCH("4KS",D28)),"Various Commodities (4Ks)",IF(ISNUMBER(SEARCH("4K",D28)),"Various Commodities (4Ks)",IF(ISNUMBER(SEARCH("HALAL",D28)),"Halal Food Products",IF(ISNUMBER(SEARCH("OAP",D28)),"Organic Agriculture",IF(ISNUMBER(SEARCH("NUPAP",D28)),"Vegetables (NUPAP/Urban Agri)","")))))))))))))) -> Various Commodities (SAAD)
A29: Region 2 | B29: Batanes | C29: Ivana | D29: Irrigation Systems | J29: DA-RFO2 | AA29: =_xlfn.IFS(J29="DA-FMRDP","Farm-to-Market Road",J29="DA-RFO2 RICE","Rice",J29="DA-RFO2 Rice Program","Rice",J29="DA-RFO2 CORN","Corn",J29="DA-RFO2 Corn Program","Corn",J29="DA-RFO2 HVCDP","High Value Crops (Vegetables/Fruits/Rootcrops)",J29="DA-RFO2 HVCDP Export","High Value Export Crops (Dragon Fruit/Ube/Okra/Banana)",J29="DA-RFO2 HVCDP Coffee","Coffee (HVCDP)",J29="DA-RFO2 LIVESTOCK","Livestock (Cattle/Carabao/Swine/Poultry)",J29="DA-RFO2 SAAD","Various Commodities (SAAD)",J29="DA-RFO2 4K","Various Commodities (4Ks)",J29="DA-RFO2 4KS","Various Commodities (4Ks)",J29="DA-RFO2 HALAL","Halal Food Products",J29="DA-RFO2 OAP","Organic Agriculture",J29="DA-RFO2 NUPAP","Vegetables (NUPAP/Urban Agri)",TRUE,IF(ISNUMBER(SEARCH("FMR",D29)),"Farm-to-Market Road",IF(ISNUMBER(SEARCH("RICE",D29)),"Rice",IF(ISNUMBER(SEARCH("CORN",D29)),"Corn",IF(ISNUMBER(SEARCH("HVCDP COFFEE",D29)),"Coffee (HVCDP)",IF(ISNUMBER(SEARCH("HVCDP EXPORT",D29)),"High Value Export Crops (Dragon Fruit/Ube/Okra/Banana)",IF(ISNUMBER(SEARCH("HVCDP",D29)),"High Value Crops (Vegetables/Fruits/Rootcrops)",IF(ISNUMBER(SEARCH("LIVESTOCK",D29)),"Livestock (Cattle/Carabao/Swine/Poultry)",IF(ISNUMBER(SEARCH("SAAD",D29)),"Various Commodities (SAAD)",IF(ISNUMBER(SEARCH("4KS",D29)),"Various Commodities (4Ks)",IF(ISNUMBER(SEARCH("4K",D29)),"Various Commodities (4Ks)",IF(ISNUMBER(SEARCH("HALAL",D29)),"Halal Food Products",IF(ISNUMBER(SEARCH("OAP",D29)),"Organic Agriculture",IF(ISNUMBER(SEARCH("NUPAP",D29)),"Vegetables (NUPAP/Urban Agri)",""))))))))))))))
A30: Region 2 | B30: Batanes | C30: Ivana | D30: Potable Water Supply Systems | J30: DA-RFO2 | AA30: =_xlfn.IFS(J30="DA-FMRDP","Farm-to-Market Road",J30="DA-RFO2 RICE","Rice",J30="DA-RFO2 Rice Program","Rice",J30="DA-RFO2 CORN","Corn",J30="DA-RFO2 Corn Program","Corn",J30="DA-RFO2 HVCDP","High Value Crops (Vegetables/Fruits/Rootcrops)",J30="DA-RFO2 HVCDP Export","High Value Export Crops (Dragon Fruit/Ube/Okra/Banana)",J30="DA-RFO2 HVCDP Coffee","Coffee (HVCDP)",J30="DA-RFO2 LIVESTOCK","Livestock (Cattle/Carabao/Swine/Poultry)",J30="DA-RFO2 SAAD","Various Commodities (SAAD)",J30="DA-RFO2 4K","Various Commodities (4Ks)",J30="DA-RFO2 4KS","Various Commodities (4Ks)",J30="DA-RFO2 HALAL","Halal Food Products",J30="DA-RFO2 OAP","Organic Agriculture",J30="DA-RFO2 NUPAP","Vegetables (NUPAP/Urban Agri)",TRUE,IF(ISNUMBER(SEARCH("FMR",D30)),"Farm-to-Market Road",IF(ISNUMBER(SEARCH("RICE",D30)),"Rice",IF(ISNUMBER(SEARCH("CORN",D30)),"Corn",IF(ISNUMBER(SEARCH("HVCDP COFFEE",D30)),"Coffee (HVCDP)",IF(ISNUMBER(SEARCH("HVCDP EXPORT",D30)),"High Value Export Crops (Dragon Fruit/Ube/Okra/Banana)",IF(ISNUMBER(SEARCH("HVCDP",D30)),"High Value Crops (Vegetables/Fruits/Rootcrops)",IF(ISNUMBER(SEARCH("LIVESTOCK",D30)),"Livestock (Cattle/Carabao/Swine/Poultry)",IF(ISNUMBER(SEARCH("SAAD",D30)),"Various Commodities (SAAD)",IF(ISNUMBER(SEARCH("4KS",D30)),"Various Commodities (4Ks)",IF(ISNUMBER(SEARCH("4K",D30)),"Various Commodities (4Ks)",IF(ISNUMBER(SEARCH("HALAL",D30)),"Halal Food Products",IF(ISNUMBER(SEARCH("OAP",D30)),"Organic Agriculture",IF(ISNUMBER(SEARCH("NUPAP",D30)),"Vegetables (NUPAP/Urban Agri)",""))))))))))))))
A31: Region 2 | B31: Batanes | C31: Ivana | D31: Silos | J31: DA-RFO2 | AA31: =_xlfn.IFS(J31="DA-FMRDP","Farm-to-Market Road",J31="DA-RFO2 RICE","Rice",J31="DA-RFO2 Rice Program","Rice",J31="DA-RFO2 CORN","Corn",J31="DA-RFO2 Corn Program","Corn",J31="DA-RFO2 HVCDP","High Value Crops (Vegetables/Fruits/Rootcrops)",J31="DA-RFO2 HVCDP Export","High Value Export Crops (Dragon Fruit/Ube/Okra/Banana)",J31="DA-RFO2 HVCDP Coffee","Coffee (HVCDP)",J31="DA-RFO2 LIVESTOCK","Livestock (Cattle/Carabao/Swine/Poultry)",J31="DA-RFO2 SAAD","Various Commodities (SAAD)",J31="DA-RFO2 4K","Various Commodities (4Ks)",J31="DA-RFO2 4KS","Various Commodities (4Ks)",J31="DA-RFO2 HALAL","Halal Food Products",J31="DA-RFO2 OAP","Organic Agriculture",J31="DA-RFO2 NUPAP","Vegetables (NUPAP/Urban Agri)",TRUE,IF(ISNUMBER(SEARCH("FMR",D31)),"Farm-to-Market Road",IF(ISNUMBER(SEARCH("RICE",D31)),"Rice",IF(ISNUMBER(SEARCH("CORN",D31)),"Corn",IF(ISNUMBER(SEARCH("HVCDP COFFEE",D31)),"Coffee (HVCDP)",IF(ISNUMBER(SEARCH("HVCDP EXPORT",D31)),"High Value Export Crops (Dragon Fruit/Ube/Okra/Banana)",IF(ISNUMBER(SEARCH("HVCDP",D31)),"High Value Crops (Vegetables/Fruits/Rootcrops)",IF(ISNUMBER(SEARCH("LIVESTOCK",D31)),"Livestock (Cattle/Carabao/Swine/Poultry)",IF(ISNUMBER(SEARCH("SAAD",D31)),"Various Commodities (SAAD)",IF(ISNUMBER(SEARCH("4KS",D31)),"Various Commodities (4Ks)",IF(ISNUMBER(SEARCH("4K",D31)),"Various Commodities (4Ks)",IF(ISNUMBER(SEARCH("HALAL",D31)),"Halal Food Products",IF(ISNUMBER(SEARCH("OAP",D31)),"Organic Agriculture",IF(ISNUMBER(SEARCH("NUPAP",D31)),"Vegetables (NUPAP/Urban Agri)",""))))))))))))))
A32: Region 2 | B32: Batanes | C32: Ivana | D32: Slaughterhouse & Abattoir | J32: DA-RFO2 | AA32: =_xlfn.IFS(J32="DA-FMRDP","Farm-to-Market Road",J32="DA-RFO2 RICE","Rice",J32="DA-RFO2 Rice Program","Rice",J32="DA-RFO2 CORN","Corn",J32="DA-RFO2 Corn Program","Corn",J32="DA-RFO2 HVCDP","High Value Crops (Vegetables/Fruits/Rootcrops)",J32="DA-RFO2 HVCDP Export","High Value Export Crops (Dragon Fruit/Ube/Okra/Banana)",J32="DA-RFO2 HVCDP Coffee","Coffee (HVCDP)",J32="DA-RFO2 LIVESTOCK","Livestock (Cattle/Carabao/Swine/Poultry)",J32="DA-RFO2 SAAD","Various Commodities (SAAD)",J32="DA-RFO2 4K","Various Commodities (4Ks)",J32="DA-RFO2 4KS","Various Commodities (4Ks)",J32="DA-RFO2 HALAL","Halal Food Products",J32="DA-RFO2 OAP","Organic Agriculture",J32="DA-RFO2 NUPAP","Vegetables (NUPAP/Urban Agri)",TRUE,IF(ISNUMBER(SEARCH("FMR",D32)),"Farm-to-Market Road",IF(ISNUMBER(SEARCH("RICE",D32)),"Rice",IF(ISNUMBER(SEARCH("CORN",D32)),"Corn",IF(ISNUMBER(SEARCH("HVCDP COFFEE",D32)),"Coffee (HVCDP)",IF(ISNUMBER(SEARCH("HVCDP EXPORT",D32)),"High Value Export Crops (Dragon Fruit/Ube/Okra/Banana)",IF(ISNUMBER(SEARCH("HVCDP",D32)),"High Value Crops (Vegetables/Fruits/Rootcrops)",IF(ISNUMBER(SEARCH("LIVESTOCK",D32)),"Livestock (Cattle/Carabao/Swine/Poultry)",IF(ISNUMBER(SEARCH("SAAD",D32)),"Various Commodities (SAAD)",IF(ISNUMBER(SEARCH("4KS",D32)),"Various Commodities (4Ks)",IF(ISNUMBER(SEARCH("4K",D32)),"Various Commodities (4Ks)",IF(ISNUMBER(SEARCH("HALAL",D32)),"Halal Food Products",IF(ISNUMBER(SEARCH("OAP",D32)),"Organic Agriculture",IF(ISNUMBER(SEARCH("NUPAP",D32)),"Vegetables (NUPAP/Urban Agri)",""))))))))))))))
A33: Region 2 | B33: Batanes | C33: Mahatao | D33: Buying, Consolidation, and Packaging Centers | J33: DA-RFO2 | AA33: =_xlfn.IFS(J33="DA-FMRDP","Farm-to-Market Road",J33="DA-RFO2 RICE","Rice",J33="DA-RFO2 Rice Program","Rice",J33="DA-RFO2 CORN","Corn",J33="DA-RFO2 Corn Program","Corn",J33="DA-RFO2 HVCDP","High Value Crops (Vegetables/Fruits/Rootcrops)",J33="DA-RFO2 HVCDP Export","High Value Export Crops (Dragon Fruit/Ube/Okra/Banana)",J33="DA-RFO2 HVCDP Coffee","Coffee (HVCDP)",J33="DA-RFO2 LIVESTOCK","Livestock (Cattle/Carabao/Swine/Poultry)",J33="DA-RFO2 SAAD","Various Commodities (SAAD)",J33="DA-RFO2 4K","Various Commodities (4Ks)",J33="DA-RFO2 4KS","Various Commodities (4Ks)",J33="DA-RFO2 HALAL","Halal Food Products",J33="DA-RFO2 OAP","Organic Agriculture",J33="DA-RFO2 NUPAP","Vegetables (NUPAP/Urban Agri)",TRUE,IF(ISNUMBER(SEARCH("FMR",D33)),"Farm-to-Market Road",IF(ISNUMBER(SEARCH("RICE",D33)),"Rice",IF(ISNUMBER(SEARCH("CORN",D33)),"Corn",IF(ISNUMBER(SEARCH("HVCDP COFFEE",D33)),"Coffee (HVCDP)",IF(ISNUMBER(SEARCH("HVCDP EXPORT",D33)),"High Value Export Crops (Dragon Fruit/Ube/Okra/Banana)",IF(ISNUMBER(SEARCH("HVCDP",D33)),"High Value Crops (Vegetables/Fruits/Rootcrops)",IF(ISNUMBER(SEARCH("LIVESTOCK",D33)),"Livestock (Cattle/Carabao/Swine/Poultry)",IF(ISNUMBER(SEARCH("SAAD",D33)),"Various Commodities (SAAD)",IF(ISNUMBER(SEARCH("4KS",D33)),"Various Commodities (4Ks)",IF(ISNUMBER(SEARCH("4K",D33)),"Various Commodities (4Ks)",IF(ISNUMBER(SEARCH("HALAL",D33)),"Halal Food Products",IF(ISNUMBER(SEARCH("OAP",D33)),"Organic Agriculture",IF(ISNUMBER(SEARCH("NUPAP",D33)),"Vegetables (NUPAP/Urban Agri)",""))))))))))))))
A34: Region 2 | B34: Batanes | C34: Mahatao | D34: FMR Construction/Concreting | E34: 12500 | J34: DA-FMRDP | AA34: =_xlfn.IFS(J34="DA-FMRDP","Farm-to-Market Road",J34="DA-RFO2 RICE","Rice",J34="DA-RFO2 Rice Program","Rice",J34="DA-RFO2 CORN","Corn",J34="DA-RFO2 Corn Program","Corn",J34="DA-RFO2 HVCDP","High Value Crops (Vegetables/Fruits/Rootcrops)",J34="DA-RFO2 HVCDP Export","High Value Export Crops (Dragon Fruit/Ube/Okra/Banana)",J34="DA-RFO2 HVCDP Coffee","Coffee (HVCDP)",J34="DA-RFO2 LIVESTOCK","Livestock (Cattle/Carabao/Swine/Poultry)",J34="DA-RFO2 SAAD","Various Commodities (SAAD)",J34="DA-RFO2 4K","Various Commodities (4Ks)",J34="DA-RFO2 4KS","Various Commodities (4Ks)",J34="DA-RFO2 HALAL","Halal Food Products",J34="DA-RFO2 OAP","Organic Agriculture",J34="DA-RFO2 NUPAP","Vegetables (NUPAP/Urban Agri)",TRUE,IF(ISNUMBER(SEARCH("FMR",D34)),"Farm-to-Market Road",IF(ISNUMBER(SEARCH("RICE",D34)),"Rice",IF(ISNUMBER(SEARCH("CORN",D34)),"Corn",IF(ISNUMBER(SEARCH("HVCDP COFFEE",D34)),"Coffee (HVCDP)",IF(ISNUMBER(SEARCH("HVCDP EXPORT",D34)),"High Value Export Crops (Dragon Fruit/Ube/Okra/Banana)",IF(ISNUMBER(SEARCH("HVCDP",D34)),"High Value Crops (Vegetables/Fruits/Rootcrops)",IF(ISNUMBER(SEARCH("LIVESTOCK",D34)),"Livestock (Cattle/Carabao/Swine/Poultry)",IF(ISNUMBER(SEARCH("SAAD",D34)),"Various Commodities (SAAD)",IF(ISNUMBER(SEARCH("4KS",D34)),"Various Commodities (4Ks)",IF(ISNUMBER(SEARCH("4K",D34)),"Various Commodities (4Ks)",IF(ISNUMBER(SEARCH("HALAL",D34)),"Halal Food Products",IF(ISNUMBER(SEARCH("OAP",D34)),"Organic Agriculture",IF(ISNUMBER(SEARCH("NUPAP",D34)),"Vegetables (NUPAP/Urban Agri)","")))))))))))))) -> Farm-to-Market Road
A35: Region 2 | B35: Batanes | C35: Mahatao | D35: Mechanical Dryers / Multi-Purpose Dryers | J35: DA-RFO2 | AA35: =_xlfn.IFS(J35="DA-FMRDP","Farm-to-Market Road",J35="DA-RFO2 RICE","Rice",J35="DA-RFO2 Rice Program","Rice",J35="DA-RFO2 CORN","Corn",J35="DA-RFO2 Corn Program","Corn",J35="DA-RFO2 HVCDP","High Value Crops (Vegetables/Fruits/Rootcrops)",J35="DA-RFO2 HVCDP Export","High Value Export Crops (Dragon Fruit/Ube/Okra/Banana)",J35="DA-RFO2 HVCDP Coffee","Coffee (HVCDP)",J35="DA-RFO2 LIVESTOCK","Livestock (Cattle/Carabao/Swine/Poultry)",J35="DA-RFO2 SAAD","Various Commodities (SAAD)",J35="DA-RFO2 4K","Various Commodities (4Ks)",J35="DA-RFO2 4KS","Various Commodities (4Ks)",J35="DA-RFO2 HALAL","Halal Food Products",J35="DA-RFO2 OAP","Organic Agriculture",J35="DA-RFO2 NUPAP","Vegetables (NUPAP/Urban Agri)",TRUE,IF(ISNUMBER(SEARCH("FMR",D35)),"Farm-to-Market Road",IF(ISNUMBER(SEARCH("RICE",D35)),"Rice",IF(ISNUMBER(SEARCH("CORN",D35)),"Corn",IF(ISNUMBER(SEARCH("HVCDP COFFEE",D35)),"Coffee (HVCDP)",IF(ISNUMBER(SEARCH("HVCDP EXPORT",D35)),"High Value Export Crops (Dragon Fruit/Ube/Okra/Banana)",IF(ISNUMBER(SEARCH("HVCDP",D35)),"High Value Crops (Vegetables/Fruits/Rootcrops)",IF(ISNUMBER(SEARCH("LIVESTOCK",D35)),"Livestock (Cattle/Carabao/Swine/Poultry)",IF(ISNUMBER(SEARCH("SAAD",D35)),"Various Commodities (SAAD)",IF(ISNUMBER(SEARCH("4KS",D35)),"Various Commodities (4Ks)",IF(ISNUMBER(SEARCH("4K",D35)),"Various Commodities (4Ks)",IF(ISNUMBER(SEARCH("HALAL",D35)),"Halal Food Products",IF(ISNUMBER(SEARCH("OAP",D35)),"Organic Agriculture",IF(ISNUMBER(SEARCH("NUPAP",D35)),"Vegetables (NUPAP/Urban Agri)",""))))))))))))))
A36: Region 2 | B36: Batanes | C36: Mahatao | D36: Warehouse Facilities | J36: DA-RFO2 | AA36: =_xlfn.IFS(J36="DA-FMRDP","Farm-to-Market Road",J36="DA-RFO2 RICE","Rice",J36="DA-RFO2 Rice Program","Rice",J36="DA-RFO2 CORN","Corn",J36="DA-RFO2 Corn Program","Corn",J36="DA-RFO2 HVCDP","High Value Crops (Vegetables/Fruits/Rootcrops)",J36="DA-RFO2 HVCDP Export","High Value Export Crops (Dragon Fruit/Ube/Okra/Banana)",J36="DA-RFO2 HVCDP Coffee","Coffee (HVCDP)",J36="DA-RFO2 LIVESTOCK","Livestock (Cattle/Carabao/Swine/Poultry)",J36="DA-RFO2 SAAD","Various Commodities (SAAD)",J36="DA-RFO2 4K","Various Commodities (4Ks)",J36="DA-RFO2 4KS","Various Commodities (4Ks)",J36="DA-RFO2 HALAL","Halal Food Products",J36="DA-RFO2 OAP","Organic Agriculture",J36="DA-RFO2 NUPAP","Vegetables (NUPAP/Urban Agri)",TRUE,IF(ISNUMBER(SEARCH("FMR",D36)),"Farm-to-Market Road",IF(ISNUMBER(SEARCH("RICE",D36)),"Rice",IF(ISNUMBER(SEARCH("CORN",D36)),"Corn",IF(ISNUMBER(SEARCH("HVCDP COFFEE",D36)),"Coffee (HVCDP)",IF(ISNUMBER(SEARCH("HVCDP EXPORT",D36)),"High Value Export Crops (Dragon Fruit/Ube/Okra/Banana)",IF(ISNUMBER(SEARCH("HVCDP",D36)),"High Value Crops (Vegetables/Fruits/Rootcrops)",IF(ISNUMBER(SEARCH("LIVESTOCK",D36)),"Livestock (Cattle/Carabao/Swine/Poultry)",IF(ISNUMBER(SEARCH("SAAD",D36)),"Various Commodities (SAAD)",IF(ISNUMBER(SEARCH("4KS",D36)),"Various Commodities (4Ks)",IF(ISNUMBER(SEARCH("4K",D36)),"Various Commodities (4Ks)",IF(ISNUMBER(SEARCH("HALAL",D36)),"Halal Food Products",IF(ISNUMBER(SEARCH("OAP",D36)),"Organic Agriculture",IF(ISNUMBER(SEARCH("NUPAP",D36)),"Vegetables (NUPAP/Urban Agri)",""))))))))))))))
A37: Region 2 | B37: Batanes | C37: Sabtang | D37: Buying, Consolidation, and Packaging Centers | J37: DA-RFO2 | AA37: =_xlfn.IFS(J37="DA-FMRDP","Farm-to-Market Road",J37="DA-RFO2 RICE","Rice",J37="DA-RFO2 Rice Program","Rice",J37="DA-RFO2 CORN","Corn",J37="DA-RFO2 Corn Program","Corn",J37="DA-RFO2 HVCDP","High Value Crops (Vegetables/Fruits/Rootcrops)",J37="DA-RFO2 HVCDP Export","High Value Export Crops (Dragon Fruit/Ube/Okra/Banana)",J37="DA-RFO2 HVCDP Coffee","Coffee (HVCDP)",J37="DA-RFO2 LIVESTOCK","Livestock (Cattle/Carabao/Swine/Poultry)",J37="DA-RFO2 SAAD","Various Commodities (SAAD)",J37="DA-RFO2 4K","Various Commodities (4Ks)",J37="DA-RFO2 4KS","Various Commodities (4Ks)",J37="DA-RFO2 HALAL","Halal Food Products",J37="DA-RFO2 OAP","Organic Agriculture",J37="DA-RFO2 NUPAP","Vegetables (NUPAP/Urban Agri)",TRUE,IF(ISNUMBER(SEARCH("FMR",D37)),"Farm-to-Market Road",IF(ISNUMBER(SEARCH("RICE",D37)),"Rice",IF(ISNUMBER(SEARCH("CORN",D37)),"Corn",IF(ISNUMBER(SEARCH("HVCDP COFFEE",D37)),"Coffee (HVCDP)",IF(ISNUMBER(SEARCH("HVCDP EXPORT",D37)),"High Value Export Crops (Dragon Fruit/Ube/Okra/Banana)",IF(ISNUMBER(SEARCH("HVCDP",D37)),"High Value Crops (Vegetables/Fruits/Rootcrops)",IF(ISNUMBER(SEARCH("LIVESTOCK",D37)),"Livestock (Cattle/Carabao/Swine/Poultry)",IF(ISNUMBER(SEARCH("SAAD",D37)),"Various Commodities (SAAD)",IF(ISNUMBER(SEARCH("4KS",D37)),"Various Commodities (4Ks)",IF(ISNUMBER(SEARCH("4K",D37)),"Various Commodities (4Ks)",IF(ISNUMBER(SEARCH("HALAL",D37)),"Halal Food Products",IF(ISNUMBER(SEARCH("OAP",D37)),"Organic Agriculture",IF(ISNUMBER(SEARCH("NUPAP",D37)),"Vegetables (NUPAP/Urban Agri)",""))))))))))))))
A38: Region 2 | B38: Batanes | C38: Sabtang | D38: Construction of Satuvang-Chaninu, Brgy. Savidug FMR Phase III, Brgy. Savidug, Sabtang, Batanes | F38: 16000 | J38: DA-FMRDP | AA38: =_xlfn.IFS(J38="DA-FMRDP","Farm-to-Market Road",J38="DA-RFO2 RICE","Rice",J38="DA-RFO2 Rice Program","Rice",J38="DA-RFO2 CORN","Corn",J38="DA-RFO2 Corn Program","Corn",J38="DA-RFO2 HVCDP","High Value Crops (Vegetables/Fruits/Rootcrops)",J38="DA-RFO2 HVCDP Export","High Value Export Crops (Dragon Fruit/Ube/Okra/Banana)",J38="DA-RFO2 HVCDP Coffee","Coffee (HVCDP)",J38="DA-RFO2 LIVESTOCK","Livestock (Cattle/Carabao/Swine/Poultry)",J38="DA-RFO2 SAAD","Various Commodities (SAAD)",J38="DA-RFO2 4K","Various Commodities (4Ks)",J38="DA-RFO2 4KS","Various Commodities (4Ks)",J38="DA-RFO2 HALAL","Halal Food Products",J38="DA-RFO2 OAP","Organic Agriculture",J38="DA-RFO2 NUPAP","Vegetables (NUPAP/Urban Agri)",TRUE,IF(ISNUMBER(SEARCH("FMR",D38)),"Farm-to-Market Road",IF(ISNUMBER(SEARCH("RICE",D38)),"Rice",IF(ISNUMBER(SEARCH("CORN",D38)),"Corn",IF(ISNUMBER(SEARCH("HVCDP COFFEE",D38)),"Coffee (HVCDP)",IF(ISNUMBER(SEARCH("HVCDP EXPORT",D38)),"High Value Export Crops (Dragon Fruit/Ube/Okra/Banana)",IF(ISNUMBER(SEARCH("HVCDP",D38)),"High Value Crops (Vegetables/Fruits/Rootcrops)",IF(ISNUMBER(SEARCH("LIVESTOCK",D38)),"Livestock (Cattle/Carabao/Swine/Poultry)",IF(ISNUMBER(SEARCH("SAAD",D38)),"Various Commodities (SAAD)",IF(ISNUMBER(SEARCH("4KS",D38)),"Various Commodities (4Ks)",IF(ISNUMBER(SEARCH("4K",D38)),"Various Commodities (4Ks)",IF(ISNUMBER(SEARCH("HALAL",D38)),"Halal Food Products",IF(ISNUMBER(SEARCH("OAP",D38)),"Organic Agriculture",IF(ISNUMBER(SEARCH("NUPAP",D38)),"Vegetables (NUPAP/Urban Agri)","")))))))))))))) -> Farm-to-Market Road
A39: Region 2 | B39: Batanes | C39: Sabtang | D39: Construction of Sitio Riwas-Roro Port, Brgy. Malakdang FMR, Brgy. Malakdang, Sabtang, Batanes | F39: 13500 | J39: DA-FMRDP | AA39: =_xlfn.IFS(J39="DA-FMRDP","Farm-to-Market Road",J39="DA-RFO2 RICE","Rice",J39="DA-RFO2 Rice Program","Rice",J39="DA-RFO2 CORN","Corn",J39="DA-RFO2 Corn Program","Corn",J39="DA-RFO2 HVCDP","High Value Crops (Vegetables/Fruits/Rootcrops)",J39="DA-RFO2 HVCDP Export","High Value Export Crops (Dragon Fruit/Ube/Okra/Banana)",J39="DA-RFO2 HVCDP Coffee","Coffee (HVCDP)",J39="DA-RFO2 LIVESTOCK","Livestock (Cattle/Carabao/Swine/Poultry)",J39="DA-RFO2 SAAD","Various Commodities (SAAD)",J39="DA-RFO2 4K","Various Commodities (4Ks)",J39="DA-RFO2 4KS","Various Commodities (4Ks)",J39="DA-RFO2 HALAL","Halal Food Products",J39="DA-RFO2 OAP","Organic Agriculture",J39="DA-RFO2 NUPAP","Vegetables (NUPAP/Urban Agri)",TRUE,IF(ISNUMBER(SEARCH("FMR",D39)),"Farm-to-Market Road",IF(ISNUMBER(SEARCH("RICE",D39)),"Rice",IF(ISNUMBER(SEARCH("CORN",D39)),"Corn",IF(ISNUMBER(SEARCH("HVCDP COFFEE",D39)),"Coffee (HVCDP)",IF(ISNUMBER(SEARCH("HVCDP EXPORT",D39)),"High Value Export Crops (Dragon Fruit/Ube/Okra/Banana)",IF(ISNUMBER(SEARCH("HVCDP",D39)),"High Value Crops (Vegetables/Fruits/Rootcrops)",IF(ISNUMBER(SEARCH("LIVESTOCK",D39)),"Livestock (Cattle/Carabao/Swine/Poultry)",IF(ISNUMBER(SEARCH("SAAD",D39)),"Various Commodities (SAAD)",IF(ISNUMBER(SEARCH("4KS",D39)),"Various Commodities (4Ks)",IF(ISNUMBER(SEARCH("4K",D39)),"Various Commodities (4Ks)",IF(ISNUMBER(SEARCH("HALAL",D39)),"Halal Food Products",IF(ISNUMBER(SEARCH("OAP",D39)),"Organic Agriculture",IF(ISNUMBER(SEARCH("NUPAP",D39)),"Vegetables (NUPAP/Urban Agri)","")))))))))))))) -> Farm-to-Market Road
A40: Region 2 | B40: Batanes | C40: Sabtang | D40: FMR Construction/Concreting | E40: 25000 | J40: DA-FMRDP | AA40: =_xlfn.IFS(J40="DA-FMRDP","Farm-to-Market Road",J40="DA-RFO2 RICE","Rice",J40="DA-RFO2 Rice Program","Rice",J40="DA-RFO2 CORN","Corn",J40="DA-RFO2 Corn Program","Corn",J40="DA-RFO2 HVCDP","High Value Crops (Vegetables/Fruits/Rootcrops)",J40="DA-RFO2 HVCDP Export","High Value Export Crops (Dragon Fruit/Ube/Okra/Banana)",J40="DA-RFO2 HVCDP Coffee","Coffee (HVCDP)",J40="DA-RFO2 LIVESTOCK","Livestock (Cattle/Carabao/Swine/Poultry)",J40="DA-RFO2 SAAD","Various Commodities (SAAD)",J40="DA-RFO2 4K","Various Commodities (4Ks)",J40="DA-RFO2 4KS","Various Commodities (4Ks)",J40="DA-RFO2 HALAL","Halal Food Products",J40="DA-RFO2 OAP","Organic Agriculture",J40="DA-RFO2 NUPAP","Vegetables (NUPAP/Urban Agri)",TRUE,IF(ISNUMBER(SEARCH("FMR",D40)),"Farm-to-Market Road",IF(ISNUMBER(SEARCH("RICE",D40)),"Rice",IF(ISNUMBER(SEARCH("CORN",D40)),"Corn",IF(ISNUMBER(SEARCH("HVCDP COFFEE",D40)),"Coffee (HVCDP)",IF(ISNUMBER(SEARCH("HVCDP EXPORT",D40)),"High Value Export Crops (Dragon Fruit/Ube/Okra/Banana)",IF(ISNUMBER(SEARCH("HVCDP",D40)),"High Value Crops (Vegetables/Fruits/Rootcrops)",IF(ISNUMBER(SEARCH("LIVESTOCK",D40)),"Livestock (Cattle/Carabao/Swine/Poultry)",IF(ISNUMBER(SEARCH("SAAD",D40)),"Various Commodities (SAAD)",IF(ISNUMBER(SEARCH("4KS",D40)),"Various Commodities (4Ks)",IF(ISNUMBER(SEARCH("4K",D40)),"Various Commodities (4Ks)",IF(ISNUMBER(SEARCH("HALAL",D40)),"Halal Food Products",IF(ISNUMBER(SEARCH("OAP",D40)),"Organic Agriculture",IF(ISNUMBER(SEARCH("NUPAP",D40)),"Vegetables (NUPAP/Urban Agri)","")))))))))))))) -> Farm-to-Market Road
A41: Region 2 | B41: Batanes | C41: Sabtang | D41: Irrigation Systems | J41: DA-RFO2 | AA41: =_xlfn.IFS(J41="DA-FMRDP","Farm-to-Market Road",J41="DA-RFO2 RICE","Rice",J41="DA-RFO2 Rice Program","Rice",J41="DA-RFO2 CORN","Corn",J41="DA-RFO2 Corn Program","Corn",J41="DA-RFO2 HVCDP","High Value Crops (Vegetables/Fruits/Rootcrops)",J41="DA-RFO2 HVCDP Export","High Value Export Crops (Dragon Fruit/Ube/Okra/Banana)",J41="DA-RFO2 HVCDP Coffee","Coffee (HVCDP)",J41="DA-RFO2 LIVESTOCK","Livestock (Cattle/Carabao/Swine/Poultry)",J41="DA-RFO2 SAAD","Various Commodities (SAAD)",J41="DA-RFO2 4K","Various Commodities (4Ks)",J41="DA-RFO2 4KS","Various Commodities (4Ks)",J41="DA-RFO2 HALAL","Halal Food Products",J41="DA-RFO2 OAP","Organic Agriculture",J41="DA-RFO2 NUPAP","Vegetables (NUPAP/Urban Agri)",TRUE,IF(ISNUMBER(SEARCH("FMR",D41)),"Farm-to-Market Road",IF(ISNUMBER(SEARCH("RICE",D41)),"Rice",IF(ISNUMBER(SEARCH("CORN",D41)),"Corn",IF(ISNUMBER(SEARCH("HVCDP COFFEE",D41)),"Coffee (HVCDP)",IF(ISNUMBER(SEARCH("HVCDP EXPORT",D41)),"High Value Export Crops (Dragon Fruit/Ube/Okra/Banana)",IF(ISNUMBER(SEARCH("HVCDP",D41)),"High Value Crops (Vegetables/Fruits/Rootcrops)",IF(ISNUMBER(SEARCH("LIVESTOCK",D41)),"Livestock (Cattle/Carabao/Swine/Poultry)",IF(ISNUMBER(SEARCH("SAAD",D41)),"Various Commodities (SAAD)",IF(ISNUMBER(SEARCH("4KS",D41)),"Various Commodities (4Ks)",IF(ISNUMBER(SEARCH("4K",D41)),"Various Commodities (4Ks)",IF(ISNUMBER(SEARCH("HALAL",D41)),"Halal Food Products",IF(ISNUMBER(SEARCH("OAP",D41)),"Organic Agriculture",IF(ISNUMBER(SEARCH("NUPAP",D41)),"Vegetables (NUPAP/Urban Agri)",""))))))))))))))
A42: Region 2 | B42: Batanes | C42: Sabtang | D42: Slaughterhouse & Abattoir | J42: DA-RFO2 | AA42: =_xlfn.IFS(J42="DA-FMRDP","Farm-to-Market Road",J42="DA-RFO2 RICE","Rice",J42="DA-RFO2 Rice Program","Rice",J42="DA-RFO2 CORN","Corn",J42="DA-RFO2 Corn Program","Corn",J42="DA-RFO2 HVCDP","High Value Crops (Vegetables/Fruits/Rootcrops)",J42="DA-RFO2 HVCDP Export","High Value Export Crops (Dragon Fruit/Ube/Okra/Banana)",J42="DA-RFO2 HVCDP Coffee","Coffee (HVCDP)",J42="DA-RFO2 LIVESTOCK","Livestock (Cattle/Carabao/Swine/Poultry)",J42="DA-RFO2 SAAD","Various Commodities (SAAD)",J42="DA-RFO2 4K","Various Commodities (4Ks)",J42="DA-RFO2 4KS","Various Commodities (4Ks)",J42="DA-RFO2 HALAL","Halal Food Products",J42="DA-RFO2 OAP","Organic Agriculture",J42="DA-RFO2 NUPAP","Vegetables (NUPAP/Urban Agri)",TRUE,IF(ISNUMBER(SEARCH("FMR",D42)),"Farm-to-Market Road",IF(ISNUMBER(SEARCH("RICE",D42)),"Rice",IF(ISNUMBER(SEARCH("CORN",D42)),"Corn",IF(ISNUMBER(SEARCH("HVCDP COFFEE",D42)),"Coffee (HVCDP)",IF(ISNUMBER(SEARCH("HVCDP EXPORT",D42)),"High Value Export Crops (Dragon Fruit/Ube/Okra/Banana)",IF(ISNUMBER(SEARCH("HVCDP",D42)),"High Value Crops (Vegetables/Fruits/Rootcrops)",IF(ISNUMBER(SEARCH("LIVESTOCK",D42)),"Livestock (Cattle/Carabao/Swine/Poultry)",IF(ISNUMBER(SEARCH("SAAD",D42)),"Various Commodities (SAAD)",IF(ISNUMBER(SEARCH("4KS",D42)),"Various Commodities (4Ks)",IF(ISNUMBER(SEARCH("4K",D42)),"Various Commodities (4Ks)",IF(ISNUMBER(SEARCH("HALAL",D42)),"Halal Food Products",IF(ISNUMBER(SEARCH("OAP",D42)),"Organic Agriculture",IF(ISNUMBER(SEARCH("NUPAP",D42)),"Vegetables (NUPAP/Urban Agri)",""))))))))))))))
...

Sheet BY COMMODITY or INDUSTRY
A1: DEPARTMENT OF AGRICULTURE
A2: FY 2027 Plan and Budget Proposals (PBP)
A3: ACCOMPLISHED BY: DA RFO2
A5: Indicative Geographic Targeting of FY 2027 Budget Proposals - per Commodity/ Industry
A7: Region | B7: Province | C7: City/ Municipality | D7: LGU-Identified Commodity for Co-Investment (2026 MAFIF & Meeting with Mindanao LCEs) | E7: DA OU's FY 2027 Proposed Allocation corresponding to the commodity/ industry in column 4 (if any) | G7: Additional FY 2027 commodity entry of the DA OU (if not reflected in Column 4) (specify the commodity) | H7: DA OU's FY 2027 Proposed Allocation corresponding to the commodity entry in Column 7 (if any) | J7: DA Operating Unit / Agency with Corresponding FY 2027 Proposal
E8: TIER 1 ('000) | F8: TIER 2 ('000) | H8: TIER 1 ('000) | I8: TIER 2 ('000)
A9: (1) | B9: (2) | C9: (3) | D9: (4) | E9: (5) | F9: (6) | G9: (7) | H9: (8) | I9: (9) | J9: (10)
A10: Region 2 | B10: Batanes | C10: [not specified] | D10: Poultry | E10: =SUMIFS('BY INTERVENTION'!$E:$E,'BY INTERVENTION'!$B:$B,B10,'BY INTERVENTION'!$C:$C,C10,'BY INTERVENTION'!$AA:$AA,D10) -> 0 | F10: =SUMIFS('BY INTERVENTION'!$F:$F,'BY INTERVENTION'!$B:$B,B10,'BY INTERVENTION'!$C:$C,C10,'BY INTERVENTION'!$AA:$AA,D10) -> 0 | J10: DA-RFO2
A11: Region 2 | B11: Batanes | C11: Basco | D11: Farm-to-Market Road | E11: =SUMIFS('BY INTERVENTION'!$E:$E,'BY INTERVENTION'!$B:$B,B11,'BY INTERVENTION'!$C:$C,C11,'BY INTERVENTION'!$AA:$AA,D11) -> 32500 | F11: =SUMIFS('BY INTERVENTION'!$F:$F,'BY INTERVENTION'!$B:$B,B11,'BY INTERVENTION'!$C:$C,C11,'BY INTERVENTION'!$AA:$AA,D11) -> 41000 | J11: DA-FMRDP
A12: Region 2 | B12: Batanes | C12: Basco | D12: High Value Crops (Vegetables/Fruits/Rootcrops) | E12: =SUMIFS('BY INTERVENTION'!$E:$E,'BY INTERVENTION'!$B:$B,B12,'BY INTERVENTION'!$C:$C,C12,'BY INTERVENTION'!$AA:$AA,D12) -> 7120 | F12: =SUMIFS('BY INTERVENTION'!$F:$F,'BY INTERVENTION'!$B:$B,B12,'BY INTERVENTION'!$C:$C,C12,'BY INTERVENTION'!$AA:$AA,D12) -> 0 | J12: DA-RFO2 HVCDP
A13: Region 2 | B13: Batanes | C13: Basco | D13: Various Commodities (SAAD) | E13: =SUMIFS('BY INTERVENTION'!$E:$E,'BY INTERVENTION'!$B:$B,B13,'BY INTERVENTION'!$C:$C,C13,'BY INTERVENTION'!$AA:$AA,D13) -> 1555 | F13: =SUMIFS('BY INTERVENTION'!$F:$F,'BY INTERVENTION'!$B:$B,B13,'BY INTERVENTION'!$C:$C,C13,'BY INTERVENTION'!$AA:$AA,D13) -> 0 | J13: DA-RFO2 SAAD
A14: Region 2 | B14: Batanes | C14: Itbayat | D14: Farm-to-Market Road | E14: =SUMIFS('BY INTERVENTION'!$E:$E,'BY INTERVENTION'!$B:$B,B14,'BY INTERVENTION'!$C:$C,C14,'BY INTERVENTION'!$AA:$AA,D14) -> 35000 | F14: =SUMIFS('BY INTERVENTION'!$F:$F,'BY INTERVENTION'!$B:$B,B14,'BY INTERVENTION'!$C:$C,C14,'BY INTERVENTION'!$AA:$AA,D14) -> 49100 | J14: DA-FMRDP
A15: Region 2 | B15: Batanes | C15: Itbayat | D15: High Value Crops (Vegetables/Fruits/Rootcrops) | E15: =SUMIFS('BY INTERVENTION'!$E:$E,'BY INTERVENTION'!$B:$B,B15,'BY INTERVENTION'!$C:$C,C15,'BY INTERVENTION'!$AA:$AA,D15) -> 7120 | F15: =SUMIFS('BY INTERVENTION'!$F:$F,'BY INTERVENTION'!$B:$B,B15,'BY INTERVENTION'!$C:$C,C15,'BY INTERVENTION'!$AA:$AA,D15) -> 0 | J15: DA-RFO2 HVCDP
A16: Region 2 | B16: Batanes | C16: Itbayat | D16: Rice | E16: =SUMIFS('BY INTERVENTION'!$E:$E,'BY INTERVENTION'!$B:$B,B16,'BY INTERVENTION'!$C:$C,C16,'BY INTERVENTION'!$AA:$AA,D16) -> 0 | F16: =SUMIFS('BY INTERVENTION'!$F:$F,'BY INTERVENTION'!$B:$B,B16,'BY INTERVENTION'!$C:$C,C16,'BY INTERVENTION'!$AA:$AA,D16) -> 0 | J16: DA-RFO2
A17: Region 2 | B17: Batanes | C17: Itbayat | D17: Various Commodities (SAAD) | E17: =SUMIFS('BY INTERVENTION'!$E:$E,'BY INTERVENTION'!$B:$B,B17,'BY INTERVENTION'!$C:$C,C17,'BY INTERVENTION'!$AA:$AA,D17) -> 1555 | F17: =SUMIFS('BY INTERVENTION'!$F:$F,'BY INTERVENTION'!$B:$B,B17,'BY INTERVENTION'!$C:$C,C17,'BY INTERVENTION'!$AA:$AA,D17) -> 0 | J17: DA-RFO2 SAAD
